Workbook

Sheet 项目情况汇总
A1: 指标 | B1: 数值 | C1: 说明
A2: 项目名称
A3: 项目地址
A4: 装机容量 | B4: =基础数据!D4 -> 1000 | C4: 来源：基础数据
A5: 单价（元/KWp） | B5: =基础数据!B6 -> 2000
A6: 总投资成本（万元） | B6: =基础数据!D6/10000 -> 200 | C6: 来源：总造价明细
A7: 首年发电量（万） | B7: ='光伏发电衰减表 输入数据'!D6/10000 -> 86.48341 | C7: 来源：光伏发电衰减表
A8: 首年度节电收益（万元） | B8: ='光伏发电衰减表 输入数据'!M31/30 -> 359230.7 | C8: 来源：税后净收益（首年）
A9: 回本周期 | B9: =业主自投收益回报表!J3 -> 第4年2个月 | C9: 累计净收益>0的时间点
A10: 项目IRR | B10: =业主自投收益回报表!G30 -> 0.23159299 | C10: 投资回报率
A11: 30年累计净收益（万元） | B11: =业主自投收益回报表!#REF!/10000 -> #REF! | C11: 收益终值

Sheet 基础数据
B2: 基础数据（一） | F2: 基础数据（二） | J2: 基础数据（三）
B3: 面积㎡ | D3: 装机容量KWp | F3: 面积㎡ | H3: 装机容量KWp | J3: 面积㎡ | L3: 装机容量KWp
D4: 1000 | F4: 0 | J4: 0
B5: 单价（元/KWp） | D5: 小计 | F5: 单价 | H5: 小计 | J5: 单价 | L5: 小计
B6: 2000 | D6: =D4*B6 -> 2000000 | H6: =F6*F4 -> 0 | J6: 0 | L6: =J4*J6 -> 0
G7: 工程造价合计 | H7: =D6+H6+L6 -> 2000000 | I7: 遮挡发电系数
G8: 总装机容量 | H8: =D4 -> 1000 | I8: 1
B10: 光伏发电站计量参数 | J10: 首年预计发电量（KW.h）（未计算衰减）
B11: 月份 | C11: 日照时长 | D11: 系统综合效率 | E11: 非正南角度 | F11: 发电天数 | G11: 实际等效可利用时间 | J11: 月份 | L11: 发电量
B12: 1月 | C12: 1.664275 | D12: 0.8 | E12: 0.95 | F12: 31 | G12: =C12*D12*E12*F12 -> 39.210319 | J12: 1月 | L12: =$H$8*C12*D12*E12*$I$8*F12 -> 39210.319
B13: 2月 | C13: 2.3417708 | D13: 0.8 | E13: 0.95 | F13: 28 | G13: =C13*D13*E13*F13 -> 49.832883 | J13: 2月 | L13: =$H$8*C13*D13*E13*$I$8*F13 -> 49832.883
B14: 3月 | C14: 3.1671208 | D14: 0.8 | E14: 0.95 | F14: 31 | G14: =C14*D14*E14*F14 -> 74.617367 | J14: 3月 | L14: =$H$8*C14*D14*E14*$I$8*F14 -> 74617.367
B15: 4月 | C15: 3.8699708 | D15: 0.8 | E15: 0.95 | F15: 30 | G15: =C15*D15*E15*F15 -> 88.235335 | J15: 4月 | L15: =$H$8*C15*D15*E15*$I$8*F15 -> 88235.335
B16: 5月 | C16: 4.0187375 | D16: 0.8 | E16: 0.95 | F16: 31 | G16: =C16*D16*E16*F16 -> 94.681455 | J16: 5月 | L16: =$H$8*C16*D16*E16*$I$8*F16 -> 94681.455
B17: 6月 | C17: 3.8155375 | D17: 0.8 | E17: 0.95 | F17: 30 | G17: =C17*D17*E17*F17 -> 86.994255 | J17: 6月 | L17: =$H$8*C17*D17*E17*$I$8*F17 -> 86994.255
B18: 7月 | C18: 5.0398458 | D18: 0.8 | E18: 0.95 | F18: 31 | G18: =C18*D18*E18*F18 -> 118.73877 | J18: 7月 | L18: =$H$8*C18*D18*E18*$I$8*F18 -> 118738.77
B19: 8月 | C19: 4.857025 | D19: 0.8 | E19: 0.95 | F19: 31 | G19: =C19*D19*E19*F19 -> 114.43151 | J19: 8月 | L19: =$H$8*C19*D19*E19*$I$8*F19 -> 114431.51
B20: 9月 | C20: 3.440775 | D20: 0.8 | E20: 0.95 | F20: 30 | G20: =C20*D20*E20*F20 -> 78.44967 | J20: 9月 | L20: =$H$8*C20*D20*E20*$I$8*F20 -> 78449.67
B21: 10月 | C21: 2.1542458 | D21: 0.8 | E21: 0.95 | F21: 31 | G21: =C21*D21*E21*F21 -> 50.754032 | J21: 10月 | L21: =$H$8*C21*D21*E21*$I$8*F21 -> 50754.032
B22: 11月 | C22: 1.8908792 | D22: 0.8 | E22: 0.95 | F22: 30 | G22: =C22*D22*E22*F22 -> 43.112045 | J22: 11月 | L22: =$H$8*C22*D22*E22*$I$8*F22 -> 43112.045 | P22: 1.91 | Q22: =AVERAGE(P22:XEX22) -> 1.803913
B23: 12月 | C23: 1.4648625 | D23: 0.8 | E23: 0.95 | F23: 31 | G23: =C23*D23*E23*F23 -> 34.512161 | J23: 12月 | L23: =$H$8*C23*D23*E23*$I$8*F23 -> 34512.16 | P23: 3.27 | Q23: =AVERAGE(P23:XEX23) -> 2.9573913
B24: 平均 | C24: =AVERAGE(C12:C23) -> 3.1437538 | G24: =SUM(G12:G23) -> 873.5698 | H24: =G24/0.95 -> 919.54716 | J24: 合计 | L24: =SUM(L12:L23) -> 873569.8 | P24: 4.64 | Q24: =AVERAGE(P24:XEX24) -> 3.8830435
P25: 5.05 | Q25: =AVERAGE(P25:XEX25) -> 4.8343478
B26: 节能减排表 | J26: 光伏保险费用（元） | P26: 6.21 | Q26: =AVERAGE(P26:XEX26) -> 5.6378261
B27: 项目 | C27: 发电量 | D27: 节约标准煤 | E27: 减排CO2 | F27: 减排SOx | G27: 减排NOx | H27: 等效植树 | J27: =H7*0.0035 -> 7000 | P27: 6.45 | Q27: =AVERAGE(P27:XEX27) -> 6.3752174
C28: 度 | D28: 吨 | E28: 吨 | F28: 吨 | G28: 吨 | H28: 棵 | J28: 光伏发电站运维费用（元） | P28: 6.54 | Q28: =AVERAGE(P28:XEX28) -> 6.5591304
B29: 第一年 | C29: ='光伏发电衰减表 输入数据'!D6 -> 864834.1 | D29: =C29*305/1000/1000 -> 263.7744 | E29: =C29*0.814/1000 -> 703.97496 | F29: =C29*6.2/1000/1000 -> 5.3619714 | G29: =C29*2.1/1000/1000 -> 1.8161516 | H29: =C29*0.00177 -> 1530.7564 | J29: =H8*1000*0.03 -> 30000 | P29: 5.58 | Q29: =AVERAGE(P29:XEX29) -> 5.5234783
B30: 25年合计 | C30: ='光伏发电衰减表 输入数据'!D31 -> 20572569 | D30: =C30*305/1000/1000 -> 6274.6335 | E30: =C30*0.814/1000 -> 16746.071 | F30: =C30*6.2/1000/1000 -> 127.54993 | G30: =C30*2.1/1000/1000 -> 43.202394 | H30: =C30*0.00177 -> 36413.447 | P30: 4.01 | Q30: =AVERAGE(P30:XEX30) -> 4.2169565
Q31: =AVERAGE(P31:XEX31) -> 2.7504348
C32: 碳交易权价值 | P32: 2.82 | Q32: =AVERAGE(P32:XEX32) -> 1.7704348
D33: 发电量（度） | E33: 减排碳（吨） | F33: 单价（元） | G33: 合计（元） | P33: 1.96 | Q33: =AVERAGE(P33:XEX33) -> 1.2678261
C34: 每年平均 | D34: =C30/30 -> 685752.29 | E34: =D34*0.814/1000 -> 558.20237 | G34: =F34*E34 -> 0 | P34: 1.21
C35: 25年合计 | D35: =D34*30 -> 20572569 | E35: =D35*0.814/1000 -> 16746.071 | G35: =E35*F35 -> 0 | P35: 4.14

Sheet 光伏发电衰减表 输入数据
Q3: 每年除去七、八、九月 平均电价计算（元/KW.h）
B4: 年发电量预估（峰值日照时长平均值） | E4: 消纳率 | F4: 余电上网率 | Q4: 供电局购电价 | R4: 尖电电价 | S4: 峰电电价 | T4: 平段电价 | U4: 谷电电价 | V4: 输配电费（尖） | W4: 输配电费（峰） | X4: 输配电费（平） | Y4: 基金及附加费
B5: 年份 | C5: 系统发电效率(%) | D5: 发电量（度） | E5: 0.924 | F5: =1-E5 -> 0.076 | G5: 发电收入 | H5: 运维 | I5: 保险 | J5: 资金成本 | K5: 税金合计 | L5: 碳权价值 | M5: 税后发电净收入 | P5: 余电上网电价（元） | R5: 0.93573 | S5: 0.93573 | T5: 0.594328 | U5: 忽略 | V5: =光伏发电衰减表min!P3 -> 0 | W5: =光伏发电衰减表min!Q3 -> 0 | X5: =光伏发电衰减表min!R3 -> 0 | Y5: =光伏发电衰减表min!S3 -> 0
B6: 1 | C6: 0.99 | D6: =$P$12*C6 -> 864834.1 | E6: =D6*$E$5 -> 799106.71 | F6: =D6*$F$5 -> 65727.392 | G6: =($P$14*C6*$E$5*$R$10+$P$14*C6*$F$5*$P$6+$P$16*C6*$E$5*$R$19+$P$16*C6*$F$5*$P$6)/1.13 -> 557610.4 | H6: =$D$35/1.06 -> 28301.887 | I6: =$F$35/1.06 -> 6603.7736 | J6: 0 | K6: ='税金参数（新）'!R4 -> 0 | L6: 0 | M6: =G6-H6-I6-J6-K6 -> 522704.74 | P6: 0.3515 | Q6: 光伏发电电价 | R6: 尖电电价 | S6: 峰电电价 | T6: 平段电价 | U6: 谷电电价
B7: 2 | C7: =C6-0.004 -> 0.986 | D7: =$P$12*C7 -> 861339.82 | E7: =D7*$E$5 -> 795878 | F7: =D7*$F$5 -> 65461.826 | G7: =($P$14*C7*$E$5*$R$10+$P$14*C7*$F$5*$P$6+$P$16*C7*$E$5*$R$19+$P$16*C7*$F$5*$P$6)/1.13 -> 555357.43 | H7: =$D$35/1.06 -> 28301.887 | I7: =$F$35/1.06 -> 6603.7736 | J7: 0 | K7: ='税金参数（新）'!R5 -> 0 | L7: 0 | M7: =G7-H7-I7-J7-K7 -> 520451.77 | P7: 电费折扣 | R7: =R5+V5+Y5 -> 0.93573 | S7: =S5+W5+Y5 -> 0.93573 | T7: =T5+X5+Y5 -> 0.594328 | U7: 忽略
B8: 3 | C8: =C7-0.004 -> 0.982 | D8: =$P$12*C8 -> 857845.54 | E8: =D8*$E$5 -> 792649.28 | F8: =D8*$F$5 -> 65196.261 | G8: =($P$14*C8*$E$5*$R$10+$P$14*C8*$F$5*$P$6+$P$16*C8*$E$5*$R$19+$P$16*C8*$F$5*$P$6)/1.13 -> 553104.45 | H8: =$D$35/1.06 -> 28301.887 | I8: =$F$35/1.06 -> 6603.7736 | J8: 0 | K8: ='税金参数（新）'!R6 -> 73606.483 | L8: 0 | M8: =G8-H8-I8-J8-K8 -> 444592.31 | P8: 1 | R8: 加权系数 | S8: 加权系数 | T8: 加权系数 | U8: 加权系数 | V8: 合计时段
B9: 4 | C9: =C8-0.004 -> 0.978 | D9: =$P$12*C9 -> 854351.26 | E9: =D9*$E$5 -> 789420.57 | F9: =D9*$F$5 -> 64930.696 | G9: =($P$14*C9*$E$5*$R$10+$P$14*C9*$F$5*$P$6+$P$16*C9*$E$5*$R$19+$P$16*C9*$F$5*$P$6)/1.13 -> 550851.48 | H9: =$D$35/1.06 -> 28301.887 | I9: =$F$35/1.06 -> 6603.7736 | J9: 0 | K9: ='税金参数（新）'!R7 -> 73297.618 | L9: 0 | M9: =G9-H9-I9-J9-K9 -> 442648.21 | P9: 全年平均电价 | R9: 0 | S9: 4 | T9: 5 | U9: 0 | V9: 9 | W9: 加权后平均电价 | X9: =(R7*R9+S7*S9+T7*T9)/V9 -> 0.74606222
B10: 5 | C10: =C9-0.004 -> 0.974 | D10: =$P$12*C10 -> 850856.98 | E10: =D10*$E$5 -> 786191.85 | F10: =D10*$F$5 -> 64665.131 | G10: =($P$14*C10*$E$5*$R$10+$P$14*C10*$F$5*$P$6+$P$16*C10*$E$5*$R$19+$P$16*C10*$F$5*$P$6)/1.13 -> 548598.51 | H10: =$D$35/1.06 -> 28301.887 | I10: =$F$35/1.06 -> 6603.7736 | J10: 0 | K10: ='税金参数（新）'!R8 -> 72988.752 | L10: 0 | M10: =G10-H10-I10-J10-K10 -> 440704.1 | P10: =(R10*9+R19*3)/12 -> 0.75554561 | Q10: 加权后平均电价 | R10: =X9*P8 -> 0.74606222
B11: 6 | C11: =C10-0.004 -> 0.97 | D11: =$P$12*C11 -> 847362.7 | E11: =D11*$E$5 -> 782963.14 | F11: =D11*$F$5 -> 64399.566 | G11: =($P$14*C11*$E$5*$R$10+$P$14*C11*$F$5*$P$6+$P$16*C11*$E$5*$R$19+$P$16*C11*$F$5*$P$6)/1.13 -> 546345.54 | H11: =$D$35/1.06 -> 28301.887 | I11: =$F$35/1.06 -> 6603.7736 | J11: 0 | K11: ='税金参数（新）'!R9 -> 72679.886 | L11: 0 | M11: =G11-H11-I11-J11-K11 -> 438759.99 | P11: 首年总发电量
B12: 7 | C12: =C11-0.004 -> 0.966 | D12: =$P$12*C12 -> 843868.43 | E12: =D12*$E$5 -> 779734.43 | F12: =D12*$F$5 -> 64134 | G12: =($P$14*C12*$E$5*$R$10+$P$14*C12*$F$5*$P$6+$P$16*C12*$E$5*$R$19+$P$16*C12*$F$5*$P$6)/1.13 -> 544092.57 | H12: =$D$35/1.06 -> 28301.887 | I12: =$F$35/1.06 -> 6603.7736 | J12: 0 | K12: ='税金参数（新）'!R10 -> 72371.021 | L12: 0 | M12: =G12-H12-I12-J12-K12 -> 436815.89 | P12: =P14+P16 -> 873569.8 | Q12: 每年七、八、九月 平均电价计算（元/KW.h）
B13: 8 | C13: =C12-0.004 -> 0.962 | D13: =$P$12*C13 -> 840374.15 | E13: =D13*$E$5 -> 776505.71 | F13: =D13*$F$5 -> 63868.435 | G13: =($P$14*C13*$E$5*$R$10+$P$14*C13*$F$5*$P$6+$P$16*C13*$E$5*$R$19+$P$16*C13*$F$5*$P$6)/1.13 -> 541839.6 | H13: =$D$35/1.06 -> 28301.887 | I13: =$F$35/1.06 -> 6603.7736 | J13: 0 | K13: ='税金参数（新）'!R11 -> 72062.155 | L13: 0 | M13: =G13-H13-I13-J13-K13 -> 434871.78 | P13: 首年除七、八、九月发电总量 | Q13: 供电局购电价 | R13: 尖电电价 | S13: 峰电电价 | T13: 平段电价 | U13: 谷电电价 | V13: 输配电费（尖） | W13: 输配电费（峰） | X13: 输配电费（平） | Y13: 基金及附加费
B14: 9 | C14: =C13-0.004 -> 0.958 | D14: =$P$12*C14 -> 836879.87 | E14: =D14*$E$5 -> 773277 | F14: =D14*$F$5 -> 63602.87 | G14: =($P$14*C14*$E$5*$R$10+$P$14*C14*$F$5*$P$6+$P$16*C14*$E$5*$R$19+$P$16*C14*$F$5*$P$6)/1.13 -> 539586.63 | H14: =$D$35/1.06 -> 28301.887 | I14: =$F$35/1.06 -> 6603.7736 | J14: 0 | K14: ='税金参数（新）'!R12 -> 71753.29 | L14: 0 | M14: =G14-H14-I14-J14-K14 -> 432927.68 | P14: =Q24+Q25+Q26+Q27+Q28+Q29+Q33+Q34+Q35 -> 561949.85 | R14: =R5 -> 0.93573 | S14: =S5 -> 0.93573 | T14: =T5 -> 0.594328 | U14: =U5 -> 忽略 | V14: =光伏发电衰减表min!P12 -> 0 | W14: =光伏发电衰减表min!Q12 -> 0 | X14: =光伏发电衰减表min!R12 -> 0 | Y14: =光伏发电衰减表min!S12 -> 0
B15: 10 | C15: =C14-0.004 -> 0.954 | D15: =$P$12*C15 -> 833385.59 | E15: =D15*$E$5 -> 770048.28 | F15: =D15*$F$5 -> 63337.305 | G15: =($P$14*C15*$E$5*$R$10+$P$14*C15*$F$5*$P$6+$P$16*C15*$E$5*$R$19+$P$16*C15*$F$5*$P$6)/1.13 -> 537333.66 | H15: =$D$35/1.06 -> 28301.887 | I15: =$F$35/1.06 -> 6603.7736 | J15: 0 | K15: ='税金参数（新）'!R13 -> 71444.424 | L15: 0 | M15: =G15-H15-I15-J15-K15 -> 430983.57 | P15: 首年七、八、九月发电总量 | Q15: 光伏发电电价 | R15: 尖电电价 | S15: 峰电电价 | T15: 平段电价 | U15: 谷电电价
B16: 11 | C16: =C15-0.004 -> 0.95 | D16: =$P$12*C16 -> 829891.31 | E16: =D16*$E$5 -> 766819.57 | F16: =D16*$F$5 -> 63071.739 | G16: =($P$14*C16*$E$5*$R$10+$P$14*C16*$F$5*$P$6+$P$16*C16*$E$5*$R$19+$P$16*C16*$F$5*$P$6)/1.13 -> 535080.68 | H16: =$D$35/1.06 -> 28301.887 | I16: =$F$35/1.06 -> 6603.7736 | J16: 0 | K16: ='税金参数（新）'!R14 -> 71135.559 | L16: 0 | M16: =G16-H16-I16-J16-K16 -> 429039.46 | P16: =Q30+Q31+Q32 -> 311619.95 | R16: =R14+V14+Y14 -> 0.93573 | S16: =S14+W14+Y14 -> 0.93573 | T16: =T14+X14+Y14 -> 0.594328 | U16: 忽略
B17: 12 | C17: =C16-0.004 -> 0.946 | D17: =$P$12*C17 -> 826397.03 | E17: =D17*$E$5 -> 763590.86 | F17: =D17*$F$5 -> 62806.174 | G17: =($P$14*C17*$E$5*$R$10+$P$14*C17*$F$5*$P$6+$P$16*C17*$E$5*$R$19+$P$16*C17*$F$5*$P$6)/1.13 -> 532827.71 | H17: =$D$35/1.06 -> 28301.887 | I17: =$F$35/1.06 -> 6603.7736 | J17: 0 | K17: ='税金参数（新）'!R15 -> 70826.693 | L17: 0 | M17: =G17-H17-I17-J17-K17 -> 427095.36 | R17: 加权系数 | S17: 加权系数 | T17: 加权系数 | U17: 加权系数 | V17: 合计时段
B18: 13 | C18: =C17-0.004 -> 0.942 | D18: =$P$12*C18 -> 822902.75 | E18: =D18*$E$5 -> 760362.14 | F18: =D18*$F$5 -> 62540.609 | G18: =($P$14*C18*$E$5*$R$10+$P$14*C18*$F$5*$P$6+$P$16*C18*$E$5*$R$19+$P$16*C18*$F$5*$P$6)/1.13 -> 530574.74 | H18: =$D$35/1.06 -> 28301.887 | I18: =$F$35/1.06 -> 6603.7736 | J18: 0 | K18: ='税金参数（新）'!R16 -> 70517.828 | L18: 0 | M18: =G18-H18-I18-J18-K18 -> 425151.25 | R18: 3 | S18: 2 | T18: 4 | U18: 0 | V18: 9 | W18: 加权后平均电价 | X18: =(R16*R18+S16*S18+T16*T18)/V18 -> 0.78399578
B19: 14 | C19: =C18-0.004 -> 0.938 | D19: =$P$12*C19 -> 819408.47 | E19: =D19*$E$5 -> 757133.43 | F19: =D19*$F$5 -> 62275.044 | G19: =($P$14*C19*$E$5*$R$10+$P$14*C19*$F$5*$P$6+$P$16*C19*$E$5*$R$19+$P$16*C19*$F$5*$P$6)/1.13 -> 528321.77 | H19: =$D$35/1.06 -> 28301.887 | I19: =$F$35/1.06 -> 6603.7736 | J19: 0 | K19: ='税金参数（新）'!R17 -> 70208.962 | L19: 0 | M19: =G19-H19-I19-J19-K19 -> 423207.15 | Q19: 加权后平均电价 | R19: =X18*P8 -> 0.78399578
B20: 15 | C20: =C19-0.004 -> 0.934 | D20: =$P$12*C20 -> 815914.19 | E20: =D20*$E$5 -> 753904.71 | F20: =D20*$F$5 -> 62009.479 | G20: =($P$14*C20*$E$5*$R$10+$P$14*C20*$F$5*$P$6+$P$16*C20*$E$5*$R$19+$P$16*C20*$F$5*$P$6)/1.13 -> 526068.8 | H20: =$D$35/1.06 -> 28301.887 | I20: =$F$35/1.06 -> 6603.7736 | J20: 0 | K20: ='税金参数（新）'!R18 -> 69900.097 | L20: 0 | M20: =G20-H20-I20-J20-K20 -> 421263.04
B21: 16 | C21: =C20-0.004 -> 0.93 | D21: =$P$12*C21 -> 812419.91 | E21: =D21*$E$5 -> 750676 | F21: =D21*$F$5 -> 61743.913 | G21: =($P$14*C21*$E$5*$R$10+$P$14*C21*$F$5*$P$6+$P$16*C21*$E$5*$R$19+$P$16*C21*$F$5*$P$6)/1.13 -> 523815.83 | H21: =$D$35/1.06 -> 28301.887 | I21: =$F$35/1.06 -> 6603.7736 | J21: 0 | K21: ='税金参数（新）'!R19 -> 69591.231 | L21: 0 | M21: =G21-H21-I21-J21-K21 -> 419318.94
B22: 17 | C22: =C21-0.004 -> 0.926 | D22: =$P$12*C22 -> 808925.63 | E22: =D22*$E$5 -> 747447.29 | F22: =D22*$F$5 -> 61478.348 | G22: =($P$14*C22*$E$5*$R$10+$P$14*C22*$F$5*$P$6+$P$16*C22*$E$5*$R$19+$P$16*C22*$F$5*$P$6)/1.13 -> 521562.86 | H22: =$D$35/1.06 -> 28301.887 | I22: =$F$35/1.06 -> 6603.7736 | J22: 0 | K22: ='税金参数（新）'!R20 -> 69282.366 | L22: 0 | M22: =G22-H22-I22-J22-K22 -> 417374.83 | P22: 首年预计发电量（KW.h）（未计算衰减） | S22: 首年预计发电量（KW.h）(已计算衰减）
B23: 18 | C23: =C22-0.004 -> 0.922 | D23: =$P$12*C23 -> 805431.35 | E23: =D23*$E$5 -> 744218.57 | F23: =D23*$F$5 -> 61212.783 | G23: =($P$14*C23*$E$5*$R$10+$P$14*C23*$F$5*$P$6+$P$16*C23*$E$5*$R$19+$P$16*C23*$F$5*$P$6)/1.13 -> 519309.88 | H23: =$D$35/1.06 -> 28301.887 | I23: =$F$35/1.06 -> 6603.7736 | J23: 0 | K23: ='税金参数（新）'!R21 -> 68973.5 | L23: 0 | M23: =G23-H23-I23-J23-K23 -> 415430.72 | P23: 月份 | Q23: 月发电量 | S23: 月份 | U23: 月发电量
B24: 19 | C24: =C23-0.004 -> 0.918 | D24: =$P$12*C24 -> 801937.08 | E24: =D24*$E$5 -> 740989.86 | F24: =D24*$F$5 -> 60947.218 | G24: =($P$14*C24*$E$5*$R$10+$P$14*C24*$F$5*$P$6+$P$16*C24*$E$5*$R$19+$P$16*C24*$F$5*$P$6)/1.13 -> 517056.91 | H24: =$D$35/1.06 -> 28301.887 | I24: =$F$35/1.06 -> 6603.7736 | J24: 0 | K24: ='税金参数（新）'!R22 -> 68664.635 | L24: 0 | M24: =G24-H24-I24-J24-K24 -> 413486.62 | P24: 1月 | Q24: =基础数据!L12 -> 39210.319 | S24: 1月 | U24: =Q24*0.99 -> 38818.216
B25: 20 | C25: =C24-0.004 -> 0.914 | D25: =$P$12*C25 -> 798442.8 | E25: =D25*$E$5 -> 737761.14 | F25: =D25*$F$5 -> 60681.653 | G25: =($P$14*C25*$E$5*$R$10+$P$14*C25*$F$5*$P$6+$P$16*C25*$E$5*$R$19+$P$16*C25*$F$5*$P$6)/1.13 -> 514803.94 | H25: =$D$35/1.06 -> 28301.887 | I25: =$F$35/1.06 -> 6603.7736 | J25: 0 | K25: ='税金参数（新）'!R23 -> 68355.769 | L25: 0 | M25: =G25-H25-I25-J25-K25 -> 411542.51 | P25: 2月 | Q25: =基础数据!L13 -> 49832.883 | S25: 2月 | U25: =Q25*0.99 -> 49334.554
B26: 21 | C26: =C25-0.004 -> 0.91 | D26: =$P$12*C26 -> 794948.52 | E26: =D26*$E$5 -> 734532.43 | F26: =D26*$F$5 -> 60416.087 | G26: =($P$14*C26*$E$5*$R$10+$P$14*C26*$F$5*$P$6+$P$16*C26*$E$5*$R$19+$P$16*C26*$F$5*$P$6)/1.13 -> 512550.97 | H26: =$D$35/1.06 -> 28301.887 | I26: =$F$35/1.06 -> 6603.7736 | J26: 0 | K26: ='税金参数（新）'!R24 -> 68046.904 | L26: 0 | M26: =G26-H26-I26-J26-K26 -> 409598.41 | P26: 3月 | Q26: =基础数据!L14 -> 74617.367 | S26: 3月 | U26: =Q26*0.99 -> 73871.193
B27: 22 | C27: =C26-0.004 -> 0.906 | D27: =$P$12*C27 -> 791454.24 | E27: =D27*$E$5 -> 731303.72 | F27: =D27*$F$5 -> 60150.522 | G27: =($P$14*C27*$E$5*$R$10+$P$14*C27*$F$5*$P$6+$P$16*C27*$E$5*$R$19+$P$16*C27*$F$5*$P$6)/1.13 -> 510298 | H27: =$D$35/1.06 -> 28301.887 | I27: =$F$35/1.06 -> 6603.7736 | J27: 0 | K27: ='税金参数（新）'!R25 -> 67738.038 | L27: 0 | M27: =G27-H27-I27-J27-K27 -> 407654.3 | P27: 4月 | Q27: =基础数据!L15 -> 88235.335 | S27: 4月 | U27: =Q27*0.99 -> 87352.982
B28: 23 | C28: =C27-0.004 -> 0.902 | D28: =$P$12*C28 -> 787959.96 | E28: =D28*$E$5 -> 728075 | F28: =D28*$F$5 -> 59884.957 | G28: =($P$14*C28*$E$5*$R$10+$P$14*C28*$F$5*$P$6+$P$16*C28*$E$5*$R$19+$P$16*C28*$F$5*$P$6)/1.13 -> 508045.03 | H28: =$D$35/1.06 -> 28301.887 | I28: =$F$35/1.06 -> 6603.7736 | J28: 0 | K28: ='税金参数（新）'!R26 -> 67429.173 | L28: 0 | M28: =G28-H28-I28-J28-K28 -> 405710.2 | P28: 5月 | Q28: =基础数据!L16 -> 94681.455 | S28: 5月 | U28: =Q28*0.99 -> 93734.641
B29: 24 | C29: =C28-0.004 -> 0.898 | D29: =$P$12*C29 -> 784465.68 | E29: =D29*$E$5 -> 724846.29 | F29: =D29*$F$5 -> 59619.392 | G29: =($P$14*C29*$E$5*$R$10+$P$14*C29*$F$5*$P$6+$P$16*C29*$E$5*$R$19+$P$16*C29*$F$5*$P$6)/1.13 -> 505792.06 | H29: =$D$35/1.06 -> 28301.887 | I29: =$F$35/1.06 -> 6603.7736 | J29: 0 | K29: ='税金参数（新）'!R27 -> 67120.307 | L29: 0 | M29: =G29-H29-I29-J29-K29 -> 403766.09 | P29: 6月 | Q29: =基础数据!L17 -> 86994.255 | S29: 6月 | U29: =Q29*0.99 -> 86124.312
B30: 25 | C30: =C29-0.004 -> 0.894 | D30: =$P$12*C30 -> 780971.4 | E30: =D30*$E$5 -> 721617.57 | F30: =D30*$F$5 -> 59353.826 | G30: =($P$14*C30*$E$5*$R$10+$P$14*C30*$F$5*$P$6+$P$16*C30*$E$5*$R$19+$P$16*C30*$F$5*$P$6)/1.13 -> 503539.09 | H30: =$D$35/1.06 -> 28301.887 | I30: =$F$35/1.06 -> 6603.7736 | J30: 0 | K30: ='税金参数（新）'!R28 -> 66811.442 | L30: 0 | M30: =G30-H30-I30-J30-K30 -> 401821.98 | P30: 7月 | Q30: =基础数据!L18 -> 118738.77 | S30: 7月 | U30: =Q30*0.99 -> 117551.38
B31: 合计 | D31: =SUM(D6:D30) -> 20572569 | E31: =SUM(E6:E30) -> 19009054 | F31: =SUM(F6:F30) -> 1563515.2 | G31: =SUM(G6:G30) -> 13264369 | M31: =SUM(M6:M30) -> 10776921 | P31: 8月 | Q31: =基础数据!L19 -> 114431.51 | S31: 8月 | U31: =Q31*0.99 -> 113287.19
A32: . | P32: 9月 | Q32: =基础数据!L20 -> 78449.67 | S32: 9月 | U32: =Q32*0.99 -> 77665.173
P33: 10月 | Q33: =基础数据!L21 -> 50754.032 | S33: 10月 | U33: =Q33*0.99 -> 50246.492
C34: 工程造价（含税） | D34: =基础数据!H7 -> 2000000 | P34: 11月 | Q34: =基础数据!L22 -> 43112.045 | S34: 11月 | U34: =Q34*0.99 -> 42680.925
C35: 运维费用 | D35: =基础数据!J29 -> 30000 | E35: 保险费用 | F35: =基础数据!J27 -> 7000 | P35: 12月 | Q35: =基础数据!L23 -> 34512.16 | S35: 12月 | U35: =Q35*0.99 -> 34167.039
P36: 合计 | Q36: =SUM(Q24:Q35) -> 873569.8 | S36: 合计 | U36: =SUM(U24:V35) -> 864834.1
C37: 工程造价（不含税） | D37: =D34/1.09 -> 1834862.4
C39: 假设运维保险都开普票

Sheet 税金参数（新）
I2: *假设企业是小微 | M2: *折旧摊销采用双倍余额递减法 | R2: *-公式不加所得税
B3: 年份 | C3: 上网收入(不含13%税） | D3: 应交上网增值税金 | E3: 运维、保险留抵进项税 | F3: 原供电局损失留抵进项税 | G3: 增值税差额 | H3: 应交增值税 | I3: 城市维护建设税 | J3: 教育费附加税 | K3: 地方教育附加 | L3: 税金及附加 | M3: 折旧摊销 | N3: 资金成本 | O3: 原供电局应交电费 | P3: 应税所得额(利润） | Q3: 应交所得税 | R3: 税金合计（增＋附加）
B4: 1 | C4: ='光伏发电衰减表 输入数据'!F6*'光伏发电衰减表 输入数据'!$P$6/1.13 -> 20445.29 | D4: =C4*0.13 -> 2657.8878 | E4: =$C$39/1.06*0.06+$E$39/1.06*0.06 -> 2094.3396 | F4: ='光伏发电衰减表 输入数据'!E6*'光伏发电衰减表 输入数据'!$P$10/1.13*0.13 -> 69459.295 | G4: =-$E$41+F4-E4+D4 -> -95114.771 | H4: =IF(G4<0,0,G4) -> 0 | I4: =H4*$K$40 -> 0 | J4: =H4*$K$41 -> 0 | K4: =H4*$K$42 -> 0 | L4: =SUM(I4:K4) -> 0 | M4: =$C$41*(2/10*100%) -> 366972.48 | N4: 0 | O4: ='光伏发电衰减表 输入数据'!E6*'光伏发电衰减表 输入数据'!$P$10/1.13 -> 534302.27 | P4: =C4+O4-$C$39/1.06-$E$39/1.06-M4-N4-L4 -> 152869.42 | Q4: =IF(P4<0,0,P4*$K$43) -> 7643.4712 | R4: =SUM(H4+L4) -> 0
B5: 2 | C5: ='光伏发电衰减表 输入数据'!F7*'光伏发电衰减表 输入数据'!$P$6/1.13 -> 20362.683 | D5: =C5*0.13 -> 2647.1488 | E5: =$C$39/1.06*0.06+$E$39/1.06*0.06 -> 2094.3396 | F5: ='光伏发电衰减表 输入数据'!E7*'光伏发电衰减表 输入数据'!$P$10/1.13*0.13 -> 69178.652 | G5: =-$E$41+SUM(F4:F5)-SUM(E4:E5)+SUM(D4:D5) -> -25383.31 | H5: =IF(G5<0,0,G5) -> 0 | I5: =H5*$K$40 -> 0 | J5: =H5*$K$41 -> 0 | K5: =H5*$K$42 -> 0 | L5: =SUM(I5:K5) -> 0 | M5: =($C$41-M4)*(2/10*100%) -> 293577.98 | N5: 0 | O5: ='光伏发电衰减表 输入数据'!E7*'光伏发电衰减表 输入数据'!$P$10/1.13 -> 532143.47 | P5: =C5+O5-$C$39/1.06-$E$39/1.06-M5-N5-L5 -> 224022.52 | Q5: =IF(P5<0,0,P5*$K$43) -> 11201.126 | R5: =SUM(H5+L5) -> 0
B6: 3 | C6: ='光伏发电衰减表 输入数据'!F8*'光伏发电衰减表 输入数据'!$P$6/1.13 -> 20280.076 | D6: =C6*0.13 -> 2636.4099 | E6: =$C$39/1.06*0.06+$E$39/1.06*0.06 -> 2094.3396 | F6: ='光伏发电衰减表 输入数据'!E8*'光伏发电衰减表 输入数据'!$P$10/1.13*0.13 -> 68898.008 | G6: =F6-E6+D6 -> 69440.078 | H6: =IF(G6<0,0,G6) -> 69440.078 | I6: =H6*$K$40 -> 2430.4027 | J6: =H6*$K$41 -> 1041.6012 | K6: =H6*$K$42 -> 694.40078 | L6: =SUM(I6:K6) -> 4166.4047 | M6: =($C$41-M5-M4)*(2/10*100%) -> 234862.39 | N6: 0 | O6: ='光伏发电衰减表 输入数据'!E8*'光伏发电衰减表 输入数据'!$P$10/1.13 -> 529984.68 | P6: =C6+O6-$C$39/1.06-$E$39/1.06-M6-N6-L6 -> 276330.3 | Q6: =IF(P6<0,0,P6*$K$43) -> 13816.515 | R6: =SUM(H6+L6) -> 73606.483
B7: 4 | C7: ='光伏发电衰减表 输入数据'!F9*'光伏发电衰减表 输入数据'!$P$6/1.13 -> 20197.469 | D7: =C7*0.13 -> 2625.6709 | E7: =$C$39/1.06*0.06+$E$39/1.06*0.06 -> 2094.3396 | F7: ='光伏发电衰减表 输入数据'!E9*'光伏发电衰减表 输入数据'!$P$10/1.13*0.13 -> 68617.364 | G7: =F7-E7+D7 -> 69148.696 | H7: =IF(G7<0,0,G7) -> 69148.696 | I7: =H7*$K$40 -> 2420.2044 | J7: =H7*$K$41 -> 1037.2304 | K7: =H7*$K$42 -> 691.48696 | L7: =SUM(I7:K7) -> 4148.9217 | M7: =($C$41-M6-M5-M4)*(2/10*100%) -> 187889.91 | N7: 0 | O7: ='光伏发电衰减表 输入数据'!E9*'光伏发电衰减表 输入数据'!$P$10/1.13 -> 527825.88 | P7: =C7+O7-$C$39/1.06-$E$39/1.06-M7-N7-L7 -> 321078.86 | Q7: =IF(P7<0,0,P7*$K$43) -> 16053.943 | R7: =SUM(H7+L7) -> 73297.618
B8: 5 | C8: ='光伏发电衰减表 输入数据'!F10*'光伏发电衰减表 输入数据'!$P$6/1.13 -> 20114.861 | D8: =C8*0.13 -> 2614.932 | E8: =$C$39/1.06*0.06+$E$39/1.06*0.06 -> 2094.3396 | F8: ='光伏发电衰减表 输入数据'!E10*'光伏发电衰减表 输入数据'!$P$10/1.13*0.13 -> 68336.721 | G8: =F8-E8+D8 -> 68857.313 | H8: =IF(G8<0,0,G8) -> 68857.313 | I8: =H8*$K$40 -> 2410.006 | J8: =H8*$K$41 -> 1032.8597 | K8: =H8*$K$42 -> 688.57313 | L8: =SUM(I8:K8) -> 4131.4388 | M8: =($C$41-M7-M6-M5-M4)*(2/10*100%) -> 150311.93 | N8: 0 | O8: ='光伏发电衰减表 输入数据'!E10*'光伏发电衰减表 输入数据'!$P$10/1.13 -> 525667.08 | P8: =C8+O8-$C$39/1.06-$E$39/1.06-M8-N8-L8 -> 356432.92 | Q8: =IF(P8<0,0,P8*$K$43) -> 17821.646 | R8: =SUM(H8+L8) -> 72988.752
B9: 6 | C9: ='光伏发电衰减表 输入数据'!F11*'光伏发电衰减表 输入数据'!$P$6/1.13 -> 20032.254 | D9: =C9*0.13 -> 2604.1931 | E9: =$C$39/1.06*0.06+$E$39/1.06*0.06 -> 2094.3396 | F9: ='光伏发电衰减表 输入数据'!E11*'光伏发电衰减表 输入数据'!$P$10/1.13*0.13 -> 68056.077 | G9: =F9-E9+D9 -> 68565.931 | H9: =IF(G9<0,0,G9) -> 68565.931 | I9: =H9*$K$40 -> 2399.8076 | J9: =H9*$K$41 -> 1028.489 | K9: =H9*$K$42 -> 685.65931 | L9: =SUM(I9:K9) -> 4113.9558 | M9: =($C$41-M8-M7-M6-M5-M4)*(2/10*100%) -> 120249.54 | N9: 0 | O9: ='光伏发电衰减表 输入数据'!E11*'光伏发电衰减表 输入数据'!$P$10/1.13 -> 523508.29 | P9: =C9+O9-$C$39/1.06-$E$39/1.06-M9-N9-L9 -> 384271.38 | Q9: =IF(P9<0,0,P9*$K$43) -> 19213.569 | R9: =SUM(H9+L9) -> 72679.886
B10: 7 | C10: ='光伏发电衰减表 输入数据'!F12*'光伏发电衰减表 输入数据'!$P$6/1.13 -> 19949.647 | D10: =C10*0.13 -> 2593.4541 | E10: =$C$39/1.06*0.06+$E$39/1.06*0.06 -> 2094.3396 | F10: ='光伏发电衰减表 输入数据'!E12*'光伏发电衰减表 输入数据'!$P$10/1.13*0.13 -> 67775.434 | G10: =F10-E10+D10 -> 68274.548 | H10: =IF(G10<0,0,G10) -> 68274.548 | I10: =H10*$K$40 -> 2389.6092 | J10: =H10*$K$41 -> 1024.1182 | K10: =H10*$K$42 -> 682.74548 | L10: =SUM(I10:K10) -> 4096.4729 | M10: =($C$41-M9-M8-M7-M6-M5-M4)*(2/10*100%) -> 96199.633 | N10: 0 | O10: ='光伏发电衰减表 输入数据'!E12*'光伏发电衰减表 输入数据'!$P$10/1.13 -> 521349.49 | P10: =C10+O10-$C$39/1.06-$E$39/1.06-M10-N10-L10 -> 406097.37 | Q10: =IF(P10<0,0,P10*$K$43) -> 20304.868 | R10: =SUM(H10+L10) -> 72371.021
B11: 8 | C11: ='光伏发电衰减表 输入数据'!F13*'光伏发电衰减表 输入数据'!$P$6/1.13 -> 19867.04 | D11: =C11*0.13 -> 2582.7152 | E11: =$C$39/1.06*0.06+$E$39/1.06*0.06 -> 2094.3396 | F11: ='光伏发电衰减表 输入数据'!E13*'光伏发电衰减表 输入数据'!$P$10/1.13*0.13 -> 67494.79 | G11: =F11-E11+D11 -> 67983.166 | H11: =IF(G11<0,0,G11) -> 67983.166 | I11: =H11*$K$40 -> 2379.4108 | J11: =H11*$K$41 -> 1019.7475 | K11: =H11*$K$42 -> 679.83166 | L11: =SUM(I11:K11) -> 4078.9899 | M11: =($C$41-M10-M9-M8-M7-M6-M5-M4)*(2/10*100%) -> 76959.706 | N11: 0 | O11: ='光伏发电衰减表 输入数据'!E13*'光伏发电衰减表 输入数据'!$P$10/1.13 -> 519190.69 | P11: =C11+O11-$C$39/1.06-$E$39/1.06-M11-N11-L11 -> 423113.38 | Q11: =IF(P11<0,0,P11*$K$43) -> 21155.669 | R11: =SUM(H11+L11) -> 72062.155
B12: 9 | C12: ='光伏发电衰减表 输入数据'!F14*'光伏发电衰减表 输入数据'!$P$6/1.13 -> 19784.433 | D12: =C12*0.13 -> 2571.9762 | E12: =$C$39/1.06*0.06+$E$39/1.06*0.06 -> 2094.3396 | F12: ='光伏发电衰减表 输入数据'!E14*'光伏发电衰减表 输入数据'!$P$10/1.13*0.13 -> 67214.146 | G12: =F12-E12+D12 -> 67691.783 | H12: =IF(G12<0,0,G12) -> 67691.783 | I12: =H12*$K$40 -> 2369.2124 | J12: =H12*$K$41 -> 1015.3767 | K12: =H12*$K$42 -> 676.91783 | L12: =SUM(I12:K12) -> 4061.507 | M12: =(C41-SUM(M4:M11))/2 -> 153919.41 | N12: 0 | O12: ='光伏发电衰减表 输入数据'!E14*'光伏发电衰减表 输入数据'!$P$10/1.13 -> 517031.9 | P12: =C12+O12-$C$39/1.06-$E$39/1.06-M12-N12-L12 -> 343929.75 | Q12: =IF(P12<0,0,P12*$K$43) -> 17196.487 | R12: =SUM(H12+L12) -> 71753.29
B13: 10 | C13: ='光伏发电衰减表 输入数据'!F15*'光伏发电衰减表 输入数据'!$P$6/1.13 -> 19701.825 | D13: =C13*0.13 -> 2561.2373 | E13: =$C$39/1.06*0.06+$E$39/1.06*0.06 -> 2094.3396 | F13: ='光伏发电衰减表 输入数据'!E15*'光伏发电衰减表 输入数据'!$P$10/1.13*0.13 -> 66933.503 | G13: =F13-E13+D13 -> 67400.4 | H13: =IF(G13<0,0,G13) -> 67400.4 | I13: =H13*$K$40 -> 2359.014 | J13: =H13*$K$41 -> 1011.006 | K13: =H13*$K$42 -> 674.004 | L13: =SUM(I13:K13) -> 4044.024 | M13: =M12 -> 153919.41 | N13: 0 | O13: ='光伏发电衰减表 输入数据'!E15*'光伏发电衰减表 输入数据'!$P$10/1.13 -> 514873.1 | P13: =C13+O13-$C$39/1.06-$E$39/1.06-M13-N13-L13 -> 341705.83 | Q13: =IF(P13<0,0,P13*$K$43) -> 17085.291 | R13: =SUM(H13+L13) -> 71444.424
B14: 11 | C14: ='光伏发电衰减表 输入数据'!F16*'光伏发电衰减表 输入数据'!$P$6/1.13 -> 19619.218 | D14: =C14*0.13 -> 2550.4983 | E14: =$C$39/1.06*0.06+$E$39/1.06*0.06 -> 2094.3396 | F14: ='光伏发电衰减表 输入数据'!E16*'光伏发电衰减表 输入数据'!$P$10/1.13*0.13 -> 66652.859 | G14: =F14-E14+D14 -> 67109.018 | H14: =IF(G14<0,0,G14) -> 67109.018 | I14: =H14*$K$40 -> 2348.8156 | J14: =H14*$K$41 -> 1006.6353 | K14: =H14*$K$42 -> 671.09018 | L14: =SUM(I14:K14) -> 4026.5411 | M14: 0 | N14: 0 | O14: ='光伏发电衰减表 输入数据'!E16*'光伏发电衰减表 输入数据'!$P$10/1.13 -> 512714.3 | P14: =C14+O14-$C$39/1.06-$E$39/1.06-M14-N14-L14 -> 493401.32 | Q14: =IF(P14<0,0,P14*$K$43) -> 24670.066 | R14: =SUM(H14+L14) -> 71135.559
B15: 12 | C15: ='光伏发电衰减表 输入数据'!F17*'光伏发电衰减表 输入数据'!$P$6/1.13 -> 19536.611 | D15: =C15*0.13 -> 2539.7594 | E15: =$C$39/1.06*0.06+$E$39/1.06*0.06 -> 2094.3396 | F15: ='光伏发电衰减表 输入数据'!E17*'光伏发电衰减表 输入数据'!$P$10/1.13*0.13 -> 66372.216 | G15: =F15-E15+D15 -> 66817.635 | H15: =IF(G15<0,0,G15) -> 66817.635 | I15: =H15*$K$40 -> 2338.6172 | J15: =H15*$K$41 -> 1002.2645 | K15: =H15*$K$42 -> 668.17635 | L15: =SUM(I15:K15) -> 4009.0581 | M15: 0 | N15: 0 | O15: ='光伏发电衰减表 输入数据'!E17*'光伏发电衰减表 输入数据'!$P$10/1.13 -> 510555.5 | P15: =C15+O15-$C$39/1.06-$E$39/1.06-M15-N15-L15 -> 491177.4 | Q15: =IF(P15<0,0,P15*$K$43) -> 24558.87 | R15: =SUM(H15+L15) -> 70826.693
B16: 13 | C16: ='光伏发电衰减表 输入数据'!F18*'光伏发电衰减表 输入数据'!$P$6/1.13 -> 19454.004 | D16: =C16*0.13 -> 2529.0205 | E16: =$C$39/1.06*0.06+$E$39/1.06*0.06 -> 2094.3396 | F16: ='光伏发电衰减表 输入数据'!E18*'光伏发电衰减表 输入数据'!$P$10/1.13*0.13 -> 66091.572 | G16: =F16-E16+D16 -> 66526.253 | H16: =IF(G16<0,0,G16) -> 66526.253 | I16: =H16*$K$40 -> 2328.4188 | J16: =H16*$K$41 -> 997.89379 | K16: =H16*$K$42 -> 665.26253 | L16: =SUM(I16:K16) -> 3991.5752 | M16: 0 | N16: 0 | O16: ='光伏发电衰减表 输入数据'!E18*'光伏发电衰减表 输入数据'!$P$10/1.13 -> 508396.71 | P16: =C16+O16-$C$39/1.06-$E$39/1.06-M16-N16-L16 -> 488953.48 | Q16: =IF(P16<0,0,P16*$K$43) -> 24447.674 | R16: =SUM(H16+L16) -> 70517.828
B17: 14 | C17: ='光伏发电衰减表 输入数据'!F19*'光伏发电衰减表 输入数据'!$P$6/1.13 -> 19371.396 | D17: =C17*0.13 -> 2518.2815 | E17: =$C$39/1.06*0.06+$E$39/1.06*0.06 -> 2094.3396 | F17: ='光伏发电衰减表 输入数据'!E19*'光伏发电衰减表 输入数据'!$P$10/1.13*0.13 -> 65810.928 | G17: =F17-E17+D17 -> 66234.87 | H17: =IF(G17<0,0,G17) -> 66234.87 | I17: =H17*$K$40 -> 2318.2205 | J17: =H17*$K$41 -> 993.52305 | K17: =H17*$K$42 -> 662.3487 | L17: =SUM(I17:K17) -> 3974.0922 | M17: 0 | N17: 0 | O17: ='光伏发电衰减表 输入数据'!E19*'光伏发电衰减表 输入数据'!$P$10/1.13 -> 506237.91 | P17: =C17+O17-$C$39/1.06-$E$39/1.06-M17-N17-L17 -> 486729.55 | Q17: =IF(P17<0,0,P17*$K$43) -> 24336.478 | R17: =SUM(H17+L17) -> 70208.962
B18: 15 | C18: ='光伏发电衰减表 输入数据'!F20*'光伏发电衰减表 输入数据'!$P$6/1.13 -> 19288.789 | D18: =C18*0.13 -> 2507.5426 | E18: =$C$39/1.06*0.06+$E$39/1.06*0.06 -> 2094.3396 | F18: ='光伏发电衰减表 输入数据'!E20*'光伏发电衰减表 输入数据'!$P$10/1.13*0.13 -> 65530.285 | G18: =F18-E18+D18 -> 65943.488 | H18: =IF(G18<0,0,G18) -> 65943.488 | I18: =H18*$K$40 -> 2308.0221 | J18: =H18*$K$41 -> 989.15231 | K18: =H18*$K$42 -> 659.43488 | L18: =SUM(I18:K18) -> 3956.6093 | M18: 0 | N18: 0 | O18: ='光伏发电衰减表 输入数据'!E20*'光伏发电衰减表 输入数据'!$P$10/1.13 -> 504079.11 | P18: =C18+O18-$C$39/1.06-$E$39/1.06-M18-N18-L18 -> 484505.63 | Q18: =IF(P18<0,0,P18*$K$43) -> 24225.282 | R18: =SUM(H18+L18) -> 69900.097
B19: 16 | C19: ='光伏发电衰减表 输入数据'!F21*'光伏发电衰减表 输入数据'!$P$6/1.13 -> 19206.182 | D19: =C19*0.13 -> 2496.8036 | E19: =$C$39/1.06*0.06+$E$39/1.06*0.06 -> 2094.3396 | F19: ='光伏发电衰减表 输入数据'!E21*'光伏发电衰减表 输入数据'!$P$10/1.13*0.13 -> 65249.641 | G19: =F19-E19+D19 -> 65652.105 | H19: =IF(G19<0,0,G19) -> 65652.105 | I19: =H19*$K$40 -> 2297.8237 | J19: =H19*$K$41 -> 984.78158 | K19: =H19*$K$42 -> 656.52105 | L19: =SUM(I19:K19) -> 3939.1263 | M19: 0 | N19: 0 | O19: ='光伏发电衰减表 输入数据'!E21*'光伏发电衰减表 输入数据'!$P$10/1.13 -> 501920.32 | P19: =C19+O19-$C$39/1.06-$E$39/1.06-M19-N19-L19 -> 482281.71 | Q19: =IF(P19<0,0,P19*$K$43) -> 24114.086 | R19: =SUM(H19+L19) -> 69591.231
B20: 17 | C20: ='光伏发电衰减表 输入数据'!F22*'光伏发电衰减表 输入数据'!$P$6/1.13 -> 19123.575 | D20: =C20*0.13 -> 2486.0647 | E20: =$C$39/1.06*0.06+$E$39/1.06*0.06 -> 2094.3396 | F20: ='光伏发电衰减表 输入数据'!E22*'光伏发电衰减表 输入数据'!$P$10/1.13*0.13 -> 64968.997 | G20: =F20-E20+D20 -> 65360.723 | H20: =IF(G20<0,0,G20) -> 65360.723 | I20: =H20*$K$40 -> 2287.6253 | J20: =H20*$K$41 -> 980.41084 | K20: =H20*$K$42 -> 653.60723 | L20: =SUM(I20:K20) -> 3921.6434 | M20: 0 | N20: 0 | O20: ='光伏发电衰减表 输入数据'!E22*'光伏发电衰减表 输入数据'!$P$10/1.13 -> 499761.52 | P20: =C20+O20-$C$39/1.06-$E$39/1.06-M20-N20-L20 -> 480057.79 | Q20: =IF(P20<0,0,P20*$K$43) -> 24002.889 | R20: =SUM(H20+L20) -> 69282.366
B21: 18 | C21: ='光伏发电衰减表 输入数据'!F23*'光伏发电衰减表 输入数据'!$P$6/1.13 -> 19040.967 | D21: =C21*0.13 -> 2475.3258 | E21: =$C$39/1.06*0.06+$E$39/1.06*0.06 -> 2094.3396 | F21: ='光伏发电衰减表 输入数据'!E23*'光伏发电衰减表 输入数据'!$P$10/1.13*0.13 -> 64688.354 | G21: =F21-E21+D21 -> 65069.34 | H21: =IF(G21<0,0,G21) -> 65069.34 | I21: =H21*$K$40 -> 2277.4269 | J21: =H21*$K$41 -> 976.0401 | K21: =H21*$K$42 -> 650.6934 | L21: =SUM(I21:K21) -> 3904.1604 | M21: 0 | N21: 0 | O21: ='光伏发电衰减表 输入数据'!E23*'光伏发电衰减表 输入数据'!$P$10/1.13 -> 497602.72 | P21: =C21+O21-$C$39/1.06-$E$39/1.06-M21-N21-L21 -> 477833.87 | Q21: =IF(P21<0,0,P21*$K$43) -> 23891.693 | R21: =SUM(H21+L21) -> 68973.5
B22: 19 | C22: ='光伏发电衰减表 输入数据'!F24*'光伏发电衰减表 输入数据'!$P$6/1.13 -> 18958.36 | D22: =C22*0.13 -> 2464.5868 | E22: =$C$39/1.06*0.06+$E$39/1.06*0.06 -> 2094.3396 | F22: ='光伏发电衰减表 输入数据'!E24*'光伏发电衰减表 输入数据'!$P$10/1.13*0.13 -> 64407.71 | G22: =F22-E22+D22 -> 64777.957 | H22: =IF(G22<0,0,G22) -> 64777.957 | I22: =H22*$K$40 -> 2267.2285 | J22: =H22*$K$41 -> 971.66936 | K22: =H22*$K$42 -> 647.77957 | L22: =SUM(I22:K22) -> 3886.6774 | M22: 0 | N22: 0 | O22: ='光伏发电衰减表 输入数据'!E24*'光伏发电衰减表 输入数据'!$P$10/1.13 -> 495443.92 | P22: =C22+O22-$C$39/1.06-$E$39/1.06-M22-N22-L22 -> 475609.95 | Q22: =IF(P22<0,0,P22*$K$43) -> 23780.497 | R22: =SUM(H22+L22) -> 68664.635
B23: 20 | C23: ='光伏发电衰减表 输入数据'!F25*'光伏发电衰减表 输入数据'!$P$6/1.13 -> 18875.753 | D23: =C23*0.13 -> 2453.8479 | E23: =$C$39/1.06*0.06+$E$39/1.06*0.06 -> 2094.3396 | F23: ='光伏发电衰减表 输入数据'!E25*'光伏发电衰减表 输入数据'!$P$10/1.13*0.13 -> 64127.067 | G23: =F23-E23+D23 -> 64486.575 | H23: =IF(G23<0,0,G23) -> 64486.575 | I23: =H23*$K$40 -> 2257.0301 | J23: =H23*$K$41 -> 967.29862 | K23: =H23*$K$42 -> 644.86575 | L23: =SUM(I23:K23) -> 3869.1945 | M23: 0 | N23: 0 | O23: ='光伏发电衰减表 输入数据'!E25*'光伏发电衰减表 输入数据'!$P$10/1.13 -> 493285.13 | P23: =C23+O23-$C$39/1.06-$E$39/1.06-M23-N23-L23 -> 473386.03 | Q23: =IF(P23<0,0,P23*$K$43) -> 23669.301 | R23: =SUM(H23+L23) -> 68355.769
B24: 21 | C24: ='光伏发电衰减表 输入数据'!F26*'光伏发电衰减表 输入数据'!$P$6/1.13 -> 18793.146 | D24: =C24*0.13 -> 2443.1089 | E24: =$C$39/1.06*0.06+$E$39/1.06*0.06 -> 2094.3396 | F24: ='光伏发电衰减表 输入数据'!E26*'光伏发电衰减表 输入数据'!$P$10/1.13*0.13 -> 63846.423 | G24: =F24-E24+D24 -> 64195.192 | H24: =IF(G24<0,0,G24) -> 64195.192 | I24: =H24*$K$40 -> 2246.8317 | J24: =H24*$K$41 -> 962.92788 | K24: =H24*$K$42 -> 641.95192 | L24: =SUM(I24:K24) -> 3851.7115 | M24: 0 | N24: 0 | O24: ='光伏发电衰减表 输入数据'!E26*'光伏发电衰减表 输入数据'!$P$10/1.13 -> 491126.33 | P24: =C24+O24-$C$39/1.06-$E$39/1.06-M24-N24-L24 -> 471162.1 | Q24: =IF(P24<0,0,P24*$K$43) -> 23558.105 | R24: =SUM(H24+L24) -> 68046.904
B25: 22 | C25: ='光伏发电衰减表 输入数据'!F27*'光伏发电衰减表 输入数据'!$P$6/1.13 -> 18710.539 | D25: =C25*0.13 -> 2432.37 | E25: =$C$39/1.06*0.06+$E$39/1.06*0.06 -> 2094.3396 | F25: ='光伏发电衰减表 输入数据'!E27*'光伏发电衰减表 输入数据'!$P$10/1.13*0.13 -> 63565.779 | G25: =F25-E25+D25 -> 63903.81 | H25: =IF(G25<0,0,G25) -> 63903.81 | I25: =H25*$K$40 -> 2236.6333 | J25: =H25*$K$41 -> 958.55715 | K25: =H25*$K$42 -> 639.0381 | L25: =SUM(I25:K25) -> 3834.2286 | M25: 0 | N25: 0 | O25: ='光伏发电衰减表 输入数据'!E27*'光伏发电衰减表 输入数据'!$P$10/1.13 -> 488967.53 | P25: =C25+O25-$C$39/1.06-$E$39/1.06-M25-N25-L25 -> 468938.18 | Q25: =IF(P25<0,0,P25*$K$43) -> 23446.909 | R25: =SUM(H25+L25) -> 67738.038
... B28: 25 | C28: ='光伏发电衰减表 输入数据'!F30*'光伏发电衰减表 输入数据'!$P$6/1.13 -> 18462.717 | D28: =C28*0.13 -> 2400.1532 | E28: =$C$39/1.06*0.06+$E$39/1.06*0.06 -> 2094.3396 | F28: ='光伏发电衰减表 输入数据'!E30*'光伏发电衰减表 输入数据'!$P$10/1.13*0.13 -> 62723.848 | G28: =F28-E28+D28 -> 63029.662 | H28: =IF(G28<0,0,G28) -> 63029.662 | I28: =H28*$K$40 -> 2206.0382 | J28: =H28*$K$41 -> 945.44493 | K28: =H28*$K$42 -> 630.29662 | L28: =SUM(I28:K28) -> 3781.7797 | M28: 0 | N28: 0 | O28: ='光伏发电衰减表 输入数据'!E30*'光伏发电衰减表 输入数据'!$P$10/1.13 -> 482491.14 | P28: =C28+O28-$C$39/1.06-$E$39/1.06-M28-N28-L28 -> 462266.42 | Q28: =IF(P28<0,0,P28*$K$43) -> 23113.321 | R28: =SUM(H28+L28) -> 66811.442
B29: 26 | C29: ='光伏发电衰减表 输入数据'!#REF!*'光伏发电衰减表 输入数据'!$P$6/1.13 -> #REF! | D29: =C29*0.13 -> #REF! | E29: =$C$39/1.06*0.06+$E$39/1.06*0.06 -> 2094.3396 | F29: ='光伏发电衰减表 输入数据'!#REF!*'光伏发电衰减表 输入数据'!$P$10/1.13*0.13 -> #REF! | G29: =F29-E29+D29 -> #REF! | H29: =IF(G29<0,0,G29) -> #REF! | I29: =H29*$K$40 -> #REF! | J29: =H29*$K$41 -> #REF! | K29: =H29*$K$42 -> #REF! | L29: =SUM(I29:K29) -> #REF! | M29: 0 | N29: 0 | O29: ='光伏发电衰减表 输入数据'!#REF!*'光伏发电衰减表 输入数据'!$P$10/1.13 -> #REF! | P29: =C29+O29-$C$39/1.06-$E$39/1.06-M29-N29-L29 -> #REF! | Q29: =IF(P29<0,0,P29*$K$43) -> #REF! | R29: =SUM(H29+L29) -> #REF!
B30: 27 | C30: ='光伏发电衰减表 输入数据'!#REF!*'光伏发电衰减表 输入数据'!$P$6/1.13 -> #REF! | D30: =C30*0.13 -> #REF! | E30: =$C$39/1.06*0.06+$E$39/1.06*0.06 -> 2094.3396 | F30: ='光伏发电衰减表 输入数据'!#REF!*'光伏发电衰减表 输入数据'!$P$10/1.13*0.13 -> #REF! | G30: =F30-E30+D30 -> #REF! | H30: =IF(G30<0,0,G30) -> #REF! | I30: =H30*$K$40 -> #REF! | J30: =H30*$K$41 -> #REF! | K30: =H30*$K$42 -> #REF! | L30: =SUM(I30:K30) -> #REF! | M30: 0 | N30: 0 | O30: ='光伏发电衰减表 输入数据'!#REF!*'光伏发电衰减表 输入数据'!$P$10/1.13 -> #REF! | P30: =C30+O30-$C$39/1.06-$E$39/1.06-M30-N30-L30 -> #REF! | Q30: =IF(P30<0,0,P30*$K$43) -> #REF! | R30: =SUM(H30+L30) -> #REF!
B31: 28 | C31: ='光伏发电衰减表 输入数据'!#REF!*'光伏发电衰减表 输入数据'!$P$6/1.13 -> #REF! | D31: =C31*0.13 -> #REF! | E31: =$C$39/1.06*0.06+$E$39/1.06*0.06 -> 2094.3396 | F31: ='光伏发电衰减表 输入数据'!#REF!*'光伏发电衰减表 输入数据'!$P$10/1.13*0.13 -> #REF! | G31: =F31-E31+D31 -> #REF! | H31: =IF(G31<0,0,G31) -> #REF! | I31: =H31*$K$40 -> #REF! | J31: =H31*$K$41 -> #REF! | K31: =H31*$K$42 -> #REF! | L31: =SUM(I31:K31) -> #REF! | M31: 0 | N31: 0 | O31: ='光伏发电衰减表 输入数据'!#REF!*'光伏发电衰减表 输入数据'!$P$10/1.13 -> #REF! | P31: =C31+O31-$C$39/1.06-$E$39/1.06-M31-N31-L31 -> #REF! | Q31: =IF(P31<0,0,P31*$K$43) -> #REF! | R31: =SUM(H31+L31) -> #REF!
B32: 29 | C32: ='光伏发电衰减表 输入数据'!#REF!*'光伏发电衰减表 输入数据'!$P$6/1.13 -> #REF! | D32: =C32*0.13 -> #REF! | E32: =$C$39/1.06*0.06+$E$39/1.06*0.06 -> 2094.3396 | F32: ='光伏发电衰减表 输入数据'!#REF!*'光伏发电衰减表 输入数据'!$P$10/1.13*0.13 -> #REF! | G32: =F32-E32+D32 -> #REF! | H32: =IF(G32<0,0,G32) -> #REF! | I32: =H32*$K$40 -> #REF! | J32: =H32*$K$41 -> #REF! | K32: =H32*$K$42 -> #REF! | L32: =SUM(I32:K32) -> #REF! | M32: 0 | N32: 0 | O32: ='光伏发电衰减表 输入数据'!#REF!*'光伏发电衰减表 输入数据'!$P$10/1.13 -> #REF! | P32: =C32+O32-$C$39/1.06-$E$39/1.06-M32-N32-L32 -> #REF! | Q32: =IF(P32<0,0,P32*$K$43) -> #REF! | R32: =SUM(H32+L32) -> #REF!
B33: 30 | C33: ='光伏发电衰减表 输入数据'!#REF!*'光伏发电衰减表 输入数据'!$P$6/1.13 -> #REF! | D33: =C33*0.13 -> #REF! | E33: =$C$39/1.06*0.06+$E$39/1.06*0.06 -> 2094.3396 | F33: ='光伏发电衰减表 输入数据'!#REF!*'光伏发电衰减表 输入数据'!$P$10/1.13*0.13 -> #REF! | G33: =F33-E33+D33 -> #REF! | H33: =IF(G33<0,0,G33) -> #REF! | I33: =H33*$K$40 -> #REF! | J33: =H33*$K$41 -> #REF! | K33: =H33*$K$42 -> #REF! | L33: =SUM(I33:K33) -> #REF! | M33: 0 | N33: 0 | O33: ='光伏发电衰减表 输入数据'!#REF!*'光伏发电衰减表 输入数据'!$P$10/1.13 -> #REF! | P33: =C33+O33-$C$39/1.06-$E$39/1.06-M33-N33-L33 -> #REF! | Q33: =IF(P33<0,0,P33*$K$43) -> #REF! | R33: =SUM(H33+L33) -> #REF!
B34: 合计 | G34: 增值税总额 | H34: =SUM(H4:H33) -> #REF! | K34: 税金及附加总额 | L34: =SUM(L4:L33) -> #REF! | P34: 所得税合计 | Q34: =SUM(Q4:Q33) -> #REF! | R34: =SUM(H34+L34+Q34) -> #REF!
G35: 注：消纳电量×全年平均电价÷1.13×0.13=原本在税局产生的可抵扣部分（损失）
G36: 造价产生可抵扣增值税，以这两部分差额起算
B38: 工程造价（含税） | C38: =基础数据!H7 -> 2000000 | H38: 名称 | J38: 原税率（%） | K38: 税率 | L38: 备注
B39: 运维费用 | C39: =基础数据!J29 -> 30000 | D39: 保险费用 | E39: =基础数据!J27 -> 7000 | H39: 增值税及附加税费 | I39: 增值税率 | J39: 0.09 | K39: =J39 -> 0.09 | L39: /
I40: 城市维护建设税率 | J40: 0.07 | K40: =J40*0.5 -> 0.035 | L40: （小微企业减征50%）
B41: 工程造价（不含税） | C41: =C38/1.09 -> 1834862.4 | D41: 造价留抵进项税 | E41: =C41*0.09 -> 165137.61 | I41: 教育费附加税率 | J41: 0.03 | K41: =J41*0.5 -> 0.015
I42: 地方教育附加 | J42: 0.02 | K42: =J42*0.5 -> 0.01
H43: 所得税 | I43: 所得税率 | J43: 0.25 | K43: 0.05 | L43: 小微企业5%
B44: 假设运维保险都开专票
...

Sheet 资金成本参数（新）
D2: 等额本金
A3: 贷款总额（元） | B3: 1000000 | D3: 年份 | E3: 剩余应计算利息的本金（元） | G3: 每期应还利息（元） | H3: 资金成本合计
A4: 贷款年化利率 | B4: 0.036 | D4: 1 | E4: 0 | F4: =B3 -> 1000000 | G4: =F4*$B$4 -> 36000 | H4: =G4 -> 36000
A5: 贷款期限（年） | B5: 5 | D5: 2 | E5: =$B$9 -> 200000 | F5: =F4-E5 -> 800000 | G5: =F5*$B$4 -> 28800 | H5: =G5 -> 28800
A6: 还款 | B6: 一年还一次 | D6: 3 | E6: =$B$9 -> 200000 | F6: =F5-E6 -> 600000 | G6: =F6*$B$4 -> 21600 | H6: =G6 -> 21600
D7: 4 | E7: =$B$9 -> 200000 | F7: =F6-E7 -> 400000 | G7: =F7*$B$4 -> 14400 | H7: =G7 -> 14400
A8: 等额本金 | D8: 5 | E8: =$B$9 -> 200000 | F8: =F7-E8 -> 200000 | G8: =F8*$B$4 -> 7200 | H8: =G8 -> 7200
A9: 每期应还本金（元） | B9: =B3/B5 -> 200000 | D9: 6
D10: 7
D11: 8
A12: *约定的利率未超过合同成立时一年期贷款市场报价利率四倍，受法律保护 | D12: 9
D13: 10
D14: 11
D15: 12
D16: 13
D17: 14
D18: 15
D19: 16
D20: 17
D21: 18
D22: 19
D23: 20

Sheet 光伏发电衰减表min EMC
K1: 每年除去七、八、九月 平均电价计算（元/KW.h）
B2: 年发电量预估（理论最小值） | E2: 业主消纳率 | F2: 余电上网率 | K2: 供电局购电价 | L2: 尖电电价 | M2: 峰电电价 | N2: 平段电价 | O2: 谷电电价 | P2: 输配电费（尖） | Q2: 输配电费（峰） | R2: 输配电费（平） | S2: 基金及附加费
B3: 年份 | C3: 系统发电效率(%) | D3: 发电量（度） | E3: =消纳率参数!K31 -> 0 | F3: =1-E3 -> 1 | G3: 节能效益（元） | H3: 月平均发电量（度） | J3: 余电上网电价（元） | L3: =光伏发电衰减表min!L3 -> 1.4773 | M3: =光伏发电衰减表min!M3 -> 1.1872 | N3: =光伏发电衰减表min!N3 -> 0.7097 | O3: 忽略 | P3: 0 | Q3: 0 | R3: 0 | S3: 0
B4: 1 | C4: 0.99 | D4: =$J$10*C4 -> #REF! | E4: =D4*E3 -> #REF! | F4: =D4*F3 -> #REF! | G4: =$J$12*C4*$E$3*$L$8*(1-$J$6)+$J$14*C4*$E$3*$L$17*(1-$J$6) -> #REF! | H4: =D4/12 -> #REF! | J4: 0.453 | K4: 光伏发电电价 | L4: 尖电电价 | M4: 峰电电价 | N4: 平段电价 | O4: 谷电电价
B5: 2 | C5: =C4-0.004 -> 0.986 | D5: =$J$10*C5 -> #REF! | E5: =D5*$E$3 -> #REF! | F5: =D5*$F$3 -> #REF! | G5: =$J$12*C5*$E$3*$L$8*(1-$J$6)+$J$14*C5*$E$3*$L$17*(1-$J$6) -> #REF! | H5: =D5/12 -> #REF! | J5: 电价折扣（EMC） | L5: =L3+P3+S3 -> 1.4773 | M5: =M3+Q3+S3 -> 1.1872 | N5: =N3+R3+S3 -> 0.7097 | O5: 忽略
B6: 3 | C6: =C5-0.004 -> 0.982 | D6: =$J$10*C6 -> #REF! | E6: =D6*$E$3 -> #REF! | F6: =D6*$F$3 -> #REF! | G6: =$J$12*C6*$E$3*$L$8*(1-$J$6)+$J$14*C6*$E$3*$L$17*(1-$J$6) -> #REF! | H6: =D6/12 -> #REF! | J6: 0.9 | L6: 加权系数 | M6: 加权系数 | N6: 加权系数 | O6: 加权系数 | P6: 合计时段
B7: 4 | C7: =C6-0.004 -> 0.978 | D7: =$J$10*C7 -> #REF! | E7: =D7*$E$3 -> #REF! | F7: =D7*$F$3 -> #REF! | G7: =$J$12*C7*$E$3*$L$8*(1-$J$6)+$J$14*C7*$E$3*$L$17*(1-$J$6) -> #REF! | H7: =D7/12 -> #REF! | J7: 全年平均电价 | L7: 0 | M7: 5 | N7: 4 | O7: 0 | P7: 9
B8: 5 | C8: =C7-0.004 -> 0.974 | D8: =$J$10*C8 -> #REF! | E8: =D8*$E$3 -> #REF! | F8: =D8*$F$3 -> #REF! | G8: =$J$12*C8*$E$3*$L$8*(1-$J$6)+$J$14*C8*$E$3*$L$17*(1-$J$6) -> #REF! | H8: =D8/12 -> #REF! | J8: =(L8*9+L17*3)/12 -> 0.99915278 | K8: 加权后平均电价 | L8: =(M5*M7+N5*N7)/P7 -> 0.97497778
B9: 6 | C9: =C8-0.004 -> 0.97 | D9: =$J$10*C9 -> #REF! | E9: =D9*$E$3 -> #REF! | F9: =D9*$F$3 -> #REF! | G9: =$J$12*C9*$E$3*$L$8*(1-$J$6)+$J$14*C9*$E$3*$L$17*(1-$J$6) -> #REF! | H9: =D9/12 -> #REF! | J9: 首年发电量
B10: 7 | C10: =C9-0.004 -> 0.966 | D10: =$J$10*C10 -> #REF! | E10: =D10*$E$3 -> #REF! | F10: =D10*$F$3 -> #REF! | G10: =$J$12*C10*$E$3*$L$8*(1-$J$6)+$J$14*C10*$E$3*$L$17*(1-$J$6) -> #REF! | H10: =D10/12 -> #REF! | J10: =J12+J14 -> #REF! | K10: 每年七、八、九月 平均电价计算（元/KW.h）
B11: 8 | C11: =C10-0.004 -> 0.962 | D11: =$J$10*C11 -> #REF! | E11: =D11*$E$3 -> #REF! | F11: =D11*$F$3 -> #REF! | G11: =$J$12*C11*$E$3*$L$8*(1-$J$6)+$J$14*C11*$E$3*$L$17*(1-$J$6) -> #REF! | H11: =D11/12 -> #REF! | J11: 首年除七、八、九月的发电总量 | K11: 供电局购电价 | L11: 尖电电价 | M11: 峰电电价 | N11: 平段电价 | O11: 谷电电价 | P11: 输配电费（尖） | Q11: 输配电费（峰） | R11: 输配电费（平） | S11: 基金及附加费
B12: 9 | C12: =C11-0.004 -> 0.958 | D12: =$J$10*C12 -> #REF! | E12: =D12*$E$3 -> #REF! | F12: =D12*$F$3 -> #REF! | G12: =$J$12*C12*$E$3*$L$8*(1-$J$6)+$J$14*C12*$E$3*$L$17*(1-$J$6) -> #REF! | H12: =D12/12 -> #REF! | J12: =M21+M22+M23+M24+M25+M26+M30+M31+M32 -> #REF! | L12: =L3 -> 1.4773 | M12: =M3 -> 1.1872 | N12: =N3 -> 0.7097 | O12: =O3 -> 忽略 | P12: 0 | Q12: 0 | R12: 0 | S12: 0
B13: 10 | C13: =C12-0.004 -> 0.954 | D13: =$J$10*C13 -> #REF! | E13: =D13*$E$3 -> #REF! | F13: =D13*$F$3 -> #REF! | G13: =$J$12*C13*$E$3*$L$8*(1-$J$6)+$J$14*C13*$E$3*$L$17*(1-$J$6) -> #REF! | H13: =D13/12 -> #REF! | J13: 首年七、八、九月发电总量 | K13: 光伏发电电价 | L13: 尖电电价 | M13: 峰电电价 | N13: 平段电价 | O13: 谷电电价
B14: 11 | C14: =C13-0.004 -> 0.95 | D14: =$J$10*C14 -> #REF! | E14: =D14*$E$3 -> #REF! | F14: =D14*$F$3 -> #REF! | G14: =$J$12*C14*$E$3*$L$8*(1-$J$6)+$J$14*C14*$E$3*$L$17*(1-$J$6) -> #REF! | H14: =D14/12 -> #REF! | J14: =M27+M28+M29 -> #REF! | L14: =L12+P12+S12 -> 1.4773 | M14: =M12+Q12+S12 -> 1.1872 | N14: =N12+R12+S12 -> 0.7097 | O14: 忽略
B15: 12 | C15: =C14-0.004 -> 0.946 | D15: =$J$10*C15 -> #REF! | E15: =D15*$E$3 -> #REF! | F15: =D15*$F$3 -> #REF! | G15: =$J$12*C15*$E$3*$L$8*(1-$J$6)+$J$14*C15*$E$3*$L$17*(1-$J$6) -> #REF! | H15: =D15/12 -> #REF! | L15: 加权系数 | M15: 加权系数 | N15: 加权系数 | O15: 加权系数 | P15: 合计时段
B16: 13 | C16: =C15-0.004 -> 0.942 | D16: =$J$10*C16 -> #REF! | E16: =D16*$E$3 -> #REF! | F16: =D16*$F$3 -> #REF! | G16: =$J$12*C16*$E$3*$L$8*(1-$J$6)+$J$14*C16*$E$3*$L$17*(1-$J$6) -> #REF! | H16: =D16/12 -> #REF! | L16: 3 | M16: 2 | N16: 4 | O16: 0 | P16: 9
B17: 14 | C17: =C16-0.004 -> 0.938 | D17: =$J$10*C17 -> #REF! | E17: =D17*$E$3 -> #REF! | F17: =D17*$F$3 -> #REF! | G17: =$J$12*C17*$E$3*$L$8*(1-$J$6)+$J$14*C17*$E$3*$L$17*(1-$J$6) -> #REF! | H17: =D17/12 -> #REF! | K17: 加权后平均电价 | L17: =(L14*L16+M14*M16+N14*N16)/P16 -> 1.0716778
B18: 15 | C18: =C17-0.004 -> 0.934 | D18: =$J$10*C18 -> #REF! | E18: =D18*$E$3 -> #REF! | F18: =D18*$F$3 -> #REF! | G18: =$J$12*C18*$E$3*$L$8*(1-$J$6)+$J$14*C18*$E$3*$L$17*(1-$J$6) -> #REF! | H18: =D18/12 -> #REF!
B19: 16 | C19: =C18-0.004 -> 0.93 | D19: =$J$10*C19 -> #REF! | E19: =D19*$E$3 -> #REF! | F19: =D19*$F$3 -> #REF! | G19: =$J$12*C19*$E$3*$L$8*(1-$J$6)+$J$14*C19*$E$3*$L$17*(1-$J$6) -> #REF! | H19: =D19/12 -> #REF! | K19: 首年预计发电量（KW.h）
B20: 17 | C20: =C19-0.004 -> 0.926 | D20: =$J$10*C20 -> #REF! | E20: =D20*$E$3 -> #REF! | F20: =D20*$F$3 -> #REF! | G20: =$J$12*C20*$E$3*$L$8*(1-$J$6)+$J$14*C20*$E$3*$L$17*(1-$J$6) -> #REF! | H20: =D20/12 -> #REF! | K20: 月份 | M20: 月发电量
B21: 18 | C21: =C20-0.004 -> 0.922 | D21: =$J$10*C21 -> #REF! | E21: =D21*$E$3 -> #REF! | F21: =D21*$F$3 -> #REF! | G21: =$J$12*C21*$E$3*$L$8*(1-$J$6)+$J$14*C21*$E$3*$L$17*(1-$J$6) -> #REF! | H21: =D21/12 -> #REF! | K21: 1月 | M21: =基础数据!#REF! -> #REF!
B22: 19 | C22: =C21-0.004 -> 0.918 | D22: =$J$10*C22 -> #REF! | E22: =D22*$E$3 -> #REF! | F22: =D22*$F$3 -> #REF! | G22: =$J$12*C22*$E$3*$L$8*(1-$J$6)+$J$14*C22*$E$3*$L$17*(1-$J$6) -> #REF! | H22: =D22/12 -> #REF! | K22: 2月 | M22: =基础数据!#REF! -> #REF!
B23: 20 | C23: =C22-0.004 -> 0.914 | D23: =$J$10*C23 -> #REF! | E23: =D23*$E$3 -> #REF! | F23: =D23*$F$3 -> #REF! | G23: =$J$12*C23*$E$3*$L$8*(1-$J$6)+$J$14*C23*$E$3*$L$17*(1-$J$6) -> #REF! | H23: =D23/12 -> #REF! | K23: 3月 | M23: =基础数据!#REF! -> #REF!
B24: 21 | C24: =C23-0.004 -> 0.91 | D24: =$J$10*C24 -> #REF! | E24: =D24*$E$3 -> #REF! | F24: =D24*$F$3 -> #REF! | G24: =$J$12*C24*$E$3*$L$8*(1-$J$6)+$J$14*C24*$E$3*$L$17*(1-$J$6) -> #REF! | H24: =D24/12 -> #REF! | K24: 4月 | M24: =基础数据!#REF! -> #REF!
B25: 22 | C25: =C24-0.004 -> 0.906 | D25: =$J$10*C25 -> #REF! | E25: =D25*$E$3 -> #REF! | F25: =D25*$F$3 -> #REF! | G25: =$J$12*C25*$E$3*$L$8*(1-$J$6)+$J$14*C25*$E$3*$L$17*(1-$J$6) -> #REF! | H25: =D25/12 -> #REF! | K25: 5月 | M25: =基础数据!#REF! -> #REF!
B26: 23 | C26: =C25-0.004 -> 0.902 | D26: =$J$10*C26 -> #REF! | E26: =D26*$E$3 -> #REF! | F26: =D26*$F$3 -> #REF! | G26: =$J$12*C26*$E$3*$L$8*(1-$J$6)+$J$14*C26*$E$3*$L$17*(1-$J$6) -> #REF! | H26: =D26/12 -> #REF! | K26: 6月 | M26: =基础数据!#REF! -> #REF!
B27: 24 | C27: =C26-0.004 -> 0.898 | D27: =$J$10*C27 -> #REF! | E27: =D27*$E$3 -> #REF! | F27: =D27*$F$3 -> #REF! | G27: =$J$12*C27*$E$3*$L$8*(1-$J$6)+$J$14*C27*$E$3*$L$17*(1-$J$6) -> #REF! | H27: =D27/12 -> #REF! | K27: 7月 | M27: =基础数据!#REF! -> #REF!
B28: 25 | C28: =C27-0.004 -> 0.894 | D28: =$J$10*C28 -> #REF! | E28: =D28*$E$3 -> #REF! | F28: =D28*$F$3 -> #REF! | G28: =$J$12*C28*$E$3*$L$8*(1-$J$6)+$J$14*C28*$E$3*$L$17*(1-$J$6) -> #REF! | H28: =D28/12 -> #REF! | K28: 8月 | M28: =基础数据!#REF! -> #REF!
B29: 26 | C29: =C28-0.004 -> 0.89 | D29: =$J$10*C29 -> #REF! | E29: =D29*$E$3 -> #REF! | F29: =D29*$F$3 -> #REF! | G29: =$J$12*C29*$E$3*$L$8*(1-$J$6)+$J$14*C29*$E$3*$L$17*(1-$J$6) -> #REF! | H29: =D29/12 -> #REF! | K29: 9月 | M29: =基础数据!#REF! -> #REF!
B30: 27 | C30: =C29-0.004 -> 0.886 | D30: =$J$10*C30 -> #REF! | E30: =D30*$E$3 -> #REF! | F30: =D30*$F$3 -> #REF! | G30: =$J$12*C30*$E$3*$L$8*(1-$J$6)+$J$14*C30*$E$3*$L$17*(1-$J$6) -> #REF! | H30: =D30/12 -> #REF! | K30: 10月 | M30: =基础数据!#REF! -> #REF!
B31: 28 | C31: =C30-0.004 -> 0.882 | D31: =$J$10*C31 -> #REF! | E31: =D31*$E$3 -> #REF! | F31: =D31*$F$3 -> #REF! | G31: =$J$12*C31*$E$3*$L$8*(1-$J$6)+$J$14*C31*$E$3*$L$17*(1-$J$6) -> #REF! | H31: =D31/12 -> #REF! | K31: 11月 | M31: =基础数据!#REF! -> #REF!
B32: 29 | C32: =C31-0.004 -> 0.878 | D32: =$J$10*C32 -> #REF! | E32: =D32*$E$3 -> #REF! | F32: =D32*$F$3 -> #REF! | G32: =$J$12*C32*$E$3*$L$8*(1-$J$6)+$J$14*C32*$E$3*$L$17*(1-$J$6) -> #REF! | H32: =D32/12 -> #REF! | K32: 12月 | M32: =基础数据!#REF! -> #REF!
B33: 30 | C33: =C32-0.004 -> 0.874 | D33: =$J$10*C33 -> #REF! | E33: =D33*$E$3 -> #REF! | F33: =D33*$F$3 -> #REF! | G33: =$J$12*C33*$E$3*$L$8*(1-$J$6)+$J$14*C33*$E$3*$L$17*(1-$J$6) -> #REF! | H33: =D33/12 -> #REF!
B34: 合计 | D34: =SUM(D4:D33) -> #REF! | E34: =SUM(E4:E33) -> #REF! | F34: =SUM(F4:F33) -> #REF! | G34: =SUM(G4:G33) -> #REF!
A35: .

Sheet 光伏发电衰减表 理论均值 EMC
K1: 每年除去七、八、九月 平均电价计算（元/KW.h）
B2: 年发电量预估（理论平均值） | E2: 业主消纳率 | F2: 余电上网率 | K2: 供电局购电价 | L2: 尖电电价 | M2: 峰电电价 | N2: 平段电价 | O2: 谷电电价 | P2: 输配电费（尖） | Q2: 输配电费（峰） | R2: 输配电费（平） | S2: 基金及附加费
B3: 年份 | C3: 系统发电效率(%) | D3: 发电量（度） | E3: 0 | F3: =1-E3 -> 1 | G3: 节能效益（元） | H3: 月平均发电量（度） | J3: 余电上网电价（元） | L3: =光伏发电衰减表min!L3 -> 1.4773 | M3: =光伏发电衰减表min!M3 -> 1.1872 | N3: =光伏发电衰减表min!N3 -> 0.7097 | O3: 忽略 | P3: =光伏发电衰减表min!P3 -> 0 | Q3: =光伏发电衰减表min!Q3 -> 0 | R3: =光伏发电衰减表min!R3 -> 0 | S3: =光伏发电衰减表min!S3 -> 0
B4: 1 | C4: 0.99 | D4: =$J$10*C4 -> #REF! | E4: =D4*E3 -> #REF! | F4: =D4*F3 -> #REF! | G4: =$J$12*C4*$E$3*$L$8*(1-$J$6)+$J$14*C4*$E$3*$L$17*(1-$J$6) -> #REF! | H4: =D4/12 -> #REF! | J4: 0.453 | K4: 光伏发电电价 | L4: 尖电电价 | M4: 峰电电价 | N4: 平段电价 | O4: 谷电电价
B5: 2 | C5: =C4-0.004 -> 0.986 | D5: =$J$10*C5 -> #REF! | E5: =D5*$E$3 -> #REF! | F5: =D5*$F$3 -> #REF! | G5: =$J$12*C5*$E$3*$L$8*(1-$J$6)+$J$14*C5*$E$3*$L$17*(1-$J$6) -> #REF! | H5: =D5/12 -> #REF! | J5: 折扣 | L5: =L3+P3+S3 -> 1.4773 | M5: =M3+Q3+S3 -> 1.1872 | N5: =N3+R3+S3 -> 0.7097 | O5: 忽略
B6: 3 | C6: =C5-0.004 -> 0.982 | D6: =$J$10*C6 -> #REF! | E6: =D6*$E$3 -> #REF! | F6: =D6*$F$3 -> #REF! | G6: =$J$12*C6*$E$3*$L$8*(1-$J$6)+$J$14*C6*$E$3*$L$17*(1-$J$6) -> #REF! | H6: =D6/12 -> #REF! | J6: 0.85 | L6: 加权系数 | M6: 加权系数 | N6: 加权系数 | O6: 加权系数 | P6: 合计时段
B7: 4 | C7: =C6-0.004 -> 0.978 | D7: =$J$10*C7 -> #REF! | E7: =D7*$E$3 -> #REF! | F7: =D7*$F$3 -> #REF! | G7: =$J$12*C7*$E$3*$L$8*(1-$J$6)+$J$14*C7*$E$3*$L$17*(1-$J$6) -> #REF! | H7: =D7/12 -> #REF! | J7: 全年平均电价 | L7: 0 | M7: 5 | N7: 4 | O7: 0 | P7: 9
B8: 5 | C8: =C7-0.004 -> 0.974 | D8: =$J$10*C8 -> #REF! | E8: =D8*$E$3 -> #REF! | F8: =D8*$F$3 -> #REF! | G8: =$J$12*C8*$E$3*$L$8*(1-$J$6)+$J$14*C8*$E$3*$L$17*(1-$J$6) -> #REF! | H8: =D8/12 -> #REF! | J8: =(L8*9+L17*3)/12 -> 0.99915278 | K8: 加权后平均电价 | L8: =(M5*M7+N5*N7)/P7 -> 0.97497778
B9: 6 | C9: =C8-0.004 -> 0.97 | D9: =$J$10*C9 -> #REF! | E9: =D9*$E$3 -> #REF! | F9: =D9*$F$3 -> #REF! | G9: =$J$12*C9*$E$3*$L$8*(1-$J$6)+$J$14*C9*$E$3*$L$17*(1-$J$6) -> #REF! | H9: =D9/12 -> #REF! | J9: 首年发电量
B10: 7 | C10: =C9-0.004 -> 0.966 | D10: =$J$10*C10 -> #REF! | E10: =D10*$E$3 -> #REF! | F10: =D10*$F$3 -> #REF! | G10: =$J$12*C10*$E$3*$L$8*(1-$J$6)+$J$14*C10*$E$3*$L$17*(1-$J$6) -> #REF! | H10: =D10/12 -> #REF! | J10: =J12+J14 -> #REF! | K10: 每年七、八、九月 平均电价计算（元/KW.h）
B11: 8 | C11: =C10-0.004 -> 0.962 | D11: =$J$10*C11 -> #REF! | E11: =D11*$E$3 -> #REF! | F11: =D11*$F$3 -> #REF! | G11: =$J$12*C11*$E$3*$L$8*(1-$J$6)+$J$14*C11*$E$3*$L$17*(1-$J$6) -> #REF! | H11: =D11/12 -> #REF! | J11: 首年除七、八、九月的发电总量 | K11: 供电局购电价 | L11: 尖电电价 | M11: 峰电电价 | N11: 平段电价 | O11: 谷电电价 | P11: 输配电费（尖） | Q11: 输配电费（峰） | R11: 输配电费（平） | S11: 基金及附加费
B12: 9 | C12: =C11-0.004 -> 0.958 | D12: =$J$10*C12 -> #REF! | E12: =D12*$E$3 -> #REF! | F12: =D12*$F$3 -> #REF! | G12: =$J$12*C12*$E$3*$L$8*(1-$J$6)+$J$14*C12*$E$3*$L$17*(1-$J$6) -> #REF! | H12: =D12/12 -> #REF! | J12: =M21+M22+M23+M24+M25+M26+M30+M31+M32 -> #REF! | L12: =L3 -> 1.4773 | M12: =M3 -> 1.1872 | N12: =N3 -> 0.7097 | O12: =O3 -> 忽略 | P12: =光伏发电衰减表min!P12 -> 0 | Q12: =光伏发电衰减表min!Q12 -> 0 | R12: =光伏发电衰减表min!R12 -> 0 | S12: =光伏发电衰减表min!S12 -> 0
B13: 10 | C13: =C12-0.004 -> 0.954 | D13: =$J$10*C13 -> #REF! | E13: =D13*$E$3 -> #REF! | F13: =D13*$F$3 -> #REF! | G13: =$J$12*C13*$E$3*$L$8*(1-$J$6)+$J$14*C13*$E$3*$L$17*(1-$J$6) -> #REF! | H13: =D13/12 -> #REF! | J13: 首年七、八、九月发电总量 | K13: 光伏发电电价 | L13: 尖电电价 | M13: 峰电电价 | N13: 平段电价 | O13: 谷电电价
B14: 11 | C14: =C13-0.004 -> 0.95 | D14: =$J$10*C14 -> #REF! | E14: =D14*$E$3 -> #REF! | F14: =D14*$F$3 -> #REF! | G14: =$J$12*C14*$E$3*$L$8*(1-$J$6)+$J$14*C14*$E$3*$L$17*(1-$J$6) -> #REF! | H14: =D14/12 -> #REF! | J14: =M27+M28+M29 -> #REF! | L14: =L12+P12+S12 -> 1.4773 | M14: =M12+Q12+S12 -> 1.1872 | N14: =N12+R12+S12 -> 0.7097 | O14: 忽略
B15: 12 | C15: =C14-0.004 -> 0.946 | D15: =$J$10*C15 -> #REF! | E15: =D15*$E$3 -> #REF! | F15: =D15*$F$3 -> #REF! | G15: =$J$12*C15*$E$3*$L$8*(1-$J$6)+$J$14*C15*$E$3*$L$17*(1-$J$6) -> #REF! | H15: =D15/12 -> #REF! | L15: 加权系数 | M15: 加权系数 | N15: 加权系数 | O15: 加权系数 | P15: 合计时段
B16: 13 | C16: =C15-0.004 -> 0.942 | D16: =$J$10*C16 -> #REF! | E16: =D16*$E$3 -> #REF! | F16: =D16*$F$3 -> #REF! | G16: =$J$12*C16*$E$3*$L$8*(1-$J$6)+$J$14*C16*$E$3*$L$17*(1-$J$6) -> #REF! | H16: =D16/12 -> #REF! | L16: 3 | M16: 2 | N16: 4 | O16: 0 | P16: 9
B17: 14 | C17: =C16-0.004 -> 0.938 | D17: =$J$10*C17 -> #REF! | E17: =D17*$E$3 -> #REF! | F17: =D17*$F$3 -> #REF! | G17: =$J$12*C17*$E$3*$L$8*(1-$J$6)+$J$14*C17*$E$3*$L$17*(1-$J$6) -> #REF! | H17: =D17/12 -> #REF! | K17: 加权后平均电价 | L17: =(L14*L16+M14*M16+N14*N16)/P16 -> 1.0716778
B18: 15 | C18: =C17-0.004 -> 0.934 | D18: =$J$10*C18 -> #REF! | E18: =D18*$E$3 -> #REF! | F18: =D18*$F$3 -> #REF! | G18: =$J$12*C18*$E$3*$L$8*(1-$J$6)+$J$14*C18*$E$3*$L$17*(1-$J$6) -> #REF! | H18: =D18/12 -> #REF!
B19: 16 | C19: =C18-0.004 -> 0.93 | D19: =$J$10*C19 -> #REF! | E19: =D19*$E$3 -> #REF! | F19: =D19*$F$3 -> #REF! | G19: =$J$12*C19*$E$3*$L$8*(1-$J$6)+$J$14*C19*$E$3*$L$17*(1-$J$6) -> #REF! | H19: =D19/12 -> #REF! | K19: 首年预计发电量（KW.h）
B20: 17 | C20: =C19-0.004 -> 0.926 | D20: =$J$10*C20 -> #REF! | E20: =D20*$E$3 -> #REF! | F20: =D20*$F$3 -> #REF! | G20: =$J$12*C20*$E$3*$L$8*(1-$J$6)+$J$14*C20*$E$3*$L$17*(1-$J$6) -> #REF! | H20: =D20/12 -> #REF! | K20: 月份 | M20: 月发电量
B21: 18 | C21: =C20-0.004 -> 0.922 | D21: =$J$10*C21 -> #REF! | E21: =D21*$E$3 -> #REF! | F21: =D21*$F$3 -> #REF! | G21: =$J$12*C21*$E$3*$L$8*(1-$J$6)+$J$14*C21*$E$3*$L$17*(1-$J$6) -> #REF! | H21: =D21/12 -> #REF! | K21: 1月 | M21: =基础数据!#REF! -> #REF!
B22: 19 | C22: =C21-0.004 -> 0.918 | D22: =$J$10*C22 -> #REF! | E22: =D22*$E$3 -> #REF! | F22: =D22*$F$3 -> #REF! | G22: =$J$12*C22*$E$3*$L$8*(1-$J$6)+$J$14*C22*$E$3*$L$17*(1-$J$6) -> #REF! | H22: =D22/12 -> #REF! | K22: 2月 | M22: =基础数据!#REF! -> #REF!
B23: 20 | C23: =C22-0.004 -> 0.914 | D23: =$J$10*C23 -> #REF! | E23: =D23*$E$3 -> #REF! | F23: =D23*$F$3 -> #REF! | G23: =$J$12*C23*$E$3*$L$8*(1-$J$6)+$J$14*C23*$E$3*$L$17*(1-$J$6) -> #REF! | H23: =D23/12 -> #REF! | K23: 3月 | M23: =基础数据!#REF! -> #REF!
B24: 21 | C24: =C23-0.004 -> 0.91 | D24: =$J$10*C24 -> #REF! | E24: =D24*$E$3 -> #REF! | F24: =D24*$F$3 -> #REF! | G24: =$J$12*C24*$E$3*$L$8*(1-$J$6)+$J$14*C24*$E$3*$L$17*(1-$J$6) -> #REF! | H24: =D24/12 -> #REF! | K24: 4月 | M24: =基础数据!#REF! -> #REF!
B25: 22 | C25: =C24-0.004 -> 0.906 | D25: =$J$10*C25 -> #REF! | E25: =D25*$E$3 -> #REF! | F25: =D25*$F$3 -> #REF! | G25: =$J$12*C25*$E$3*$L$8*(1-$J$6)+$J$14*C25*$E$3*$L$17*(1-$J$6) -> #REF! | H25: =D25/12 -> #REF! | K25: 5月 | M25: =基础数据!#REF! -> #REF!
B26: 23 | C26: =C25-0.004 -> 0.902 | D26: =$J$10*C26 -> #REF! | E26: =D26*$E$3 -> #REF! | F26: =D26*$F$3 -> #REF! | G26: =$J$12*C26*$E$3*$L$8*(1-$J$6)+$J$14*C26*$E$3*$L$17*(1-$J$6) -> #REF! | H26: =D26/12 -> #REF! | K26: 6月 | M26: =基础数据!#REF! -> #REF!
B27: 24 | C27: =C26-0.004 -> 0.898 | D27: =$J$10*C27 -> #REF! | E27: =D27*$E$3 -> #REF! | F27: =D27*$F$3 -> #REF! | G27: =$J$12*C27*$E$3*$L$8*(1-$J$6)+$J$14*C27*$E$3*$L$17*(1-$J$6) -> #REF! | H27: =D27/12 -> #REF! | K27: 7月 | M27: =基础数据!#REF! -> #REF!
B28: 25 | C28: =C27-0.004 -> 0.894 | D28: =$J$10*C28 -> #REF! | E28: =D28*$E$3 -> #REF! | F28: =D28*$F$3 -> #REF! | G28: =$J$12*C28*$E$3*$L$8*(1-$J$6)+$J$14*C28*$E$3*$L$17*(1-$J$6) -> #REF! | H28: =D28/12 -> #REF! | K28: 8月 | M28: =基础数据!#REF! -> #REF!
B29: 26 | C29: =C28-0.004 -> 0.89 | D29: =$J$10*C29 -> #REF! | E29: =D29*$E$3 -> #REF! | F29: =D29*$F$3 -> #REF! | G29: =$J$12*C29*$E$3*$L$8*(1-$J$6)+$J$14*C29*$E$3*$L$17*(1-$J$6) -> #REF! | H29: =D29/12 -> #REF! | K29: 9月 | M29: =基础数据!#REF! -> #REF!
B30: 27 | C30: =C29-0.004 -> 0.886 | D30: =$J$10*C30 -> #REF! | E30: =D30*$E$3 -> #REF! | F30: =D30*$F$3 -> #REF! | G30: =$J$12*C30*$E$3*$L$8*(1-$J$6)+$J$14*C30*$E$3*$L$17*(1-$J$6) -> #REF! | H30: =D30/12 -> #REF! | K30: 10月 | M30: =基础数据!#REF! -> #REF!
B31: 28 | C31: =C30-0.004 -> 0.882 | D31: =$J$10*C31 -> #REF! | E31: =D31*$E$3 -> #REF! | F31: =D31*$F$3 -> #REF! | G31: =$J$12*C31*$E$3*$L$8*(1-$J$6)+$J$14*C31*$E$3*$L$17*(1-$J$6) -> #REF! | H31: =D31/12 -> #REF! | K31: 11月 | M31: =基础数据!#REF! -> #REF!
B32: 29 | C32: =C31-0.004 -> 0.878 | D32: =$J$10*C32 -> #REF! | E32: =D32*$E$3 -> #REF! | F32: =D32*$F$3 -> #REF! | G32: =$J$12*C32*$E$3*$L$8*(1-$J$6)+$J$14*C32*$E$3*$L$17*(1-$J$6) -> #REF! | H32: =D32/12 -> #REF! | K32: 12月 | M32: =基础数据!#REF! -> #REF!
B33: 30 | C33: =C32-0.004 -> 0.874 | D33: =$J$10*C33 -> #REF! | E33: =D33*$E$3 -> #REF! | F33: =D33*$F$3 -> #REF! | G33: =$J$12*C33*$E$3*$L$8*(1-$J$6)+$J$14*C33*$E$3*$L$17*(1-$J$6) -> #REF! | H33: =D33/12 -> #REF!
B34: 合计 | D34: =SUM(D4:D33) -> #REF! | E34: =SUM(E4:E33) -> #REF! | F34: =SUM(F4:F33) -> #REF! | G34: =SUM(G4:G33) -> #REF!
A35: .

Sheet 消纳率参数
B2: 电费单 | F2: 按业主电费单核算
A3: 1月 | B3: 尖 | F3: 月份 | G3: 可消纳光伏电 | H3: 光伏发电量 | I3: 消纳率
B4: 峰 | C4: 90720 | F4: 1 | G4: =C3+C4*5/7+C5*4/9 -> 102311.11 | H4: ='光伏发电衰减表 输入数据'!U24 -> 38818.216 | I4: =IF(G4/H4<1,G4/H4,1) -> 1
B5: 平 | C5: 84400 | F5: 2 | G5: =C6+C7*5/7+C8*4/9 -> 332624.76 | H5: ='光伏发电衰减表 输入数据'!U25 -> 49334.554 | I5: =IF(G5/H5<1,G5/H5,1) -> 1
A6: 2月 | B6: 尖 | F6: 3 | G6: =C9+C10*5/7+C11*4/9 -> 410921.9 | H6: ='光伏发电衰减表 输入数据'!U26 -> 73871.193 | I6: =IF(G6/H6<1,G6/H6,1) -> 1 | K6: 当月消纳率 | L6: 结算价格
B7: 峰 | C7: 294240 | F7: 4 | G7: =C12+C13*5/7+C14*4/9 -> 354786.03 | H7: ='光伏发电衰减表 输入数据'!U27 -> 87352.982 | I7: =IF(G7/H7<1,G7/H7,1) -> 1 | K7: 消纳率＜10% | L7: 0.95
B8: 平 | C8: 275520 | F8: 5 | G8: =C15+C16*5/7+C17*4/9 -> 338659.05 | H8: ='光伏发电衰减表 输入数据'!U28 -> 93734.641 | I8: =IF(G8/H8<1,G8/H8,1) -> 1 | K8: 10%≤ 消纳率 ＜20% | L8: 0.92
A9: 3月 | B9: 尖 | F9: 6 | G9: =C18+C19*5/7+C20*4/9 -> 324708.57 | H9: ='光伏发电衰减表 输入数据'!U29 -> 86124.312 | I9: =IF(G9/H9<1,G9/H9,1) -> 1 | K9: 20%≤ 消纳率 ＜30% | L9: 0.89
B10: 峰 | C10: 360400 | F10: 7 | G10: =C21+C22*5/7+C23*4/9 -> 367488.25 | H10: ='光伏发电衰减表 输入数据'!U30 -> 117551.38 | I10: =IF(G10/H10<1,G10/H10,1) -> 1 | K10: 30%≤ 消纳率 ＜40% | L10: 0.86
B11: 平 | C11: 345360 | F11: 8 | G11: =C24+C25*5/7+C26*4/9 -> 413293.97 | H11: ='光伏发电衰减表 输入数据'!U31 -> 113287.19 | I11: =IF(G11/H11<1,G11/H11,1) -> 1 | K11: 40%≤ 消纳率 ＜50% | L11: 0.83
A12: 4月 | B12: 尖 | F12: 9 | G12: =C27+C28*5/7+C29*4/9 -> 371916.19 | H12: ='光伏发电衰减表 输入数据'!U32 -> 77665.173 | I12: =IF(G12/H12<1,G12/H12,1) -> 1 | K12: 50%≤ 消纳率 ＜60% | L12: 0.8
B13: 峰 | C13: 313120 | F13: 10 | G13: =C30+C31*5/7+C32*4/9 -> 343503.49 | H13: ='光伏发电衰减表 输入数据'!U33 -> 50246.492 | I13: =IF(G13/H13<1,G13/H13,1) -> 1 | K13: 60%≤ 消纳率 ＜70% | L13: 0.77
B14: 平 | C14: 295040 | F14: 11 | G14: =C33+C34*5/7+C35*4/9 -> 300897.78 | H14: ='光伏发电衰减表 输入数据'!U34 -> 42680.925 | I14: =IF(G14/H14<1,G14/H14,1) -> 1 | K14: 70%≤ 消纳率 ＜80% | L14: 0.74
A15: 5月 | B15: 尖 | C15: 27440 | F15: 12 | G15: =C36+C37*5/7+C38*4/9 -> 381104.76 | H15: ='光伏发电衰减表 输入数据'!U35 -> 34167.039 | I15: =IF(G15/H15<1,G15/H15,1) -> 1 | K15: 80%≤ 消纳率 ＜90% | L15: 0.71
B16: 峰 | C16: 262480 | F16: 合计 | G16: =SUM(G4:G15) -> 4042215.9 | H16: =SUM(H4:H15) -> 864834.1 | I16: =AVERAGE(I4:I15) -> 1 | K16: 90%≤ 消纳率 ≤100% | L16: 0.68
B17: 平 | C17: 278400
A18: 6月 | B18: 尖 | C18: 28640
B19: 峰 | C19: 247840 | F19: 按业主变压器核算（假设满负载） | K19: *无电费单、装机容量>变压器容量的情况，用业主变压器核算 1小时用电量=变压器容量×功率系数
B20: 平 | C20: 267840 | F20: 月份 | G20: 可消纳光伏电 | H20: 光伏发电量 | I20: 消纳率
A21: 7月 | B21: 尖 | C21: 126560 | F21: 1 | G21: =$L$22*$L$23*$L$24*31 -> 133920 | H21: ='光伏发电衰减表 输入数据'!U24 -> 38818.216 | I21: =G21/H21 -> 3.4499267
B22: 峰 | C22: 160240 | F22: 2 | G22: =$L$22*$L$23*$L$24*28 -> 120960 | H22: ='光伏发电衰减表 输入数据'!U25 -> 49334.554 | I22: =G22/H22 -> 2.4518312 | K22: 变压器容量（KVA） | L22: 600
B23: 平 | C23: 284560 | F23: 3 | G23: =$L$22*$L$23*$L$24*31 -> 133920 | H23: ='光伏发电衰减表 输入数据'!U26 -> 73871.193 | I23: =G23/H23 -> 1.8128853 | K23: 功率系数 | L23: 0.8
A24: 8月 | B24: 尖 | C24: 142480 | F24: 4 | G24: =$L$22*$L$23*$L$24*30 -> 129600 | H24: ='光伏发电衰减表 输入数据'!U27 -> 87352.982 | I24: =G24/H24 -> 1.4836357 | K24: 客户一天生产总时长（小时） | L24: 9
B25: 峰 | C25: 184160 | F25: 5 | G25: =$L$22*$L$23*$L$24*31 -> 133920 | H25: ='光伏发电衰减表 输入数据'!U28 -> 93734.641 | I25: =G25/H25 -> 1.4287141
B26: 平 | C26: 313360 | F26: 6 | G26: =$L$22*$L$23*$L$24*30 -> 129600 | H26: ='光伏发电衰减表 输入数据'!U29 -> 86124.312 | I26: =G26/H26 -> 1.5048016
A27: 9月 | B27: 尖 | C27: 127440 | F27: 7 | G27: =$L$22*$L$23*$L$24*31 -> 133920 | H27: ='光伏发电衰减表 输入数据'!U30 -> 117551.38 | I27: =G27/H27 -> 1.1392465
B28: 峰 | C28: 166800 | F28: 8 | G28: =$L$22*$L$23*$L$24*31 -> 133920 | H28: ='光伏发电衰减表 输入数据'!U31 -> 113287.19 | I28: =G28/H28 -> 1.1821283
B29: 平 | C29: 282000 | F29: 9 | G29: =$L$22*$L$23*$L$24*30 -> 129600 | H29: ='光伏发电衰减表 输入数据'!U32 -> 77665.173 | I29: =G29/H29 -> 1.6687016
A30: 10月 | B30: 尖 | C30: 12320 | F30: 10 | G30: =$L$22*$L$23*$L$24*31 -> 133920 | H30: ='光伏发电衰减表 输入数据'!U33 -> 50246.492 | I30: =G30/H30 -> 2.6652607
B31: 峰 | C31: 286000 | F31: 11 | G31: =$L$22*$L$23*$L$24*30 -> 129600 | H31: ='光伏发电衰减表 输入数据'!U34 -> 42680.925 | I31: =G31/H31 -> 3.0364853
B32: 平 | C32: 285520 | F32: 12 | G32: =$L$22*$L$23*$L$24*31 -> 133920 | H32: ='光伏发电衰减表 输入数据'!U35 -> 34167.039 | I32: =G32/H32 -> 3.9195671
A33: 11月 | B33: 尖 | C33: 0 | F33: 合计 | G33: =SUM(G21:G32) -> 1576800 | H33: =SUM(H21:H32) -> 864834.1 | I33: =G33/H33 -> 1.8232399
B34: 峰 | C34: 266000
B35: 平 | C35: 249520
A36: 12月 | B36: 尖 | C36: 0
B37: 峰 | C37: 333440
B38: 平 | C38: 321600

Sheet 业主自投收益回报表
B2: 业主自投收益回报表（峰值日照时长平均值） | J2: 回本周期
B3: 年份 | C3: 发电量 | D3: 税前发电收入 | E3: 投资成本 | F3: 税后发电净收入 | G3: 累计净收入 | J3: {=_xlfn.LET(_xlpm.年份列,B4:B29,_xlpm.净利列,F4:F29,_xlpm.累计列,G4:G29,_xlpm.i,_xlfn.XMATCH(TRUE,_xlpm.累计列>0,0),_xlpm.回本月,-INDEX(_xlpm.累计列,_xlpm.i-1)/(INDEX(_xlpm.净利列,_xlpm.i-1)/12),_xlpm.回本年,INDEX(_xlpm.年份列,_xlpm.i-1),"第"&INT(_xlpm.回本年)&"年"&ROUND(MOD(_xlpm.回本年+_xlpm.回本月/12,1)*12,0)&"个月")} -> 第4年2个月
B4: 0 | C4: 0 | D4: 0 | E4: =基础数据!H7 -> 2000000 | F4: =-E4 -> -2000000 | G4: =F4 -> -2000000
B5: 1 | C5: ='光伏发电衰减表 输入数据'!D6 -> 864834.1 | D5: ='光伏发电衰减表 输入数据'!G6 -> 557610.4 | E5: 0 | F5: ='光伏发电衰减表 输入数据'!M6 -> 522704.74 | G5: =G4+F5 -> -1477295.3
