Workbook

Sheet 基础数据
B2: 光伏系统（一） | F2: 棚架（二） | J2: 棚架（三）
B3: 面积㎡ | D3: 装机容量KWp | F3: 面积㎡ | H3: 装机容量KWp | J3: 面积㎡ | L3: 装机容量KWp
D4: 1000 | J4: 0
B5: 单价（元/KWp） | D5: 小计 | F5: 单价 | H5: 小计 | J5: 单价 | L5: 小计
B6: 2000 | D6: =D4*B6 -> 2000000 | F6: 0 | H6: =F6*F4 -> 0 | J6: 0 | L6: =J4*J6 -> 0
G7: 工程造价合计 | H7: =D6+H6+L6 -> 2000000 | I7: 遮挡发电系数
G8: 总装机容量 | H8: =D4 -> 1000 | I8: 1
B10: 光伏发电站计量参数 | I10: 综合造价 | J10: 首年预计发电量（KW.h）（未计算衰减）
B11: 月份 | C11: 日照时长 | D11: 系统综合效率 | E11: 非正南角度 | F11: 发电天数 | G11: 实际等效可利用时间 | I11: =H7/D4/1000 -> 2 | J11: 月份 | K11: 发电量
B12: 1月 | C12: 1.664275 | D12: 0.8 | E12: 0.95 | F12: 31 | G12: =C12*D12*E12*F12 -> 39.210319 | J12: 1月 | K12: =$H$8*C12*D12*E12*$I$8*F12 -> 39210.319
B13: 2月 | C13: 2.3417708 | D13: 0.8 | E13: 0.95 | F13: 28 | G13: =C13*D13*E13*F13 -> 49.832883 | J13: 2月 | K13: =$H$8*C13*D13*E13*$I$8*F13 -> 49832.883
B14: 3月 | C14: 3.1671208 | D14: 0.8 | E14: 0.95 | F14: 31 | G14: =C14*D14*E14*F14 -> 74.617367 | J14: 3月 | K14: =$H$8*C14*D14*E14*$I$8*F14 -> 74617.367
B15: 4月 | C15: 3.8699708 | D15: 0.8 | E15: 0.95 | F15: 30 | G15: =C15*D15*E15*F15 -> 88.235335 | J15: 4月 | K15: =$H$8*C15*D15*E15*$I$8*F15 -> 88235.335
B16: 5月 | C16: 4.0187375 | D16: 0.8 | E16: 0.95 | F16: 31 | G16: =C16*D16*E16*F16 -> 94.681455 | J16: 5月 | K16: =$H$8*C16*D16*E16*$I$8*F16 -> 94681.455
B17: 6月 | C17: 3.8155375 | D17: 0.8 | E17: 0.95 | F17: 30 | G17: =C17*D17*E17*F17 -> 86.994255 | J17: 6月 | K17: =$H$8*C17*D17*E17*$I$8*F17 -> 86994.255
B18: 7月 | C18: 5.0398458 | D18: 0.8 | E18: 0.95 | F18: 31 | G18: =C18*D18*E18*F18 -> 118.73877 | J18: 7月 | K18: =$H$8*C18*D18*E18*$I$8*F18 -> 118738.77
B19: 8月 | C19: 4.857025 | D19: 0.8 | E19: 0.95 | F19: 31 | G19: =C19*D19*E19*F19 -> 114.43151 | J19: 8月 | K19: =$H$8*C19*D19*E19*$I$8*F19 -> 114431.51
B20: 9月 | C20: 3.440775 | D20: 0.8 | E20: 0.95 | F20: 30 | G20: =C20*D20*E20*F20 -> 78.44967 | J20: 9月 | K20: =$H$8*C20*D20*E20*$I$8*F20 -> 78449.67
B21: 10月 | C21: 2.1542458 | D21: 0.8 | E21: 0.95 | F21: 31 | G21: =C21*D21*E21*F21 -> 50.754032 | J21: 10月 | K21: =$H$8*C21*D21*E21*$I$8*F21 -> 50754.032
B22: 11月 | C22: 1.8908792 | D22: 0.8 | E22: 0.95 | F22: 30 | G22: =C22*D22*E22*F22 -> 43.112045 | J22: 11月 | K22: =$H$8*C22*D22*E22*$I$8*F22 -> 43112.045
B23: 12月 | C23: 1.4648625 | D23: 0.8 | E23: 0.95 | F23: 31 | G23: =C23*D23*E23*F23 -> 34.512161 | J23: 12月 | K23: =$H$8*C23*D23*E23*$I$8*F23 -> 34512.16
B24: 平均 | C24: =AVERAGE(C12:C23) -> 3.1437538 | G24: =SUM(G12:G23) -> 873.5698 | J24: 合计 | K24: =SUM(K12:K23) -> 873569.8
B26: 节能减排表 | J26: 光伏保险费用（元）
B27: 项目 | C27: 发电量 | D27: 节约标准煤 | E27: 减排CO2 | F27: 减排SOx | G27: 减排NOx | H27: 等效植树 | J27: =H7*0.0035 -> 7000
C28: 度 | D28: 吨 | E28: 吨 | F28: 吨 | G28: 吨 | H28: 棵 | J28: 光伏发电站运维费用（元）
B29: 第一年 | C29: ='光伏发电衰减表 输入数据'!D6 -> 864834.1 | D29: =C29*305/1000/1000 -> 263.7744 | E29: =C29*0.814/1000 -> 703.97496 | F29: =C29*6.2/1000/1000 -> 5.3619714 | G29: =C29*2.1/1000/1000 -> 1.8161516 | H29: =C29*0.00177 -> 1530.7564 | J29: =H8*1000*0.03 -> 30000
B30: 25年合计 | C30: ='光伏发电衰减表 输入数据'!D31 -> 20572569 | D30: =C30*305/1000/1000 -> 6274.6335 | E30: =C30*0.814/1000 -> 16746.071 | F30: =C30*6.2/1000/1000 -> 127.54993 | G30: =C30*2.1/1000/1000 -> 43.202394 | H30: =C30*0.00177 -> 36413.447
C31: 碳交易权价值
D32: 发电量（度） | E32: 减排碳（吨） | F32: 单价（元） | G32: 合计（元）
C33: 每年平均 | D33: =C30/25 -> 822902.75 | E33: =D33*0.814/1000 -> 669.84284 | G33: =F33*E33 -> 0
C34: 25年合计 | D34: =D33*25 -> 20572569 | E34: =D34*0.814/1000 -> 16746.071 | G34: =E34*F34 -> 0

Sheet 光伏发电衰减表 输入数据
R3: 每年除去七、八、九月 平均电价计算（元/KW.h）
B4: 年发电量预估（峰值日照时长平均值） | E4: 消纳率 | F4: 余电上网率 | G4: *成立新公司 | K4: 本测算表假设5% | R4: 供电局购电价 | S4: 尖电电价 | T4: 峰电电价 | U4: 平段电价 | V4: 谷电电价 | W4: 输配电费（尖） | X4: 输配电费（峰） | Y4: 输配电费（平） | Z4: 基金及附加费
B5: 年份 | C5: 系统发电效率(%) | D5: 发电量（度） | E5: 0.924 | F5: =1-E5 -> 0.076 | G5: 发电收入（不含13%增值税） | H5: 运维 | I5: 保险 | J5: 资金成本 | K5: 租金 | L5: 经营费5% | M5: 税金合计 | N5: 碳权价值 | O5: 税后发电净收入 | Q5: 余电上网电价（元） | S5: 1.4506 | T5: 1.1659 | U5: 0.6973 | V5: 忽略 | W5: =光伏发电衰减表min!P3 -> 0 | X5: =光伏发电衰减表min!Q3 -> 0 | Y5: =光伏发电衰减表min!R3 -> 0 | Z5: =光伏发电衰减表min!S3 -> 0
B6: 1 | C6: 0.99 | D6: =$Q$12*C6 -> 864834.1 | E6: =D6*$E$5 -> 799106.71 | F6: =D6*$F$5 -> 65727.392 | G6: =($Q$14*C6*$E$5*$S$10+$Q$14*C6*$F$5*$Q$6+$Q$16*C6*$E$5*$S$19+$Q$16*C6*$F$5*$Q$6)/1.13 -> 587271.72 | H6: =$D$35/1.06 -> 28301.887 | I6: =$F$35/1.06 -> 6603.7736 | J6: =税金参数!O4 -> 112485.37 | K6: ='业主收益（租金、节能收益）'!D5/1.05 -> 4743.8095 | L6: =G6*0 -> 0 | M6: =税金参数!R4 -> 3408.2201 | N6: 0 | O6: =G6-H6-I6-J6-K6-L6-M6 -> 431728.66 | Q6: 0.453 | R6: 光伏发电电价 | S6: 尖电电价 | T6: 峰电电价 | U6: 平段电价 | V6: 谷电电价
B7: 2 | C7: =C6-0.004 -> 0.986 | D7: =$Q$12*C7 -> 861339.82 | E7: =D7*$E$5 -> 795878 | F7: =D7*$F$5 -> 65461.826 | G7: =($Q$14*C7*$E$5*$S$10+$Q$14*C7*$F$5*$Q$6+$Q$16*C7*$E$5*$S$19+$Q$16*C7*$F$5*$Q$6)/1.13 -> 584898.91 | H7: =$D$35/1.06 -> 28301.887 | I7: =$F$35/1.06 -> 6603.7736 | J7: =税金参数!O5 -> 102387.15 | K7: ='业主收益（租金、节能收益）'!D6/1.05 -> 4743.8095 | L7: =G7*0 -> 0 | M7: =税金参数!R5 -> 7464.2152 | N7: 0 | O7: =G7-H7-I7-J7-K7-L7-M7 -> 435398.07 | Q7: 电费折扣 | S7: =S5+W5+Z5 -> 1.4506 | T7: =T5+X5+Z5 -> 1.1659 | U7: =U5+Y5+Z5 -> 0.6973 | V7: 忽略
B8: 3 | C8: =C7-0.004 -> 0.982 | D8: =$Q$12*C8 -> 857845.54 | E8: =D8*$E$5 -> 792649.28 | F8: =D8*$F$5 -> 65196.261 | G8: =($Q$14*C8*$E$5*$S$10+$Q$14*C8*$F$5*$Q$6+$Q$16*C8*$E$5*$S$19+$Q$16*C8*$F$5*$Q$6)/1.13 -> 582526.09 | H8: =$D$35/1.06 -> 28301.887 | I8: =$F$35/1.06 -> 6603.7736 | J8: =税金参数!O6 -> 89249.336 | K8: ='业主收益（租金、节能收益）'!D7/1.05 -> 4743.8095 | L8: =G8*0 -> 0 | M8: =税金参数!R6 -> 70107.382 | N8: 0 | O8: =G8-H8-I8-J8-K8-L8-M8 -> 383519.91 | Q8: 0.8 | S8: 加权系数 | T8: 加权系数 | U8: 加权系数 | V8: 加权系数 | W8: 合计时段
B9: 4 | C9: =C8-0.004 -> 0.978 | D9: =$Q$12*C9 -> 854351.26 | E9: =D9*$E$5 -> 789420.57 | F9: =D9*$F$5 -> 64930.696 | G9: =($Q$14*C9*$E$5*$S$10+$Q$14*C9*$F$5*$Q$6+$Q$16*C9*$E$5*$S$19+$Q$16*C9*$F$5*$Q$6)/1.13 -> 580153.28 | H9: =$D$35/1.06 -> 28301.887 | I9: =$F$35/1.06 -> 6603.7736 | J9: =税金参数!O7 -> 75301.208 | K9: ='业主收益（租金、节能收益）'!D8/1.05 -> 4743.8095 | L9: =G9*0 -> 0 | M9: =税金参数!R7 -> 150289.21 | N9: 0 | O9: =G9-H9-I9-J9-K9-L9-M9 -> 314913.39 | Q9: 全年平均电价 | S9: 0 | T9: 5 | U9: 4 | V9: 0 | W9: 9 | X9: 加权后平均电价 | Y9: =(S7*S9+T7*T9+U7*U9)/W9 -> 0.95763333
B10: 5 | C10: =C9-0.004 -> 0.974 | D10: =$Q$12*C10 -> 850856.98 | E10: =D10*$E$5 -> 786191.85 | F10: =D10*$F$5 -> 64665.131 | G10: =($Q$14*C10*$E$5*$S$10+$Q$14*C10*$F$5*$Q$6+$Q$16*C10*$E$5*$S$19+$Q$16*C10*$F$5*$Q$6)/1.13 -> 577780.46 | H10: =$D$35/1.06 -> 28301.887 | I10: =$F$35/1.06 -> 6603.7736 | J10: =税金参数!O8 -> 60492.79 | K10: ='业主收益（租金、节能收益）'!D9/1.05 -> 4743.8095 | L10: =G10*0 -> 0 | M10: =税金参数!R8 -> 93294.7 | N10: 0 | O10: =G10-H10-I10-J10-K10-L10-M10 -> 384343.5 | Q10: =(S10*9+S19*3)/12 -> 0.78508667 | R10: 加权后平均电价 | S10: =Y9*Q8 -> 0.76610667
B11: 6 | C11: =C10-0.004 -> 0.97 | D11: =$Q$12*C11 -> 847362.7 | E11: =D11*$E$5 -> 782963.14 | F11: =D11*$F$5 -> 64399.566 | G11: =($Q$14*C11*$E$5*$S$10+$Q$14*C11*$F$5*$Q$6+$Q$16*C11*$E$5*$S$19+$Q$16*C11*$F$5*$Q$6)/1.13 -> 575407.65 | H11: =$D$35/1.06 -> 28301.887 | I11: =$F$35/1.06 -> 6603.7736 | J11: =税金参数!O9 -> 44771.021 | K11: ='业主收益（租金、节能收益）'!D10/1.05 -> 4743.8095 | L11: =G11*0 -> 0 | M11: =税金参数!R9 -> 95139.219 | N11: 0 | O11: =G11-H11-I11-J11-K11-L11-M11 -> 395847.94 | Q11: 首年总发电量
B12: 7 | C12: =C11-0.004 -> 0.966 | D12: =$Q$12*C12 -> 843868.43 | E12: =D12*$E$5 -> 779734.43 | F12: =D12*$F$5 -> 64134 | G12: =($Q$14*C12*$E$5*$S$10+$Q$14*C12*$F$5*$Q$6+$Q$16*C12*$E$5*$S$19+$Q$16*C12*$F$5*$Q$6)/1.13 -> 573034.83 | H12: =$D$35/1.06 -> 28301.887 | I12: =$F$35/1.06 -> 6603.7736 | J12: =税金参数!O10 -> 28079.568 | K12: ='业主收益（租金、节能收益）'!D11/1.05 -> 4743.8095 | L12: =G12*0 -> 0 | M12: =税金参数!R10 -> 96731.597 | N12: 0 | O12: =G12-H12-I12-J12-K12-L12-M12 -> 408574.2 | Q12: =Q14+Q16 -> 873569.8 | R12: 每年七、八、九月 平均电价计算（元/KW.h）
B13: 8 | C13: =C12-0.004 -> 0.962 | D13: =$Q$12*C13 -> 840374.15 | E13: =D13*$E$5 -> 776505.71 | F13: =D13*$F$5 -> 63868.435 | G13: =($Q$14*C13*$E$5*$S$10+$Q$14*C13*$F$5*$Q$6+$Q$16*C13*$E$5*$S$19+$Q$16*C13*$F$5*$Q$6)/1.13 -> 570662.02 | H13: =$D$35/1.06 -> 28301.887 | I13: =$F$35/1.06 -> 6603.7736 | J13: =税金参数!O11 -> 10358.622 | K13: ='业主收益（租金、节能收益）'!D12/1.05 -> 4743.8095 | L13: =G13*0 -> 0 | M13: =税金参数!R11 -> 98134.952 | N13: 0 | O13: =G13-H13-I13-J13-K13-L13-M13 -> 422518.97 | Q13: 首年除七、八、九月发电总量 | R13: 供电局购电价 | S13: 尖电电价 | T13: 峰电电价 | U13: 平段电价 | V13: 谷电电价 | W13: 输配电费（尖） | X13: 输配电费（峰） | Y13: 输配电费（平） | Z13: 基金及附加费
B14: 9 | C14: =C13-0.004 -> 0.958 | D14: =$Q$12*C14 -> 836879.87 | E14: =D14*$E$5 -> 773277 | F14: =D14*$F$5 -> 63602.87 | G14: =($Q$14*C14*$E$5*$S$10+$Q$14*C14*$F$5*$Q$6+$Q$16*C14*$E$5*$S$19+$Q$16*C14*$F$5*$Q$6)/1.13 -> 568289.2 | H14: =$D$35/1.06 -> 28301.887 | I14: =$F$35/1.06 -> 6603.7736 | J14: =税金参数!O12 -> 0 | K14: ='业主收益（租金、节能收益）'!D13/1.05 -> 4743.8095 | L14: =G14*0 -> 0 | M14: =税金参数!R12 -> 94360.208 | N14: 0 | O14: =G14-H14-I14-J14-K14-L14-M14 -> 434279.53 | Q14: =R24+R25+R26+R27+R28+R29+R33+R34+R35 -> 561949.85 | S14: =S5 -> 1.4506 | T14: =T5 -> 1.1659 | U14: =U5 -> 0.6973 | V14: =V5 -> 忽略 | W14: =光伏发电衰减表min!P12 -> 0 | X14: =光伏发电衰减表min!Q12 -> 0 | Y14: =光伏发电衰减表min!R12 -> 0 | Z14: =光伏发电衰减表min!S12 -> 0
B15: 10 | C15: =C14-0.004 -> 0.954 | D15: =$Q$12*C15 -> 833385.59 | E15: =D15*$E$5 -> 770048.28 | F15: =D15*$F$5 -> 63337.305 | G15: =($Q$14*C15*$E$5*$S$10+$Q$14*C15*$F$5*$Q$6+$Q$16*C15*$E$5*$S$19+$Q$16*C15*$F$5*$Q$6)/1.13 -> 565916.39 | H15: =$D$35/1.06 -> 28301.887 | I15: =$F$35/1.06 -> 6603.7736 | J15: =税金参数!O13 -> 0 | K15: ='业主收益（租金、节能收益）'!D14/1.05 -> 4743.8095 | L15: =G15*0 -> 0 | M15: =税金参数!R13 -> 93915.519 | N15: 0 | O15: =G15-H15-I15-J15-K15-L15-M15 -> 432351.4 | Q15: 首年七、八、九月发电总量 | R15: 光伏发电电价 | S15: 尖电电价 | T15: 峰电电价 | U15: 平段电价 | V15: 谷电电价
B16: 11 | C16: =C15-0.004 -> 0.95 | D16: =$Q$12*C16 -> 829891.31 | E16: =D16*$E$5 -> 766819.57 | F16: =D16*$F$5 -> 63071.739 | G16: =($Q$14*C16*$E$5*$S$10+$Q$14*C16*$F$5*$Q$6+$Q$16*C16*$E$5*$S$19+$Q$16*C16*$F$5*$Q$6)/1.13 -> 563543.57 | H16: =$D$35/1.06 -> 28301.887 | I16: =$F$35/1.06 -> 6603.7736 | J16: =税金参数!O14 -> 0 | K16: ='业主收益（租金、节能收益）'!D15/1.05 -> 4743.8095 | L16: =G16*0 -> 0 | M16: =税金参数!R14 -> 101166.8 | N16: 0 | O16: =G16-H16-I16-J16-K16-L16-M16 -> 422727.3 | Q16: =R30+R31+R32 -> 311619.95 | S16: =S14+W14+Z14 -> 1.4506 | T16: =T14+X14+Z14 -> 1.1659 | U16: =U14+Y14+Z14 -> 0.6973 | V16: 忽略
B17: 12 | C17: =C16-0.004 -> 0.946 | D17: =$Q$12*C17 -> 826397.03 | E17: =D17*$E$5 -> 763590.86 | F17: =D17*$F$5 -> 62806.174 | G17: =($Q$14*C17*$E$5*$S$10+$Q$14*C17*$F$5*$Q$6+$Q$16*C17*$E$5*$S$19+$Q$16*C17*$F$5*$Q$6)/1.13 -> 561170.76 | H17: =$D$35/1.06 -> 28301.887 | I17: =$F$35/1.06 -> 6603.7736 | J17: =税金参数!O15 -> 0 | K17: ='业主收益（租金、节能收益）'!D16/1.05 -> 4743.8095 | L17: =G17*0 -> 0 | M17: =税金参数!R15 -> 100722.11 | N17: 0 | O17: =G17-H17-I17-J17-K17-L17-M17 -> 420799.18 | S17: 加权系数 | T17: 加权系数 | U17: 加权系数 | V17: 加权系数 | W17: 合计时段
B18: 13 | C18: =C17-0.004 -> 0.942 | D18: =$Q$12*C18 -> 822902.75 | E18: =D18*$E$5 -> 760362.14 | F18: =D18*$F$5 -> 62540.609 | G18: =($Q$14*C18*$E$5*$S$10+$Q$14*C18*$F$5*$Q$6+$Q$16*C18*$E$5*$S$19+$Q$16*C18*$F$5*$Q$6)/1.13 -> 558797.94 | H18: =$D$35/1.06 -> 28301.887 | I18: =$F$35/1.06 -> 6603.7736 | J18: =税金参数!O16 -> 0 | K18: ='业主收益（租金、节能收益）'!D17/1.05 -> 4743.8095 | L18: =G18*0 -> 0 | M18: =税金参数!R16 -> 100277.42 | N18: 0 | O18: =G18-H18-I18-J18-K18-L18-M18 -> 418871.05 | S18: 3 | T18: 2 | U18: 4 | V18: 0 | W18: 9 | X18: 加权后平均电价 | Y18: =(S16*S18+T16*T18+U16*U18)/W18 -> 1.0525333
B19: 14 | C19: =C18-0.004 -> 0.938 | D19: =$Q$12*C19 -> 819408.47 | E19: =D19*$E$5 -> 757133.43 | F19: =D19*$F$5 -> 62275.044 | G19: =($Q$14*C19*$E$5*$S$10+$Q$14*C19*$F$5*$Q$6+$Q$16*C19*$E$5*$S$19+$Q$16*C19*$F$5*$Q$6)/1.13 -> 556425.13 | H19: =$D$35/1.06 -> 28301.887 | I19: =$F$35/1.06 -> 6603.7736 | J19: =税金参数!O17 -> 0 | K19: ='业主收益（租金、节能收益）'!D18/1.05 -> 4743.8095 | L19: =G19*0 -> 0 | M19: =税金参数!R17 -> 99832.733 | N19: 0 | O19: =G19-H19-I19-J19-K19-L19-M19 -> 416942.93 | R19: 加权后平均电价 | S19: =Y18*Q8 -> 0.84202667
B20: 15 | C20: =C19-0.004 -> 0.934 | D20: =$Q$12*C20 -> 815914.19 | E20: =D20*$E$5 -> 753904.71 | F20: =D20*$F$5 -> 62009.479 | G20: =($Q$14*C20*$E$5*$S$10+$Q$14*C20*$F$5*$Q$6+$Q$16*C20*$E$5*$S$19+$Q$16*C20*$F$5*$Q$6)/1.13 -> 554052.31 | H20: =$D$35/1.06 -> 28301.887 | I20: =$F$35/1.06 -> 6603.7736 | J20: =税金参数!O18 -> 0 | K20: ='业主收益（租金、节能收益）'!D19/1.05 -> 4743.8095 | L20: =G20*0 -> 0 | M20: =税金参数!R18 -> 99388.043 | N20: 0 | O20: =G20-H20-I20-J20-K20-L20-M20 -> 415014.8
B21: 16 | C21: =C20-0.004 -> 0.93 | D21: =$Q$12*C21 -> 812419.91 | E21: =D21*$E$5 -> 750676 | F21: =D21*$F$5 -> 61743.913 | G21: =($Q$14*C21*$E$5*$S$10+$Q$14*C21*$F$5*$Q$6+$Q$16*C21*$E$5*$S$19+$Q$16*C21*$F$5*$Q$6)/1.13 -> 551679.5 | H21: =$D$35/1.06 -> 28301.887 | I21: =$F$35/1.06 -> 6603.7736 | J21: =税金参数!O19 -> 0 | K21: ='业主收益（租金、节能收益）'!D20/1.05 -> 4743.8095 | L21: =G21*0 -> 0 | M21: =税金参数!R19 -> 98943.354 | N21: 0 | O21: =G21-H21-I21-J21-K21-L21-M21 -> 413086.67
B22: 17 | C22: =C21-0.004 -> 0.926 | D22: =$Q$12*C22 -> 808925.63 | E22: =D22*$E$5 -> 747447.29 | F22: =D22*$F$5 -> 61478.348 | G22: =($Q$14*C22*$E$5*$S$10+$Q$14*C22*$F$5*$Q$6+$Q$16*C22*$E$5*$S$19+$Q$16*C22*$F$5*$Q$6)/1.13 -> 549306.68 | H22: =$D$35/1.06 -> 28301.887 | I22: =$F$35/1.06 -> 6603.7736 | J22: =税金参数!O20 -> 0 | K22: ='业主收益（租金、节能收益）'!D21/1.05 -> 4743.8095 | L22: =G22*0 -> 0 | M22: =税金参数!R20 -> 98498.665 | N22: 0 | O22: =G22-H22-I22-J22-K22-L22-M22 -> 411158.55 | Q22: 首年预计发电量（KW.h）（未计算衰减） | T22: 首年预计发电量（KW.h）(计算衰减） | X22: *默认首年1%衰减，如需变化手动调整
B23: 18 | C23: =C22-0.004 -> 0.922 | D23: =$Q$12*C23 -> 805431.35 | E23: =D23*$E$5 -> 744218.57 | F23: =D23*$F$5 -> 61212.783 | G23: =($Q$14*C23*$E$5*$S$10+$Q$14*C23*$F$5*$Q$6+$Q$16*C23*$E$5*$S$19+$Q$16*C23*$F$5*$Q$6)/1.13 -> 546933.87 | H23: =$D$35/1.06 -> 28301.887 | I23: =$F$35/1.06 -> 6603.7736 | J23: =税金参数!O21 -> 0 | K23: ='业主收益（租金、节能收益）'!D22/1.05 -> 4743.8095 | L23: =G23*0 -> 0 | M23: =税金参数!R21 -> 98053.975 | N23: 0 | O23: =G23-H23-I23-J23-K23-L23-M23 -> 409230.42 | Q23: 月份 | R23: 月发电量 | T23: 月份 | V23: 月发电量
B24: 19 | C24: =C23-0.004 -> 0.918 | D24: =$Q$12*C24 -> 801937.08 | E24: =D24*$E$5 -> 740989.86 | F24: =D24*$F$5 -> 60947.218 | G24: =($Q$14*C24*$E$5*$S$10+$Q$14*C24*$F$5*$Q$6+$Q$16*C24*$E$5*$S$19+$Q$16*C24*$F$5*$Q$6)/1.13 -> 544561.05 | H24: =$D$35/1.06 -> 28301.887 | I24: =$F$35/1.06 -> 6603.7736 | J24: =税金参数!O22 -> 0 | K24: ='业主收益（租金、节能收益）'!D23/1.05 -> 4743.8095 | L24: =G24*0 -> 0 | M24: =税金参数!R22 -> 97609.286 | N24: 0 | O24: =G24-H24-I24-J24-K24-L24-M24 -> 407302.3 | Q24: 1月 | R24: =基础数据!K12 -> 39210.319 | T24: 1月 | V24: =R24*0.99 -> 38818.216
B25: 20 | C25: =C24-0.004 -> 0.914 | D25: =$Q$12*C25 -> 798442.8 | E25: =D25*$E$5 -> 737761.14 | F25: =D25*$F$5 -> 60681.653 | G25: =($Q$14*C25*$E$5*$S$10+$Q$14*C25*$F$5*$Q$6+$Q$16*C25*$E$5*$S$19+$Q$16*C25*$F$5*$Q$6)/1.13 -> 542188.24 | H25: =$D$35/1.06 -> 28301.887 | I25: =$F$35/1.06 -> 6603.7736 | J25: =税金参数!O23 -> 0 | K25: ='业主收益（租金、节能收益）'!D24/1.05 -> 4743.8095 | L25: =G25*0 -> 0 | M25: =税金参数!R23 -> 97164.597 | N25: 0 | O25: =G25-H25-I25-J25-K25-L25-M25 -> 405374.17 | Q25: 2月 | R25: =基础数据!K13 -> 49832.883 | T25: 2月 | V25: =R25*0.99 -> 49334.554
B26: 21 | C26: =C25-0.004 -> 0.91 | D26: =$Q$12*C26 -> 794948.52 | E26: =D26*$E$5 -> 734532.43 | F26: =D26*$F$5 -> 60416.087 | G26: =($Q$14*C26*$E$5*$S$10+$Q$14*C26*$F$5*$Q$6+$Q$16*C26*$E$5*$S$19+$Q$16*C26*$F$5*$Q$6)/1.13 -> 539815.42 | H26: =$D$35/1.06 -> 28301.887 | I26: =$F$35/1.06 -> 6603.7736 | J26: =税金参数!O24 -> 0 | K26: ='业主收益（租金、节能收益）'!D25/1.05 -> 4743.8095 | L26: =G26*0 -> 0 | M26: =税金参数!R24 -> 96719.908 | N26: 0 | O26: =G26-H26-I26-J26-K26-L26-M26 -> 403446.05 | Q26: 3月 | R26: =基础数据!K14 -> 74617.367 | T26: 3月 | V26: =R26*0.99 -> 73871.193
B27: 22 | C27: =C26-0.004 -> 0.906 | D27: =$Q$12*C27 -> 791454.24 | E27: =D27*$E$5 -> 731303.72 | F27: =D27*$F$5 -> 60150.522 | G27: =($Q$14*C27*$E$5*$S$10+$Q$14*C27*$F$5*$Q$6+$Q$16*C27*$E$5*$S$19+$Q$16*C27*$F$5*$Q$6)/1.13 -> 537442.61 | H27: =$D$35/1.06 -> 28301.887 | I27: =$F$35/1.06 -> 6603.7736 | J27: =税金参数!O25 -> 0 | K27: ='业主收益（租金、节能收益）'!D26/1.05 -> 4743.8095 | L27: =G27*0 -> 0 | M27: =税金参数!R25 -> 96275.218 | N27: 0 | O27: =G27-H27-I27-J27-K27-L27-M27 -> 401517.92 | Q27: 4月 | R27: =基础数据!K15 -> 88235.335 | T27: 4月 | V27: =R27*0.99 -> 87352.982
B28: 23 | C28: =C27-0.004 -> 0.902 | D28: =$Q$12*C28 -> 787959.96 | E28: =D28*$E$5 -> 728075 | F28: =D28*$F$5 -> 59884.957 | G28: =($Q$14*C28*$E$5*$S$10+$Q$14*C28*$F$5*$Q$6+$Q$16*C28*$E$5*$S$19+$Q$16*C28*$F$5*$Q$6)/1.13 -> 535069.79 | H28: =$D$35/1.06 -> 28301.887 | I28: =$F$35/1.06 -> 6603.7736 | J28: =税金参数!O26 -> 0 | K28: ='业主收益（租金、节能收益）'!D27/1.05 -> 4743.8095 | L28: =G28*0 -> 0 | M28: =税金参数!R26 -> 95830.529 | N28: 0 | O28: =G28-H28-I28-J28-K28-L28-M28 -> 399589.79 | Q28: 5月 | R28: =基础数据!K16 -> 94681.455 | T28: 5月 | V28: =R28*0.99 -> 93734.641
B29: 24 | C29: =C28-0.004 -> 0.898 | D29: =$Q$12*C29 -> 784465.68 | E29: =D29*$E$5 -> 724846.29 | F29: =D29*$F$5 -> 59619.392 | G29: =($Q$14*C29*$E$5*$S$10+$Q$14*C29*$F$5*$Q$6+$Q$16*C29*$E$5*$S$19+$Q$16*C29*$F$5*$Q$6)/1.13 -> 532696.98 | H29: =$D$35/1.06 -> 28301.887 | I29: =$F$35/1.06 -> 6603.7736 | J29: =税金参数!O27 -> 0 | K29: ='业主收益（租金、节能收益）'!D28/1.05 -> 4743.8095 | L29: =G29*0 -> 0 | M29: =税金参数!R27 -> 95385.84 | N29: 0 | O29: =G29-H29-I29-J29-K29-L29-M29 -> 397661.67 | Q29: 6月 | R29: =基础数据!K17 -> 86994.255 | T29: 6月 | V29: =R29*0.99 -> 86124.312
B30: 25 | C30: =C29-0.004 -> 0.894 | D30: =$Q$12*C30 -> 780971.4 | E30: =D30*$E$5 -> 721617.57 | F30: =D30*$F$5 -> 59353.826 | G30: =($Q$14*C30*$E$5*$S$10+$Q$14*C30*$F$5*$Q$6+$Q$16*C30*$E$5*$S$19+$Q$16*C30*$F$5*$Q$6)/1.13 -> 530324.16 | H30: =$D$35/1.06 -> 28301.887 | I30: =$F$35/1.06 -> 6603.7736 | J30: =税金参数!O28 -> 0 | K30: ='业主收益（租金、节能收益）'!D29/1.05 -> 4743.8095 | L30: =G30*0 -> 0 | M30: =税金参数!R28 -> 94941.151 | N30: 0 | O30: =G30-H30-I30-J30-K30-L30-M30 -> 395733.54 | Q30: 7月 | R30: =基础数据!K18 -> 118738.77 | T30: 7月 | V30: =R30*0.99 -> 117551.38
B31: 合计 | D31: =SUM(D6:D30) -> 20572569 | E31: =SUM(E6:E30) -> 19009054 | F31: =SUM(F6:F30) -> 1563515.2 | G31: =SUM(G6:G30) -> 13969949 | H31: =SUM(H6:H30) -> 707547.17 | I31: =SUM(I6:I30) -> 165094.34 | J31: =SUM(J6:J30) -> 523125.07 | K31: =SUM(K6:K30) -> 118595.24 | ... M31: =SUM(M6:M30) -> 2273654.8 | O31: =SUM(O6:O30) -> 10181932 | Q31: 8月 | R31: =基础数据!K19 -> 114431.51 | T31: 8月 | V31: =R31*0.99 -> 113287.19
Q32: 9月 | R32: =基础数据!K20 -> 78449.67 | T32: 9月 | V32: =R32*0.99 -> 77665.173
Q33: 10月 | R33: =基础数据!K21 -> 50754.032 | T33: 10月 | V33: =R33*0.99 -> 50246.492
C34: 工程造价 | D34: =基础数据!H7 -> 2000000 | Q34: 11月 | R34: =基础数据!K22 -> 43112.045 | T34: 11月 | V34: =R34*0.99 -> 42680.925
C35: 运维费用 | D35: =基础数据!J29 -> 30000 | E35: 保险费用 | F35: =基础数据!J27 -> 7000 | Q35: 12月 | R35: =基础数据!K23 -> 34512.16 | T35: 12月 | V35: =R35*0.99 -> 34167.039
Q36: 合计 | R36: =SUM(R24:R35) -> 873569.8 | T36: 合计 | V36: =SUM(V24:W35) -> 864834.1
A37: . | C37: *假设运维保险开专票

Sheet 业主收益（租金、节能收益）
C3: 业主租金收益 | I3: 业主节能收益
C4: 年份 | D4: 业主租金收益（元/年） | E4: 累计租金收益（元） | I4: 年发电量预估（峰值日照时长平均值） | L4: 消纳率 | M4: 业主节能收益（元/年）
C5: 1 | D5: =$A$8*$A$10 -> 4981 | E5: =D5 -> 4981 | I5: 年份 | J5: 系统发电效率 | K5: 发电量 | L5: 0.5853
C6: 2 | D6: =$A$8*$A$10 -> 4981 | E6: =E5+D6 -> 9962 | I6: 1 | J6: ='光伏发电衰减表 输入数据'!C6 -> 0.99 | K6: ='光伏发电衰减表 输入数据'!D6 -> 864834.1 | L6: =K6*$L$5 -> 506187.4 | M6: =L6*$G$14 -> 78965.234
A7: 租赁面积（㎡） | C7: 3 | D7: =$A$8*$A$10 -> 4981 | E7: =E6+D7 -> 14943 | G7: 南网电价（元/KWh） | I7: 2 | J7: ='光伏发电衰减表 输入数据'!C7 -> 0.986 | K7: ='光伏发电衰减表 输入数据'!D7 -> 861339.82 | L7: =K7*$L$5 -> 504142.2 | M7: =L7*$G$14 -> 78646.183
A8: 4981 | C8: 4 | D8: =$A$8*$A$10 -> 4981 | E8: =E7+D8 -> 19924 | G8: 0.78 | I8: 3 | J8: ='光伏发电衰减表 输入数据'!C8 -> 0.982 | K8: ='光伏发电衰减表 输入数据'!D8 -> 857845.54 | L8: =K8*$L$5 -> 502097 | M8: =L8*$G$14 -> 78327.131
A9: 租金（元/㎡/年） | C9: 5 | D9: =$A$8*$A$10 -> 4981 | E9: =E8+D9 -> 24905 | G9: 电能折扣（%） | I9: 4 | J9: ='光伏发电衰减表 输入数据'!C9 -> 0.978 | K9: ='光伏发电衰减表 输入数据'!D9 -> 854351.26 | L9: =K9*$L$5 -> 500051.79 | M9: =L9*$G$14 -> 78008.08
A10: 1 | C10: 6 | D10: =$A$8*$A$10 -> 4981 | E10: =E9+D10 -> 29886 | G10: 0.8 | I10: 5 | J10: ='光伏发电衰减表 输入数据'!C10 -> 0.974 | K10: ='光伏发电衰减表 输入数据'!D10 -> 850856.98 | L10: =K10*$L$5 -> 498006.59 | M10: =L10*$G$14 -> 77689.028
C11: 7 | D11: =$A$8*$A$10 -> 4981 | E11: =E10+D11 -> 34867 | G11: 打折电价（元/KWh） | I11: 6 | J11: ='光伏发电衰减表 输入数据'!C11 -> 0.97 | K11: ='光伏发电衰减表 输入数据'!D11 -> 847362.7 | L11: =K11*$L$5 -> 495961.39 | M11: =L11*$G$14 -> 77369.977
C12: 8 | D12: =$A$8*$A$10 -> 4981 | E12: =E11+D12 -> 39848 | G12: =G8*G10 -> 0.624 | I12: 7 | J12: ='光伏发电衰减表 输入数据'!C12 -> 0.966 | K12: ='光伏发电衰减表 输入数据'!D12 -> 843868.43 | L12: =K12*$L$5 -> 493916.19 | M12: =L12*$G$14 -> 77050.926
C13: 9 | D13: =$A$8*$A$10 -> 4981 | E13: =E12+D13 -> 44829 | G13: 每消纳1KWh能节约（元/KWh） | I13: 8 | J13: ='光伏发电衰减表 输入数据'!C13 -> 0.962 | K13: ='光伏发电衰减表 输入数据'!D13 -> 840374.15 | L13: =K13*$L$5 -> 491870.99 | M13: =L13*$G$14 -> 76731.874
C14: 10 | D14: =$A$8*$A$10 -> 4981 | E14: =E13+D14 -> 49810 | G14: =G8-G12 -> 0.156 | I14: 9 | J14: ='光伏发电衰减表 输入数据'!C14 -> 0.958 | K14: ='光伏发电衰减表 输入数据'!D14 -> 836879.87 | L14: =K14*$L$5 -> 489825.79 | M14: =L14*$G$14 -> 76412.823
C15: 11 | D15: =$A$8*$A$10 -> 4981 | E15: =E14+D15 -> 54791 | I15: 10 | J15: ='光伏发电衰减表 输入数据'!C15 -> 0.954 | K15: ='光伏发电衰减表 输入数据'!D15 -> 833385.59 | L15: =K15*$L$5 -> 487780.58 | M15: =L15*$G$14 -> 76093.771
C16: 12 | D16: =$A$8*$A$10 -> 4981 | E16: =E15+D16 -> 59772 | I16: 11 | J16: ='光伏发电衰减表 输入数据'!C16 -> 0.95 | K16: ='光伏发电衰减表 输入数据'!D16 -> 829891.31 | L16: =K16*$L$5 -> 485735.38 | M16: =L16*$G$14 -> 75774.72
C17: 13 | D17: =$A$8*$A$10 -> 4981 | E17: =E16+D17 -> 64753 | I17: 12 | J17: ='光伏发电衰减表 输入数据'!C17 -> 0.946 | K17: ='光伏发电衰减表 输入数据'!D17 -> 826397.03 | L17: =K17*$L$5 -> 483690.18 | M17: =L17*$G$14 -> 75455.668
C18: 14 | D18: =$A$8*$A$10 -> 4981 | E18: =E17+D18 -> 69734 | I18: 13 | J18: ='光伏发电衰减表 输入数据'!C18 -> 0.942 | K18: ='光伏发电衰减表 输入数据'!D18 -> 822902.75 | L18: =K18*$L$5 -> 481644.98 | M18: =L18*$G$14 -> 75136.617
C19: 15 | D19: =$A$8*$A$10 -> 4981 | E19: =E18+D19 -> 74715 | I19: 14 | J19: ='光伏发电衰减表 输入数据'!C19 -> 0.938 | K19: ='光伏发电衰减表 输入数据'!D19 -> 819408.47 | L19: =K19*$L$5 -> 479599.78 | M19: =L19*$G$14 -> 74817.565
C20: 16 | D20: =$A$8*$A$10 -> 4981 | E20: =E19+D20 -> 79696 | I20: 15 | J20: ='光伏发电衰减表 输入数据'!C20 -> 0.934 | K20: ='光伏发电衰减表 输入数据'!D20 -> 815914.19 | L20: =K20*$L$5 -> 477554.58 | M20: =L20*$G$14 -> 74498.514
C21: 17 | D21: =$A$8*$A$10 -> 4981 | E21: =E20+D21 -> 84677 | I21: 16 | J21: ='光伏发电衰减表 输入数据'!C21 -> 0.93 | K21: ='光伏发电衰减表 输入数据'!D21 -> 812419.91 | L21: =K21*$L$5 -> 475509.38 | M21: =L21*$G$14 -> 74179.463
C22: 18 | D22: =$A$8*$A$10 -> 4981 | E22: =E21+D22 -> 89658 | I22: 17 | J22: ='光伏发电衰减表 输入数据'!C22 -> 0.926 | K22: ='光伏发电衰减表 输入数据'!D22 -> 808925.63 | L22: =K22*$L$5 -> 473464.17 | M22: =L22*$G$14 -> 73860.411
C23: 19 | D23: =$A$8*$A$10 -> 4981 | E23: =E22+D23 -> 94639 | I23: 18 | J23: ='光伏发电衰减表 输入数据'!C23 -> 0.922 | K23: ='光伏发电衰减表 输入数据'!D23 -> 805431.35 | L23: =K23*$L$5 -> 471418.97 | M23: =L23*$G$14 -> 73541.36
C24: 20 | D24: =$A$8*$A$10 -> 4981 | E24: =E23+D24 -> 99620 | I24: 19 | J24: ='光伏发电衰减表 输入数据'!C24 -> 0.918 | K24: ='光伏发电衰减表 输入数据'!D24 -> 801937.08 | L24: =K24*$L$5 -> 469373.77 | M24: =L24*$G$14 -> 73222.308
C25: 21 | D25: =$A$8*$A$10 -> 4981 | E25: =E24+D25 -> 104601 | I25: 20 | J25: ='光伏发电衰减表 输入数据'!C25 -> 0.914 | K25: ='光伏发电衰减表 输入数据'!D25 -> 798442.8 | L25: =K25*$L$5 -> 467328.57 | M25: =L25*$G$14 -> 72903.257
C26: 22 | D26: =$A$8*$A$10 -> 4981 | E26: =E25+D26 -> 109582 | I26: 21 | J26: ='光伏发电衰减表 输入数据'!C26 -> 0.91 | K26: ='光伏发电衰减表 输入数据'!D26 -> 794948.52 | L26: =K26*$L$5 -> 465283.37 | M26: =L26*$G$14 -> 72584.205
... C29: 25 | D29: =$A$8*$A$10 -> 4981 | E29: =E28+D29 -> 124525 | I29: 24 | J29: ='光伏发电衰减表 输入数据'!C29 -> 0.898 | K29: ='光伏发电衰减表 输入数据'!D29 -> 784465.68 | L29: =K29*$L$5 -> 459147.76 | M29: =L29*$G$14 -> 71627.051
I30: 25 | J30: ='光伏发电衰减表 输入数据'!C30 -> 0.894 | K30: ='光伏发电衰减表 输入数据'!D30 -> 780971.4 | L30: =K30*$L$5 -> 457102.56 | M30: =L30*$G$14 -> 71307.999
I31: 合计 | K31: =SUM(K6:K30) -> 20572569 | L31: =SUM(L6:L30) -> 12041124 | M31: =SUM(M6:M30) -> 1878415.4

Sheet 税金参数
E2: 本测算表假设5% | F2: *增值税正负处抵扣完要手动转换公式 数字转正后第一个表格同上公式，正数第二个表格用新公式 | H2: *小微税率 | I2: *小微税率 | J2: *小微税率 | O2: *等额本息（融资租赁） | Q2: *小微税率
B3: 年份 | C3: 发电收入增值税(卖电＋上网） | D3: 运维、保险留抵进项税 | E3: 租金留抵进项税5% | F3: 增值税 | G3: 应交增值税 | H3: 城市维护建设税 | I3: 教育费附加税 | J3: 地方教育附加 | K3: 税金及附加 | L3: 折旧摊销 | M3: 经营费5% | N3: 租金 | O3: 资金成本 | P3: 应税所得额（利润） | Q3: 应交所得税5% | R3: 税金合计
B4: 1 | C4: ='光伏发电衰减表 输入数据'!G6*0.13 -> 76345.324 | D4: =$C$39/1.06*0.06+$E$39/1.06*0.06 -> 2094.3396 | E4: ='业主收益（租金、节能收益）'!D5/1.05*0.05 -> 237.19048 | F4: =-$E$41-D4-E4+C4 -> -91123.821 | G4: =IF(F4<0,0,F4) -> 0 | H4: =G4*$L$40 -> 0 | I4: =G4*$L$41 -> 0 | J4: =G4*$L$42 -> 0 | K4: =SUM(H4:J4) -> 0 | L4: =$C$41*(2/10*100%) -> 366972.48 | M4: ='光伏发电衰减表 输入数据'!L6 -> 0 | N4: ='业主收益（租金、节能收益）'!D5/1.05 -> 4743.8095 | O4: ='等额本息（融资租赁）'!P10 -> 112485.37 | P4: ='光伏发电衰减表 输入数据'!G6-$C$39/1.06-$E$39/1.06-L4-M4-N4-O4-K4 -> 68164.402 | Q4: =IF(P4<0,0,P4*$L$43) -> 3408.2201 | R4: =G4+K4+Q4 -> 3408.2201
B5: 2 | C5: ='光伏发电衰减表 输入数据'!G7*0.13 -> 76036.858 | D5: =$C$39/1.06*0.06+$E$39/1.06*0.06 -> 2094.3396 | E5: ='业主收益（租金、节能收益）'!D6/1.05*0.05 -> 237.19048 | F5: =-$E$41-SUM($D$4:D5)-SUM($E$4:E5)+SUM($C$4:C5) -> -17418.493 | G5: =IF(F5<0,0,F5) -> 0 | H5: =G5*$L$40 -> 0 | I5: =G5*$L$41 -> 0 | J5: =G5*$L$42 -> 0 | K5: =SUM(H5:J5) -> 0 | L5: =($C$41-L4)*(2/10*100%) -> 293577.98 | M5: ='光伏发电衰减表 输入数据'!L7 -> 0 | N5: ='业主收益（租金、节能收益）'!D6/1.05 -> 4743.8095 | O5: ='等额本息（融资租赁）'!P11 -> 102387.15 | P5: ='光伏发电衰减表 输入数据'!G7-$C$39/1.06-$E$39/1.06-L5-M5-N5-O5-K5 -> 149284.3 | Q5: =IF(P5<0,0,P5*$L$43) -> 7464.2152 | R5: =G5+K5+Q5 -> 7464.2152
B6: 3 | C6: ='光伏发电衰减表 输入数据'!G8*0.13 -> 75728.392 | D6: =$C$39/1.06*0.06+$E$39/1.06*0.06 -> 2094.3396 | E6: ='业主收益（租金、节能收益）'!D7/1.05*0.05 -> 237.19048 | F6: =-$E$41-SUM($D$4:D6)-SUM($E$4:E6)+SUM($C$4:C6) -> 55978.37 | G6: =IF(F6<0,0,F6) -> 55978.37 | H6: =G6*$L$40 -> 1959.2429 | I6: =G6*$L$41 -> 839.67554 | J6: =G6*$L$42 -> 559.7837 | K6: =SUM(H6:J6) -> 3358.7022 | L6: =($C$41-L5-L4)*(2/10*100%) -> 234862.39 | M6: ='光伏发电衰减表 输入数据'!L8 -> 0 | N6: ='业主收益（租金、节能收益）'!D7/1.05 -> 4743.8095 | O6: ='等额本息（融资租赁）'!P12 -> 89249.336 | P6: ='光伏发电衰减表 输入数据'!G8-$C$39/1.06-$E$39/1.06-L6-M6-N6-O6-K6 -> 215406.2 | Q6: =IF(P6<0,0,P6*$L$43) -> 10770.31 | R6: =G6+K6+Q6 -> 70107.382
B7: 4 | C7: ='光伏发电衰减表 输入数据'!G9*0.13 -> 75419.926 | D7: =$C$39/1.06*0.06+$E$39/1.06*0.06 -> 2094.3396 | E7: ='业主收益（租金、节能收益）'!D8/1.05*0.05 -> 237.19048 | F7: =-$E$41-SUM($D$4:D7)-SUM($E$4:E7)+SUM($C$4:C7) -> 129066.77 | G7: =IF(F7<0,0,F7) -> 129066.77 | H7: =G7*$L$40 -> 4517.3368 | I7: =G7*$L$41 -> 1936.0015 | J7: =G7*$L$42 -> 1290.6677 | K7: =SUM(H7:J7) -> 7744.0059 | L7: =($C$41-L6-L5-L4)*(2/10*100%) -> 187889.91 | M7: ='光伏发电衰减表 输入数据'!L9 -> 0 | N7: ='业主收益（租金、节能收益）'!D8/1.05 -> 4743.8095 | O7: ='等额本息（融资租赁）'!P13 -> 75301.208 | P7: ='光伏发电衰减表 输入数据'!G9-$C$39/1.06-$E$39/1.06-L7-M7-N7-O7-K7 -> 269568.69 | Q7: =IF(P7<0,0,P7*$L$43) -> 13478.434 | R7: =G7+K7+Q7 -> 150289.21
B8: 5 | C8: ='光伏发电衰减表 输入数据'!G10*0.13 -> 75111.46 | D8: =$C$39/1.06*0.06+$E$39/1.06*0.06 -> 2094.3396 | E8: ='业主收益（租金、节能收益）'!D9/1.05*0.05 -> 237.19048 | F8: =C8-D8-E8 -> 72779.93 | G8: =IF(F8<0,0,F8) -> 72779.93 | H8: =G8*$L$40 -> 2547.2976 | I8: =G8*$L$41 -> 1091.699 | J8: =G8*$L$42 -> 727.7993 | K8: =SUM(H8:J8) -> 4366.7958 | L8: =($C$41-L7-L6-L5-L4)*(2/10*100%) -> 150311.93 | M8: ='光伏发电衰减表 输入数据'!L10 -> 0 | N8: ='业主收益（租金、节能收益）'!D9/1.05 -> 4743.8095 | O8: ='等额本息（融资租赁）'!P14 -> 60492.79 | P8: ='光伏发电衰减表 输入数据'!G10-$C$39/1.06-$E$39/1.06-L8-M8-N8-O8-K8 -> 322959.48 | Q8: =IF(P8<0,0,P8*$L$43) -> 16147.974 | R8: =G8+K8+Q8 -> 93294.7
B9: 6 | C9: ='光伏发电衰减表 输入数据'!G11*0.13 -> 74802.994 | D9: =$C$39/1.06*0.06+$E$39/1.06*0.06 -> 2094.3396 | E9: ='业主收益（租金、节能收益）'!D10/1.05*0.05 -> 237.19048 | F9: =C9-D9-E9 -> 72471.464 | G9: =IF(F9<0,0,F9) -> 72471.464 | H9: =G9*$L$40 -> 2536.5012 | I9: =G9*$L$41 -> 1087.072 | J9: =G9*$L$42 -> 724.71464 | K9: =SUM(H9:J9) -> 4348.2879 | L9: =($C$41-L8-L7-L6-L5-L4)*(2/10*100%) -> 120249.54 | M9: ='光伏发电衰减表 输入数据'!L11 -> 0 | N9: ='业主收益（租金、节能收益）'!D10/1.05 -> 4743.8095 | O9: ='等额本息（融资租赁）'!P15 -> 44771.021 | P9: ='光伏发电衰减表 输入数据'!G11-$C$39/1.06-$E$39/1.06-L9-M9-N9-O9-K9 -> 366389.33 | Q9: =IF(P9<0,0,P9*$L$43) -> 18319.466 | R9: =G9+K9+Q9 -> 95139.219
B10: 7 | C10: ='光伏发电衰减表 输入数据'!G12*0.13 -> 74494.528 | D10: =$C$39/1.06*0.06+$E$39/1.06*0.06 -> 2094.3396 | E10: ='业主收益（租金、节能收益）'!D11/1.05*0.05 -> 237.19048 | F10: =C10-D10-E10 -> 72162.998 | G10: =IF(F10<0,0,F10) -> 72162.998 | H10: =G10*$L$40 -> 2525.7049 | I10: =G10*$L$41 -> 1082.445 | J10: =G10*$L$42 -> 721.62998 | K10: =SUM(H10:J10) -> 4329.7799 | L10: =($C$41-L9-L8-L7-L6-L5-L4)*(2/10*100%) -> 96199.633 | M10: ='光伏发电衰减表 输入数据'!L12 -> 0 | N10: ='业主收益（租金、节能收益）'!D11/1.05 -> 4743.8095 | O10: ='等额本息（融资租赁）'!P16 -> 28079.568 | P10: ='光伏发电衰减表 输入数据'!G12-$C$39/1.06-$E$39/1.06-L10-M10-N10-O10-K10 -> 404776.38 | Q10: =IF(P10<0,0,P10*$L$43) -> 20238.819 | R10: =G10+K10+Q10 -> 96731.597
B11: 8 | C11: ='光伏发电衰减表 输入数据'!G13*0.13 -> 74186.062 | D11: =$C$39/1.06*0.06+$E$39/1.06*0.06 -> 2094.3396 | E11: ='业主收益（租金、节能收益）'!D12/1.05*0.05 -> 237.19048 | F11: =C11-D11-E11 -> 71854.532 | G11: =IF(F11<0,0,F11) -> 71854.532 | H11: =G11*$L$40 -> 2514.9086 | I11: =G11*$L$41 -> 1077.818 | J11: =G11*$L$42 -> 718.54532 | K11: =SUM(H11:J11) -> 4311.2719 | L11: =($C$41-L10-L9-L8-L7-L6-L5-L4)*(2/10*100%) -> 76959.706 | M11: ='光伏发电衰减表 输入数据'!L13 -> 0 | N11: ='业主收益（租金、节能收益）'!D12/1.05 -> 4743.8095 | O11: ='等额本息（融资租赁）'!P17 -> 10358.622 | P11: ='光伏发电衰减表 输入数据'!G13-$C$39/1.06-$E$39/1.06-L11-M11-N11-O11-K11 -> 439382.95 | Q11: =IF(P11<0,0,P11*$L$43) -> 21969.147 | R11: =G11+K11+Q11 -> 98134.952
B12: 9 | C12: ='光伏发电衰减表 输入数据'!G14*0.13 -> 73877.596 | D12: =$C$39/1.06*0.06+$E$39/1.06*0.06 -> 2094.3396 | E12: ='业主收益（租金、节能收益）'!D13/1.05*0.05 -> 237.19048 | F12: =C12-D12-E12 -> 71546.066 | G12: =IF(F12<0,0,F12) -> 71546.066 | H12: =G12*$L$40 -> 2504.1123 | I12: =G12*$L$41 -> 1073.191 | J12: =G12*$L$42 -> 715.46066 | K12: =SUM(H12:J12) -> 4292.764 | L12: =(C41-SUM(L4:L11))/2 -> 153919.41 | M12: ='光伏发电衰减表 输入数据'!L14 -> 0 | N12: ='业主收益（租金、节能收益）'!D13/1.05 -> 4743.8095 | O12: ='等额本息（融资租赁）'!P18 -> 0 | P12: ='光伏发电衰减表 输入数据'!G14-$C$39/1.06-$E$39/1.06-L12-M12-N12-O12-K12 -> 370427.56 | Q12: =IF(P12<0,0,P12*$L$43) -> 18521.378 | R12: =G12+K12+Q12 -> 94360.208
B13: 10 | C13: ='光伏发电衰减表 输入数据'!G15*0.13 -> 73569.131 | D13: =$C$39/1.06*0.06+$E$39/1.06*0.06 -> 2094.3396 | E13: ='业主收益（租金、节能收益）'!D14/1.05*0.05 -> 237.19048 | F13: =C13-D13-E13 -> 71237.6 | G13: =IF(F13<0,0,F13) -> 71237.6 | H13: =G13*$L$40 -> 2493.316 | I13: =G13*$L$41 -> 1068.564 | J13: =G13*$L$42 -> 712.376 | K13: =SUM(H13:J13) -> 4274.256 | L13: =L12 -> 153919.41 | M13: ='光伏发电衰减表 输入数据'!L15 -> 0 | N13: ='业主收益（租金、节能收益）'!D14/1.05 -> 4743.8095 | O13: ='等额本息（融资租赁）'!P19 -> 0 | P13: ='光伏发电衰减表 输入数据'!G15-$C$39/1.06-$E$39/1.06-L13-M13-N13-O13-K13 -> 368073.25 | Q13: =IF(P13<0,0,P13*$L$43) -> 18403.662 | R13: =G13+K13+Q13 -> 93915.519
B14: 11 | C14: ='光伏发电衰减表 输入数据'!G16*0.13 -> 73260.665 | D14: =$C$39/1.06*0.06+$E$39/1.06*0.06 -> 2094.3396 | E14: ='业主收益（租金、节能收益）'!D15/1.05*0.05 -> 237.19048 | F14: =C14-D14-E14 -> 70929.134 | G14: =IF(F14<0,0,F14) -> 70929.134 | H14: =G14*$L$40 -> 2482.5197 | I14: =G14*$L$41 -> 1063.937 | J14: =G14*$L$42 -> 709.29134 | K14: =SUM(H14:J14) -> 4255.7481 | L14: 0 | M14: ='光伏发电衰减表 输入数据'!L16 -> 0 | N14: ='业主收益（租金、节能收益）'!D15/1.05 -> 4743.8095 | O14: ='等额本息（融资租赁）'!P20 -> 0 | P14: ='光伏发电衰减表 输入数据'!G16-$C$39/1.06-$E$39/1.06-L14-M14-N14-O14-K14 -> 519638.36 | Q14: =IF(P14<0,0,P14*$L$43) -> 25981.918 | R14: =G14+K14+Q14 -> 101166.8
B15: 12 | C15: ='光伏发电衰减表 输入数据'!G17*0.13 -> 72952.199 | D15: =$C$39/1.06*0.06+$E$39/1.06*0.06 -> 2094.3396 | E15: ='业主收益（租金、节能收益）'!D16/1.05*0.05 -> 237.19048 | F15: =C15-D15-E15 -> 70620.669 | G15: =IF(F15<0,0,F15) -> 70620.669 | H15: =G15*$L$40 -> 2471.7234 | I15: =G15*$L$41 -> 1059.31 | J15: =G15*$L$42 -> 706.20669 | K15: =SUM(H15:J15) -> 4237.2401 | L15: 0 | M15: ='光伏发电衰减表 输入数据'!L17 -> 0 | N15: ='业主收益（租金、节能收益）'!D16/1.05 -> 4743.8095 | O15: ='等额本息（融资租赁）'!P21 -> 0 | P15: ='光伏发电衰减表 输入数据'!G17-$C$39/1.06-$E$39/1.06-L15-M15-N15-O15-K15 -> 517284.05 | Q15: =IF(P15<0,0,P15*$L$43) -> 25864.202 | R15: =G15+K15+Q15 -> 100722.11
B16: 13 | C16: ='光伏发电衰减表 输入数据'!G18*0.13 -> 72643.733 | D16: =$C$39/1.06*0.06+$E$39/1.06*0.06 -> 2094.3396 | E16: ='业主收益（租金、节能收益）'!D17/1.05*0.05 -> 237.19048 | F16: =C16-D16-E16 -> 70312.203 | G16: =IF(F16<0,0,F16) -> 70312.203 | H16: =G16*$L$40 -> 2460.9271 | I16: =G16*$L$41 -> 1054.683 | J16: =G16*$L$42 -> 703.12203 | K16: =SUM(H16:J16) -> 4218.7322 | L16: 0 | M16: ='光伏发电衰减表 输入数据'!L18 -> 0 | N16: ='业主收益（租金、节能收益）'!D17/1.05 -> 4743.8095 | O16: ='等额本息（融资租赁）'!P22 -> 0 | P16: ='光伏发电衰减表 输入数据'!G18-$C$39/1.06-$E$39/1.06-L16-M16-N16-O16-K16 -> 514929.74 | Q16: =IF(P16<0,0,P16*$L$43) -> 25746.487 | R16: =G16+K16+Q16 -> 100277.42
B17: 14 | C17: ='光伏发电衰减表 输入数据'!G19*0.13 -> 72335.267 | D17: =$C$39/1.06*0.06+$E$39/1.06*0.06 -> 2094.3396 | E17: ='业主收益（租金、节能收益）'!D18/1.05*0.05 -> 237.19048 | F17: =C17-D17-E17 -> 70003.737 | G17: =IF(F17<0,0,F17) -> 70003.737 | H17: =G17*$L$40 -> 2450.1308 | I17: =G17*$L$41 -> 1050.056 | J17: =G17*$L$42 -> 700.03737 | K17: =SUM(H17:J17) -> 4200.2242 | L17: 0 | M17: ='光伏发电衰减表 输入数据'!L19 -> 0 | N17: ='业主收益（租金、节能收益）'!D18/1.05 -> 4743.8095 | O17: ='等额本息（融资租赁）'!P23 -> 0 | P17: ='光伏发电衰减表 输入数据'!G19-$C$39/1.06-$E$39/1.06-L17-M17-N17-O17-K17 -> 512575.43 | Q17: =IF(P17<0,0,P17*$L$43) -> 25628.772 | R17: =G17+K17+Q17 -> 99832.733
B18: 15 | C18: ='光伏发电衰减表 输入数据'!G20*0.13 -> 72026.801 | D18: =$C$39/1.06*0.06+$E$39/1.06*0.06 -> 2094.3396 | E18: ='业主收益（租金、节能收益）'!D19/1.05*0.05 -> 237.19048 | F18: =C18-D18-E18 -> 69695.271 | G18: =IF(F18<0,0,F18) -> 69695.271 | H18: =G18*$L$40 -> 2439.3345 | I18: =G18*$L$41 -> 1045.4291 | J18: =G18*$L$42 -> 696.95271 | K18: =SUM(H18:J18) -> 4181.7162 | L18: 0 | M18: ='光伏发电衰减表 输入数据'!L20 -> 0 | N18: ='业主收益（租金、节能收益）'!D19/1.05 -> 4743.8095 | O18: ='等额本息（融资租赁）'!P24 -> 0 | P18: ='光伏发电衰减表 输入数据'!G20-$C$39/1.06-$E$39/1.06-L18-M18-N18-O18-K18 -> 510221.13 | Q18: =IF(P18<0,0,P18*$L$43) -> 25511.056 | R18: =G18+K18+Q18 -> 99388.043
B19: 16 | C19: ='光伏发电衰减表 输入数据'!G21*0.13 -> 71718.335 | D19: =$C$39/1.06*0.06+$E$39/1.06*0.06 -> 2094.3396 | E19: ='业主收益（租金、节能收益）'!D20/1.05*0.05 -> 237.19048 | F19: =C19-D19-E19 -> 69386.805 | G19: =IF(F19<0,0,F19) -> 69386.805 | H19: =G19*$L$40 -> 2428.5382 | I19: =G19*$L$41 -> 1040.8021 | J19: =G19*$L$42 -> 693.86805 | K19: =SUM(H19:J19) -> 4163.2083 | L19: 0 | M19: ='光伏发电衰减表 输入数据'!L21 -> 0 | N19: ='业主收益（租金、节能收益）'!D20/1.05 -> 4743.8095 | O19: ='等额本息（融资租赁）'!P25 -> 0 | P19: ='光伏发电衰减表 输入数据'!G21-$C$39/1.06-$E$39/1.06-L19-M19-N19-O19-K19 -> 507866.82 | Q19: =IF(P19<0,0,P19*$L$43) -> 25393.341 | R19: =G19+K19+Q19 -> 98943.354
B20: 17 | C20: ='光伏发电衰减表 输入数据'!G22*0.13 -> 71409.869 | D20: =$C$39/1.06*0.06+$E$39/1.06*0.06 -> 2094.3396 | E20: ='业主收益（租金、节能收益）'!D21/1.05*0.05 -> 237.19048 | F20: =C20-D20-E20 -> 69078.339 | G20: =IF(F20<0,0,F20) -> 69078.339 | H20: =G20*$L$40 -> 2417.7419 | I20: =G20*$L$41 -> 1036.1751 | J20: =G20*$L$42 -> 690.78339 | K20: =SUM(H20:J20) -> 4144.7003 | L20: 0 | M20: ='光伏发电衰减表 输入数据'!L22 -> 0 | N20: ='业主收益（租金、节能收益）'!D21/1.05 -> 4743.8095 | O20: ='等额本息（融资租赁）'!P26 -> 0 | P20: ='光伏发电衰减表 输入数据'!G22-$C$39/1.06-$E$39/1.06-L20-M20-N20-O20-K20 -> 505512.51 | Q20: =IF(P20<0,0,P20*$L$43) -> 25275.626 | R20: =G20+K20+Q20 -> 98498.665
B21: 18 | C21: ='光伏发电衰减表 输入数据'!G23*0.13 -> 71101.403 | D21: =$C$39/1.06*0.06+$E$39/1.06*0.06 -> 2094.3396 | E21: ='业主收益（租金、节能收益）'!D22/1.05*0.05 -> 237.19048 | F21: =C21-D21-E21 -> 68769.873 | G21: =IF(F21<0,0,F21) -> 68769.873 | H21: =G21*$L$40 -> 2406.9455 | I21: =G21*$L$41 -> 1031.5481 | J21: =G21*$L$42 -> 687.69873 | K21: =SUM(H21:J21) -> 4126.1924 | L21: 0 | M21: ='光伏发电衰减表 输入数据'!L23 -> 0 | N21: ='业主收益（租金、节能收益）'!D22/1.05 -> 4743.8095 | O21: ='等额本息（融资租赁）'!P27 -> 0 | P21: ='光伏发电衰减表 输入数据'!G23-$C$39/1.06-$E$39/1.06-L21-M21-N21-O21-K21 -> 503158.21 | Q21: =IF(P21<0,0,P21*$L$43) -> 25157.91 | R21: =G21+K21+Q21 -> 98053.975
B22: 19 | C22: ='光伏发电衰减表 输入数据'!G24*0.13 -> 70792.937 | D22: =$C$39/1.06*0.06+$E$39/1.06*0.06 -> 2094.3396 | E22: ='业主收益（租金、节能收益）'!D23/1.05*0.05 -> 237.19048 | F22: =C22-D22-E22 -> 68461.407 | G22: =IF(F22<0,0,F22) -> 68461.407 | H22: =G22*$L$40 -> 2396.1492 | I22: =G22*$L$41 -> 1026.9211 | J22: =G22*$L$42 -> 684.61407 | K22: =SUM(H22:J22) -> 4107.6844 | L22: 0 | M22: ='光伏发电衰减表 输入数据'!L24 -> 0 | N22: ='业主收益（租金、节能收益）'!D23/1.05 -> 4743.8095 | O22: ='等额本息（融资租赁）'!P28 -> 0 | P22: ='光伏发电衰减表 输入数据'!G24-$C$39/1.06-$E$39/1.06-L22-M22-N22-O22-K22 -> 500803.9 | Q22: =IF(P22<0,0,P22*$L$43) -> 25040.195 | R22: =G22+K22+Q22 -> 97609.286
B23: 20 | C23: ='光伏发电衰减表 输入数据'!G25*0.13 -> 70484.471 | D23: =$C$39/1.06*0.06+$E$39/1.06*0.06 -> 2094.3396 | E23: ='业主收益（租金、节能收益）'!D24/1.05*0.05 -> 237.19048 | F23: =C23-D23-E23 -> 68152.941 | G23: =IF(F23<0,0,F23) -> 68152.941 | H23: =G23*$L$40 -> 2385.3529 | I23: =G23*$L$41 -> 1022.2941 | J23: =G23*$L$42 -> 681.52941 | K23: =SUM(H23:J23) -> 4089.1765 | L23: 0 | M23: ='光伏发电衰减表 输入数据'!L25 -> 0 | N23: ='业主收益（租金、节能收益）'!D24/1.05 -> 4743.8095 | O23: ='等额本息（融资租赁）'!P29 -> 0 | P23: ='光伏发电衰减表 输入数据'!G25-$C$39/1.06-$E$39/1.06-L23-M23-N23-O23-K23 -> 498449.59 | Q23: =IF(P23<0,0,P23*$L$43) -> 24922.48 | R23: =G23+K23+Q23 -> 97164.597
B24: 21 | C24: ='光伏发电衰减表 输入数据'!G26*0.13 -> 70176.005 | D24: =$C$39/1.06*0.06+$E$39/1.06*0.06 -> 2094.3396 | E24: ='业主收益（租金、节能收益）'!D25/1.05*0.05 -> 237.19048 | F24: =C24-D24-E24 -> 67844.475 | G24: =IF(F24<0,0,F24) -> 67844.475 | H24: =G24*$L$40 -> 2374.5566 | I24: =G24*$L$41 -> 1017.6671 | J24: =G24*$L$42 -> 678.44475 | K24: =SUM(H24:J24) -> 4070.6685 | L24: 0 | M24: ='光伏发电衰减表 输入数据'!L26 -> 0 | N24: ='业主收益（租金、节能收益）'!D25/1.05 -> 4743.8095 | O24: ='等额本息（融资租赁）'!P30 -> 0 | P24: ='光伏发电衰减表 输入数据'!G26-$C$39/1.06-$E$39/1.06-L24-M24-N24-O24-K24 -> 496095.28 | Q24: =IF(P24<0,0,P24*$L$43) -> 24804.764 | R24: =G24+K24+Q24 -> 96719.908
B25: 22 | C25: ='光伏发电衰减表 输入数据'!G27*0.13 -> 69867.539 | D25: =$C$39/1.06*0.06+$E$39/1.06*0.06 -> 2094.3396 | E25: ='业主收益（租金、节能收益）'!D26/1.05*0.05 -> 237.19048 | F25: =C25-D25-E25 -> 67536.009 | G25: =IF(F25<0,0,F25) -> 67536.009 | H25: =G25*$L$40 -> 2363.7603 | I25: =G25*$L$41 -> 1013.0401 | J25: =G25*$L$42 -> 675.36009 | K25: =SUM(H25:J25) -> 4052.1605 | L25: 0 | M25: ='光伏发电衰减表 输入数据'!L27 -> 0 | N25: ='业主收益（租金、节能收益）'!D26/1.05 -> 4743.8095 | O25: ='等额本息（融资租赁）'!P31 -> 0 | P25: ='光伏发电衰减表 输入数据'!G27-$C$39/1.06-$E$39/1.06-L25-M25-N25-O25-K25 -> 493740.98 | Q25: =IF(P25<0,0,P25*$L$43) -> 24687.049 | R25: =G25+K25+Q25 -> 96275.218
... B28: 25 | C28: ='光伏发电衰减表 输入数据'!G30*0.13 -> 68942.141 | D28: =$C$39/1.06*0.06+$E$39/1.06*0.06 -> 2094.3396 | E28: ='业主收益（租金、节能收益）'!D29/1.05*0.05 -> 237.19048 | F28: =C28-D28-E28 -> 66610.611 | G28: =IF(F28<0,0,F28) -> 66610.611 | H28: =G28*$L$40 -> 2331.3714 | I28: =G28*$L$41 -> 999.15917 | J28: =G28*$L$42 -> 666.10611 | K28: =SUM(H28:J28) -> 3996.6367 | L28: 0 | M28: ='光伏发电衰减表 输入数据'!L30 -> 0 | N28: ='业主收益（租金、节能收益）'!D29/1.05 -> 4743.8095 | O28: ='等额本息（融资租赁）'!P34 -> 0 | P28: ='光伏发电衰减表 输入数据'!G30-$C$39/1.06-$E$39/1.06-L28-M28-N28-O28-K28 -> 486678.06 | Q28: =IF(P28<0,0,P28*$L$43) -> 24333.903 | R28: =G28+K28+Q28 -> 94941.151
R29: =G29+K29+Q29 -> 0
R30: =G30+K30+Q30 -> 0
R31: =G31+K31+Q31 -> 0
R32: =G32+K32+Q32 -> 0
R33: =G33+K33+Q33 -> 0
B34: 合计 | F34: 增值税合计 | G34: =SUM(G4:G33) -> 1648645.8 | J34: 税金及附加合计 | K34: =SUM(K4:K28) -> 98918.749 | M34: =SUM(M4:M28) -> 0 | O34: =SUM(O4:O11) -> 523125.07 | P34: 所得税合计 | Q34: =SUM(Q4:Q28) -> 526090.28 | R34: =SUM(R4:R28) -> 2273654.8
I37: *假设按原税率进行纳税
B38: 工程造价（含税） | C38: =基础数据!H7 -> 2000000 | I38: 名称 | K38: 原税率（%） | L38: 税率(小微企业） | M38: 备注
B39: 运维费用 | C39: =基础数据!J29 -> 30000 | D39: 保险费用 | E39: =基础数据!J27 -> 7000 | I39: 增值税及附加税费 | J39: 增值税率 | K39: 0.09 | L39: =K39 -> 0.09 | M39: /
J40: 城市维护建设税率 | K40: 0.07 | L40: =K40*0.5 -> 0.035 | M40: （小微企业减征50%）
B41: 工程造价（不含税） | C41: =C38/1.09 -> 1834862.4 | D41: 造价留抵进项税 | E41: =C38/1.09*0.09 -> 165137.61 | J41: 教育费附加税率 | K41: 0.03 | L41: =K41*0.5 -> 0.015
J42: 地方教育附加 | K42: 0.02 | L42: =K42*0.5 -> 0.01
I43: 所得税 | J43: 所得税率 | K43: 0.25 | L43: 0.05 | M43: 小微企业5%
B45: *企业出租房屋，一般纳税人税率为9%，小规模纳税人税率为5% 一般纳税人出租其2016年4月30日前取得的不动产，按5%征收

Sheet 等额本息（融资租赁）
A1: 租金计划表（原表格参考，投放本金100万） | I1: 租金计划表（月还款） | Q1: 租金计划表（年还款）
A2: 编制时间 | B2: 2024-07-30 | F2: 单位：元 | I2: 编制时间 | J2: 2024-07-30 | K2: =PMT(L6/12,N3,N4) -> -26282.86 | L2: =K2*N3 -> -2523154.6 | M2: 1258285.4 | N2: 单位：元 | Q2: 编制时间 | R2: 2024-07-30 | S2: =PMT(T6,V3,V4) -> -292168.84 | V2: 单位：元
A3: 租赁方式 | B3: 直租 | C3: 计划投放日期 | D3: 2024-07-30 | E3: 租赁期限(月) | F3: 96 | I3: 租赁方式 | J3: 直租 | K3: 计划投放日期 | L3: 2024-07-30 | M3: 租赁期限(月) | N3: 96 | Q3: 租赁方式 | R3: 直租 | S3: 计划投放日期 | T3: 2024-07-30 | U3: 租赁期限(年) | V3: 8
A4: 合同金额 | B4: 1000000 | C4: 首付款金额(直租) | D4: 0 | E4: 投放本金 | F4: 1000000 | I4: 合同金额 | J4: 1000000 | K4: 首付款金额(直租) | L4: 0 | M4: 投放本金 | N4: =基础数据!H7 -> 2000000 | Q4: 合同金额 | S4: 首付款金额(直租) | T4: 0 | U4: 投放本金 | V4: =基础数据!H7 -> 2000000
A5: 项目IRR | B5: 0.0654 | C5: 质保金金额(直租) | D5: 0 | E5: 客户风险金金额 | F5: 50000 | I5: 项目IRR | J5: 0.0654 | K5: 质保金金额(直租) | L5: 0 | M5: 客户风险金金额 | Q5: 项目IRR | S5: 质保金金额(直租) | T5: 0 | U5: 客户风险金金额
A6: 厂商保证金金额 | B6: 0 | C6: 年租息率 | D6: 0.06 | E6: 名义货价 | F6: 100 | I6: 厂商保证金金额 | J6: 0 | K6: 年租息率 | L6: 0.06 | M6: 名义货价 | N6: 100 | Q6: 厂商保证金金额 | R6: 0 | S6: 年租息率 | T6: 0.036 | U6: 名义货价 | V6: 100
A7: LPR利率发布日期 | B7: 45495 | C7: 当期LPR利率 | D7: 0.0385 | E7: 加减点 | F7: 0.0215 | G7: =D105/E105/8 -> 0.03228567 | I7: LPR利率发布日期 | J7: 45495 | K7: 当期LPR利率 | L7: 0.0385 | M7: 加减点 | N7: 0.0215 | P7: =L105/K105/8 -> 0.025916525 | Q7: LPR利率发布日期 | R7: 45495 | S7: 当期LPR利率 | T7: 0.0385 | U7: 加减点 | V7: 0.0215
A8: 期次 | B8: 租金支付日 | C8: 当期租金总额 | D8: 当期租赁利息 | E8: 当期租赁本金 | F8: 剩余本金 | I8: 期次 | J8: 租金支付日 | K8: 当期租金总额 | L8: 当期租赁利息 | M8: 当期租赁本金 | N8: 剩余本金 | Q8: 期次 | R8: 租金支付日 | S8: 当期租金总额 | T8: 当期租赁利息 | U8: 当期租赁本金 | V8: 剩余本金
A9: 1 | B9: 45514 | C9: 9808.1 | D9: 1666.67 | E9: 8141.43 | F9: 991858.57 | I9: 1 | J9: 45514 | K9: =-K2/31*24 -> 20348.021 | L9: =$N$4*$L$6/12/31*24 -> 7741.9355 | M9: =K9-L9 -> 12606.085 | N9: =N4-M9 -> 1987393.9 | O9: 年份 | P9: 每年利息合计 | Q9: 1 | R9: 45514 | S9: =-$S$2 -> 292168.84 | T9: =V4*T6 -> 72000 | U9: =S9-T9 -> 220168.84 | V9: =V4-U9 -> 1779831.2
A10: 2 | B10: 45545 | C10: 13141.43 | D10: 4959.29 | E10: 8182.14 | F10: 983676.43 | I10: 2 | J10: 45545 | K10: =-K2 -> 26282.86 | L10: =N9*$L$6/12 -> 9936.9696 | M10: =K10-L10 -> 16345.891 | N10: =N9-M10 -> 1971048 | O10: 1 | P10: =SUM(L9:L20) -> 112485.37 | Q10: 2 | R10: 45879 | S10: =-$S$2 -> 292168.84 | T10: =V9*$T$6 -> 64073.922 | U10: =S10-T10 -> 228094.92 | V10: =V9-U10 -> 1551736.2 | W10: 40.979506
A11: 3 | B11: 45575 | C11: 13141.43 | D11: 4918.38 | E11: 8223.05 | F11: 975453.38 | I11: 3 | J11: 45575 | K11: =K10 -> 26282.86 | L11: =N10*$L$6/12 -> 9855.2401 | M11: =K11-L11 -> 16427.62 | N11: =N10-M11 -> 1954620.4 | O11: 2 | P11: =SUM(L21:L32) -> 102387.15 | Q11: 3 | R11: 46244 | S11: =-$S$2 -> 292168.84 | T11: =V10*$T$6 -> 55862.505 | U11: =S11-T11 -> 236306.33 | V11: =V10-U11 -> 1315429.9 | W11: 35.857067
A12: 4 | B12: 45606 | C12: 13141.43 | D12: 4877.27 | E12: 8264.16 | F12: 967189.22 | I12: 4 | J12: 45606 | K12: =K11 -> 26282.86 | L12: =N11*$L$6/12 -> 9773.102 | M12: =K12-L12 -> 16509.758 | N12: =N11-M12 -> 1938110.6 | O12: 3 | P12: =SUM(L33:L44) -> 89249.336 | Q12: 4 | R12: 46609 | S12: =-$S$2 -> 292168.84 | T12: =V11*$T$6 -> 47355.477 | U12: =S12-T12 -> 244813.36 | V12: =V11-U12 -> 1070616.6 | W12: 30.734629
A13: 5 | B13: 45636 | C13: 13141.43 | D13: 4835.95 | E13: 8305.48 | F13: 958883.74 | I13: 5 | J13: 45636 | K13: =K12 -> 26282.86 | L13: =N12*$L$6/12 -> 9690.5532 | M13: =K13-L13 -> 16592.307 | N13: =N12-M13 -> 1921518.3 | O13: 4 | P13: =SUM(L45:L56) -> 75301.208 | Q13: 5 | R13: 46975 | S13: =-$S$2 -> 292168.84 | T13: =V12*$T$6 -> 38542.196 | U13: =S13-T13 -> 253626.64 | V13: =V12-U13 -> 816989.91 | W13: 25.612191
A14: 6 | B14: 45667 | C14: 13141.43 | D14: 4794.42 | E14: 8347.01 | F14: 950536.73 | I14: 6 | J14: 45667 | K14: =K13 -> 26282.86 | L14: =N13*$L$6/12 -> 9607.5917 | M14: =K14-L14 -> 16675.269 | N14: =N13-M14 -> 1904843.1 | O14: 5 | P14: =SUM(L57:L68) -> 60492.79 | Q14: 6 | R14: 47340 | S14: =-$S$2 -> 292168.84 | T14: =V13*$T$6 -> 29411.637 | U14: =S14-T14 -> 262757.2 | V14: =V13-U14 -> 554232.71 | W14: 20.489753
A15: 7 | B15: 45698 | C15: 13141.43 | D15: 4752.68 | E15: 8388.75 | F15: 942147.98 | I15: 7 | J15: 45698 | K15: =K14 -> 26282.86 | L15: =N14*$L$6/12 -> 9524.2153 | M15: =K15-L15 -> 16758.645 | N15: =N14-M15 -> 1888084.4 | O15: 6 | P15: =SUM(L69:L80) -> 44771.021 | Q15: 7 | R15: 47705 | S15: =-$S$2 -> 292168.84 | T15: =V14*$T$6 -> 19952.378 | U15: =S15-T15 -> 272216.46 | V15: =V14-U15 -> 282016.25 | W15: 15.367315
A16: 8 | B16: 45726 | C16: 13141.43 | D16: 4710.74 | E16: 8430.69 | F16: 933717.29 | I16: 8 | J16: 45726 | K16: =K15 -> 26282.86 | L16: =N15*$L$6/12 -> 9440.4221 | M16: =K16-L16 -> 16842.438 | N16: =N15-M16 -> 1871242 | O16: 7 | P16: =SUM(L81:L92) -> 28079.568 | Q16: 8 | R16: 48070 | S16: =-$S$2 -> 292168.84 | T16: =V15*$T$6 -> 10152.585 | U16: =S16-T16 -> 282016.25 | V16: =V15-U16 -> 1.5133992e-09 | W16: 10.244876
A17: 9 | B17: 45757 | C17: 13141.43 | D17: 4668.59 | E17: 8472.84 | F17: 925244.45 | I17: 9 | J17: 45757 | K17: =K16 -> 26282.86 | L17: =N16*$L$6/12 -> 9356.2099 | M17: =K17-L17 -> 16926.65 | N17: =N16-M17 -> 1854315.3 | O17: 8 | P17: =SUM(L93:L104) -> 10358.622 | R17: 合计 | S17: =SUM(S9:S16) -> 2337350.7 | T17: =SUM(T9:T16) -> 337350.7 | U17: =SUM(U9:U16) -> 2000000 | W17: 5.1224382
A18: 10 | B18: 45787 | C18: 13141.43 | D18: 4626.22 | E18: 8515.21 | F18: 916729.24 | I18: 10 | J18: 45787 | K18: =K17 -> 26282.86 | L18: =N17*$L$6/12 -> 9271.5767 | M18: =K18-L18 -> 17011.284 | N18: =N17-M18 -> 1837304.1
A19: 11 | B19: 45818 | C19: 13141.43 | D19: 4583.65 | E19: 8557.78 | F19: 908171.46 | I19: 11 | J19: 45818 | K19: =K18 -> 26282.86 | L19: =N18*$L$6/12 -> 9186.5203 | M19: =K19-L19 -> 17096.34 | N19: =N18-M19 -> 1820207.7
A20: 12 | B20: 45848 | C20: 13141.43 | D20: 4540.86 | E20: 8600.57 | F20: 899570.89 | I20: 12 | J20: 45848 | K20: =K19 -> 26282.86 | L20: =N19*$L$6/12 -> 9101.0386 | M20: =K20-L20 -> 17181.822 | N20: =N19-M20 -> 1803025.9
A21: 13 | B21: 45879 | C21: 13141.43 | D21: 4497.85 | E21: 8643.58 | F21: 890927.31 | I21: 13 | J21: 45879 | K21: =K20 -> 26282.86 | L21: =N20*$L$6/12 -> 9015.1294 | M21: =K21-L21 -> 17267.731 | N21: =N20-M21 -> 1785758.2
A22: 14 | B22: 45910 | C22: 13141.43 | D22: 4454.64 | E22: 8686.79 | F22: 882240.52 | I22: 14 | J22: 45910 | K22: =K21 -> 26282.86 | L22: =N21*$L$6/12 -> 8928.7908 | M22: =K22-L22 -> 17354.07 | N22: =N21-M22 -> 1768404.1
A23: 15 | B23: 45940 | C23: 13141.43 | D23: 4411.2 | E23: 8730.23 | F23: 873510.29 | I23: 15 | J23: 45940 | K23: =K22 -> 26282.86 | L23: =N22*$L$6/12 -> 8842.0204 | M23: =K23-L23 -> 17440.84 | N23: =N22-M23 -> 1750963.2
A24: 16 | B24: 45971 | C24: 13141.43 | D24: 4367.55 | E24: 8773.88 | F24: 864736.41 | I24: 16 | J24: 45971 | K24: =K23 -> 26282.86 | L24: =N23*$L$6/12 -> 8754.8162 | M24: =K24-L24 -> 17528.044 | N24: =N23-M24 -> 1733435.2
A25: 17 | B25: 46001 | C25: 13141.43 | D25: 4323.68 | E25: 8817.75 | F25: 855918.66 | I25: 17 | J25: 46001 | K25: =K24 -> 26282.86 | L25: =N24*$L$6/12 -> 8667.176 | M25: =K25-L25 -> 17615.684 | N25: =N24-M25 -> 1715819.5
A26: 18 | B26: 46032 | C26: 13141.43 | D26: 4279.59 | E26: 8861.84 | F26: 847056.82 | I26: 18 | J26: 46032 | K26: =K25 -> 26282.86 | L26: =N25*$L$6/12 -> 8579.0976 | M26: =K26-L26 -> 17703.763 | N26: =N25-M26 -> 1698115.8
A27: 19 | B27: 46063 | C27: 13141.43 | D27: 4235.28 | E27: 8906.15 | F27: 838150.67 | I27: 19 | J27: 46063 | K27: =K26 -> 26282.86 | L27: =N26*$L$6/12 -> 8490.5788 | M27: =K27-L27 -> 17792.282 | N27: =N26-M27 -> 1680323.5
A28: 20 | B28: 46091 | C28: 13141.43 | D28: 4190.75 | E28: 8950.68 | F28: 829199.99 | I28: 20 | J28: 46091 | K28: =K27 -> 26282.86 | L28: =N27*$L$6/12 -> 8401.6174 | M28: =K28-L28 -> 17881.243 | N28: =N27-M28 -> 1662442.2
A29: 21 | B29: 46122 | C29: 13141.43 | D29: 4146 | E29: 8995.43 | F29: 820204.56 | I29: 21 | J29: 46122 | K29: =K28 -> 26282.86 | L29: =N28*$L$6/12 -> 8312.2112 | M29: =K29-L29 -> 17970.649 | N29: =N28-M29 -> 1644471.6
... A103: 95 | B103: 48375 | C103: 13141.43 | D103: 130.44 | E103: 13010.99 | F103: 13076.05 | I103: 95 | J103: 48375 | K103: =K102 -> 26282.86 | L103: =N102*$L$6/12 -> 290.10395 | M103: =K103-L103 -> 25992.756 | N103: =N102-M103 -> 32028.033
A104: 96 | B104: 48424 | C104: 13182.84 | D104: 106.79 | E104: 13076.05 | F104: 0 | I104: 96 | J104: 48424 | K104: =N103+L104 -> 32188.173 | L104: =N103*$L$6/12 -> 160.14017 | M104: =K104-L104 -> 32028.033 | N104: =N103-M104 -> 0
A105: 合计 | C105: 1258285.4 | D105: 258285.36 | E105: 1000000 | I105: 合计 | K105: =SUM(K9:K104) -> 2523125.1 | L105: =SUM(L9:L104) -> 523125.07 | M105: =SUM(M9:M104) -> 2000000

Sheet 等额本金（银行贷款）
D2: 等额本金（年还款）
A3: 贷款总额（元） | B3: =基础数据!H7 -> 2000000 | D3: 期数 | E3: 剩余应计算利息的本金（元） | G3: 每年应还利息（元） | H3: 资金成本合计
A4: 贷款利率 | B4: 0.036 | D4: 1 | E4: 0 | F4: =B3 -> 2000000 | G4: =F4*$B$4 -> 72000 | H4: =G4 -> 72000
A5: 贷款期数 | B5: 8 | D5: 2 | E5: =$B$9 -> 250000 | F5: =F4-E5 -> 1750000 | G5: =F5*$B$4 -> 63000 | H5: =G5 -> 63000
D6: 3 | E6: =$B$9 -> 250000 | F6: =F5-E6 -> 1500000 | G6: =F6*$B$4 -> 54000 | H6: =G6 -> 54000
D7: 4 | E7: =$B$9 -> 250000 | F7: =F6-E7 -> 1250000 | G7: =F7*$B$4 -> 45000 | H7: =G7 -> 45000
A8: 等额本金 | D8: 5 | E8: =$B$9 -> 250000 | F8: =F7-E8 -> 1000000 | G8: =F8*$B$4 -> 36000 | H8: =G8 -> 36000
A9: 每期应还本金（元） | B9: =B3/B5 -> 250000 | D9: 6 | E9: =$B$9 -> 250000 | F9: =F8-E9 -> 750000 | G9: =F9*$B$4 -> 27000 | H9: =G9 -> 27000
D10: 7 | E10: =$B$9 -> 250000 | F10: =F9-E10 -> 500000 | G10: =F10*$B$4 -> 18000 | H10: =G10 -> 18000
A11: *若需要月还款，还款期数=年*12 | D11: 8 | E11: =$B$9 -> 250000 | F11: =F10-E11 -> 250000 | G11: =F11*$B$4 -> 9000 | H11: =G11 -> 9000
A12: *月利率=年利率/12 | D12: 9 | E12: =$B$9 -> 250000
D13: 10
D14: 11
D15: 12
D16: 13
D17: 14
D18: 15
D19: 16
D20: 17
D21: 18
D22: 19
D23: 20
D24: 21
... D99: 96

Sheet 光伏发电衰减表min EMC
K1: 每年除去七、八、九月 平均电价计算（元/KW.h）
B2: 年发电量预估（理论最小值） | E2: 业主消纳率 | F2: 余电上网率 | K2: 供电局购电价 | L2: 尖电电价 | M2: 峰电电价 | N2: 平段电价 | O2: 谷电电价 | P2: 输配电费（尖） | Q2: 输配电费（峰） | R2: 输配电费（平） | S2: 基金及附加费
B3: 年份 | C3: 系统发电效率(%) | D3: 发电量（度） | E3: =消纳率参数!K31 -> 0 | F3: =1-E3 -> 1 | G3: 节能效益（元） | H3: 月平均发电量（度） | J3: 余电上网电价（元） | L3: =光伏发电衰减表min!L3 -> 1.4773 | M3: =光伏发电衰减表min!M3 -> 1.1872 | N3: =光伏发电衰减表min!N3 -> 0.7097 | O3: 忽略 | P3: 0 | Q3: 0 | R3: 0 | S3: 0
B4: 1 | C4: 0.99 | D4: =$J$10*C4 -> #REF! | E4: =D4*E3 -> #REF! | F4: =D4*F3 -> #REF! | G4: =$J$12*C4*$E$3*$L$8*(1-$J$6)+$J$14*C4*$E$3*$L$17*(1-$J$6) -> #REF! | H4: =D4/12 -> #REF! | J4: 0.453 | K4: 光伏发电电价 | L4: 尖电电价 | M4: 峰电电价 | N4: 平段电价 | O4: 谷电电价
B5: 2 | C5: =C4-0.004 -> 0.986 | D5: =$J$10*C5 -> #REF! | E5: =D5*$E$3 -> #REF! | F5: =D5*$F$3 -> #REF! | G5: =$J$12*C5*$E$3*$L$8*(1-$J$6)+$J$14*C5*$E$3*$L$17*(1-$J$6) -> #REF! | H5: =D5/12 -> #REF! | J5: 电价折扣（EMC） | L5: =L3+P3+S3 -> 1.4773 | M5: =M3+Q3+S3 -> 1.1872 | N5: =N3+R3+S3 -> 0.7097 | O5: 忽略
B6: 3 | C6: =C5-0.004 -> 0.982 | D6: =$J$10*C6 -> #REF! | E6: =D6*$E$3 -> #REF! | F6: =D6*$F$3 -> #REF! | G6: =$J$12*C6*$E$3*$L$8*(1-$J$6)+$J$14*C6*$E$3*$L$17*(1-$J$6) -> #REF! | H6: =D6/12 -> #REF! | J6: 0.9 | L6: 加权系数 | M6: 加权系数 | N6: 加权系数 | O6: 加权系数 | P6: 合计时段
B7: 4 | C7: =C6-0.004 -> 0.978 | D7: =$J$10*C7 -> #REF! | E7: =D7*$E$3 -> #REF! | F7: =D7*$F$3 -> #REF! | G7: =$J$12*C7*$E$3*$L$8*(1-$J$6)+$J$14*C7*$E$3*$L$17*(1-$J$6) -> #REF! | H7: =D7/12 -> #REF! | J7: 全年平均电价 | L7: 0 | M7: 5 | N7: 4 | O7: 0 | P7: 9
B8: 5 | C8: =C7-0.004 -> 0.974 | D8: =$J$10*C8 -> #REF! | E8: =D8*$E$3 -> #REF! | F8: =D8*$F$3 -> #REF! | G8: =$J$12*C8*$E$3*$L$8*(1-$J$6)+$J$14*C8*$E$3*$L$17*(1-$J$6) -> #REF! | H8: =D8/12 -> #REF! | J8: =(L8*9+L17*3)/12 -> 0.99915278 | K8: 加权后平均电价 | L8: =(M5*M7+N5*N7)/P7 -> 0.97497778
B9: 6 | C9: =C8-0.004 -> 0.97 | D9: =$J$10*C9 -> #REF! | E9: =D9*$E$3 -> #REF! | F9: =D9*$F$3 -> #REF! | G9: =$J$12*C9*$E$3*$L$8*(1-$J$6)+$J$14*C9*$E$3*$L$17*(1-$J$6) -> #REF! | H9: =D9/12 -> #REF! | J9: 首年发电量
B10: 7 | C10: =C9-0.004 -> 0.966 | D10: =$J$10*C10 -> #REF! | E10: =D10*$E$3 -> #REF! | F10: =D10*$F$3 -> #REF! | G10: =$J$12*C10*$E$3*$L$8*(1-$J$6)+$J$14*C10*$E$3*$L$17*(1-$J$6) -> #REF! | H10: =D10/12 -> #REF! | J10: =J12+J14 -> #REF! | K10: 每年七、八、九月 平均电价计算（元/KW.h）
B11: 8 | C11: =C10-0.004 -> 0.962 | D11: =$J$10*C11 -> #REF! | E11: =D11*$E$3 -> #REF! | F11: =D11*$F$3 -> #REF! | G11: =$J$12*C11*$E$3*$L$8*(1-$J$6)+$J$14*C11*$E$3*$L$17*(1-$J$6) -> #REF! | H11: =D11/12 -> #REF! | J11: 首年除七、八、九月的发电总量 | K11: 供电局购电价 | L11: 尖电电价 | M11: 峰电电价 | N11: 平段电价 | O11: 谷电电价 | P11: 输配电费（尖） | Q11: 输配电费（峰） | R11: 输配电费（平） | S11: 基金及附加费
B12: 9 | C12: =C11-0.004 -> 0.958 | D12: =$J$10*C12 -> #REF! | E12: =D12*$E$3 -> #REF! | F12: =D12*$F$3 -> #REF! | G12: =$J$12*C12*$E$3*$L$8*(1-$J$6)+$J$14*C12*$E$3*$L$17*(1-$J$6) -> #REF! | H12: =D12/12 -> #REF! | J12: =M21+M22+M23+M24+M25+M26+M30+M31+M32 -> #REF! | L12: =L3 -> 1.4773 | M12: =M3 -> 1.1872 | N12: =N3 -> 0.7097 | O12: =O3 -> 忽略 | P12: 0 | Q12: 0 | R12: 0 | S12: 0
B13: 10 | C13: =C12-0.004 -> 0.954 | D13: =$J$10*C13 -> #REF! | E13: =D13*$E$3 -> #REF! | F13: =D13*$F$3 -> #REF! | G13: =$J$12*C13*$E$3*$L$8*(1-$J$6)+$J$14*C13*$E$3*$L$17*(1-$J$6) -> #REF! | H13: =D13/12 -> #REF! | J13: 首年七、八、九月发电总量 | K13: 光伏发电电价 | L13: 尖电电价 | M13: 峰电电价 | N13: 平段电价 | O13: 谷电电价
B14: 11 | C14: =C13-0.004 -> 0.95 | D14: =$J$10*C14 -> #REF! | E14: =D14*$E$3 -> #REF! | F14: =D14*$F$3 -> #REF! | G14: =$J$12*C14*$E$3*$L$8*(1-$J$6)+$J$14*C14*$E$3*$L$17*(1-$J$6) -> #REF! | H14: =D14/12 -> #REF! | J14: =M27+M28+M29 -> #REF! | L14: =L12+P12+S12 -> 1.4773 | M14: =M12+Q12+S12 -> 1.1872 | N14: =N12+R12+S12 -> 0.7097 | O14: 忽略
B15: 12 | C15: =C14-0.004 -> 0.946 | D15: =$J$10*C15 -> #REF! | E15: =D15*$E$3 -> #REF! | F15: =D15*$F$3 -> #REF! | G15: =$J$12*C15*$E$3*$L$8*(1-$J$6)+$J$14*C15*$E$3*$L$17*(1-$J$6) -> #REF! | H15: =D15/12 -> #REF! | L15: 加权系数 | M15: 加权系数 | N15: 加权系数 | O15: 加权系数 | P15: 合计时段
B16: 13 | C16: =C15-0.004 -> 0.942 | D16: =$J$10*C16 -> #REF! | E16: =D16*$E$3 -> #REF! | F16: =D16*$F$3 -> #REF! | G16: =$J$12*C16*$E$3*$L$8*(1-$J$6)+$J$14*C16*$E$3*$L$17*(1-$J$6) -> #REF! | H16: =D16/12 -> #REF! | L16: 3 | M16: 2 | N16: 4 | O16: 0 | P16: 9
B17: 14 | C17: =C16-0.004 -> 0.938 | D17: =$J$10*C17 -> #REF! | E17: =D17*$E$3 -> #REF! | F17: =D17*$F$3 -> #REF! | G17: =$J$12*C17*$E$3*$L$8*(1-$J$6)+$J$14*C17*$E$3*$L$17*(1-$J$6) -> #REF! | H17: =D17/12 -> #REF! | K17: 加权后平均电价 | L17: =(L14*L16+M14*M16+N14*N16)/P16 -> 1.0716778
B18: 15 | C18: =C17-0.004 -> 0.934 | D18: =$J$10*C18 -> #REF! | E18: =D18*$E$3 -> #REF! | F18: =D18*$F$3 -> #REF! | G18: =$J$12*C18*$E$3*$L$8*(1-$J$6)+$J$14*C18*$E$3*$L$17*(1-$J$6) -> #REF! | H18: =D18/12 -> #REF!
B19: 16 | C19: =C18-0.004 -> 0.93 | D19: =$J$10*C19 -> #REF! | E19: =D19*$E$3 -> #REF! | F19: =D19*$F$3 -> #REF! | G19: =$J$12*C19*$E$3*$L$8*(1-$J$6)+$J$14*C19*$E$3*$L$17*(1-$J$6) -> #REF! | H19: =D19/12 -> #REF! | K19: 首年预计发电量（KW.h）
B20: 17 | C20: =C19-0.004 -> 0.926 | D20: =$J$10*C20 -> #REF! | E20: =D20*$E$3 -> #REF! | F20: =D20*$F$3 -> #REF! | G20: =$J$12*C20*$E$3*$L$8*(1-$J$6)+$J$14*C20*$E$3*$L$17*(1-$J$6) -> #REF! | H20: =D20/12 -> #REF! | K20: 月份 | M20: 月发电量
B21: 18 | C21: =C20-0.004 -> 0.922 | D21: =$J$10*C21 -> #REF! | E21: =D21*$E$3 -> #REF! | F21: =D21*$F$3 -> #REF! | G21: =$J$12*C21*$E$3*$L$8*(1-$J$6)+$J$14*C21*$E$3*$L$17*(1-$J$6) -> #REF! | H21: =D21/12 -> #REF! | K21: 1月 | M21: =基础数据!#REF! -> #REF!
B22: 19 | C22: =C21-0.004 -> 0.918 | D22: =$J$10*C22 -> #REF! | E22: =D22*$E$3 -> #REF! | F22: =D22*$F$3 -> #REF! | G22: =$J$12*C22*$E$3*$L$8*(1-$J$6)+$J$14*C22*$E$3*$L$17*(1-$J$6) -> #REF! | H22: =D22/12 -> #REF! | K22: 2月 | M22: =基础数据!#REF! -> #REF!
B23: 20 | C23: =C22-0.004 -> 0.914 | D23: =$J$10*C23 -> #REF! | E23: =D23*$E$3 -> #REF! | F23: =D23*$F$3 -> #REF! | G23: =$J$12*C23*$E$3*$L$8*(1-$J$6)+$J$14*C23*$E$3*$L$17*(1-$J$6) -> #REF! | H23: =D23/12 -> #REF! | K23: 3月 | M23: =基础数据!#REF! -> #REF!
B24: 21 | C24: =C23-0.004 -> 0.91 | D24: =$J$10*C24 -> #REF! | E24: =D24*$E$3 -> #REF! | F24: =D24*$F$3 -> #REF! | G24: =$J$12*C24*$E$3*$L$8*(1-$J$6)+$J$14*C24*$E$3*$L$17*(1-$J$6) -> #REF! | H24: =D24/12 -> #REF! | K24: 4月 | M24: =基础数据!#REF! -> #REF!
B25: 22 | C25: =C24-0.004 -> 0.906 | D25: =$J$10*C25 -> #REF! | E25: =D25*$E$3 -> #REF! | F25: =D25*$F$3 -> #REF! | G25: =$J$12*C25*$E$3*$L$8*(1-$J$6)+$J$14*C25*$E$3*$L$17*(1-$J$6) -> #REF! | H25: =D25/12 -> #REF! | K25: 5月 | M25: =基础数据!#REF! -> #REF!
B26: 23 | C26: =C25-0.004 -> 0.902 | D26: =$J$10*C26 -> #REF! | E26: =D26*$E$3 -> #REF! | F26: =D26*$F$3 -> #REF! | G26: =$J$12*C26*$E$3*$L$8*(1-$J$6)+$J$14*C26*$E$3*$L$17*(1-$J$6) -> #REF! | H26: =D26/12 -> #REF! | K26: 6月 | M26: =基础数据!#REF! -> #REF!
B27: 24 | C27: =C26-0.004 -> 0.898 | D27: =$J$10*C27 -> #REF! | E27: =D27*$E$3 -> #REF! | F27: =D27*$F$3 -> #REF! | G27: =$J$12*C27*$E$3*$L$8*(1-$J$6)+$J$14*C27*$E$3*$L$17*(1-$J$6) -> #REF! | H27: =D27/12 -> #REF! | K27: 7月 | M27: =基础数据!#REF! -> #REF!
B28: 25 | C28: =C27-0.004 -> 0.894 | D28: =$J$10*C28 -> #REF! | E28: =D28*$E$3 -> #REF! | F28: =D28*$F$3 -> #REF! | G28: =$J$12*C28*$E$3*$L$8*(1-$J$6)+$J$14*C28*$E$3*$L$17*(1-$J$6) -> #REF! | H28: =D28/12 -> #REF! | K28: 8月 | M28: =基础数据!#REF! -> #REF!
B29: 26 | C29: =C28-0.004 -> 0.89 | D29: =$J$10*C29 -> #REF! | E29: =D29*$E$3 -> #REF! | F29: =D29*$F$3 -> #REF! | G29: =$J$12*C29*$E$3*$L$8*(1-$J$6)+$J$14*C29*$E$3*$L$17*(1-$J$6) -> #REF! | H29: =D29/12 -> #REF! | K29: 9月 | M29: =基础数据!#REF! -> #REF!
B30: 27 | C30: =C29-0.004 -> 0.886 | D30: =$J$10*C30 -> #REF! | E30: =D30*$E$3 -> #REF! | F30: =D30*$F$3 -> #REF! | G30: =$J$12*C30*$E$3*$L$8*(1-$J$6)+$J$14*C30*$E$3*$L$17*(1-$J$6) -> #REF! | H30: =D30/12 -> #REF! | K30: 10月 | M30: =基础数据!#REF! -> #REF!
B31: 28 | C31: =C30-0.004 -> 0.882 | D31: =$J$10*C31 -> #REF! | E31: =D31*$E$3 -> #REF! | F31: =D31*$F$3 -> #REF! | G31: =$J$12*C31*$E$3*$L$8*(1-$J$6)+$J$14*C31*$E$3*$L$17*(1-$J$6) -> #REF! | H31: =D31/12 -> #REF! | K31: 11月 | M31: =基础数据!#REF! -> #REF!
B32: 29 | C32: =C31-0.004 -> 0.878 | D32: =$J$10*C32 -> #REF! | E32: =D32*$E$3 -> #REF! | F32: =D32*$F$3 -> #REF! | G32: =$J$12*C32*$E$3*$L$8*(1-$J$6)+$J$14*C32*$E$3*$L$17*(1-$J$6) -> #REF! | H32: =D32/12 -> #REF! | K32: 12月 | M32: =基础数据!#REF! -> #REF!
B33: 30 | C33: =C32-0.004 -> 0.874 | D33: =$J$10*C33 -> #REF! | E33: =D33*$E$3 -> #REF! | F33: =D33*$F$3 -> #REF! | G33: =$J$12*C33*$E$3*$L$8*(1-$J$6)+$J$14*C33*$E$3*$L$17*(1-$J$6) -> #REF! | H33: =D33/12 -> #REF!
B34: 合计 | D34: =SUM(D4:D33) -> #REF! | E34: =SUM(E4:E33) -> #REF! | F34: =SUM(F4:F33) -> #REF! | G34: =SUM(G4:G33) -> #REF!
A35: .

Sheet 光伏发电衰减表 理论均值 EMC
K1: 每年除去七、八、九月 平均电价计算（元/KW.h）
B2: 年发电量预估（理论平均值） | E2: 业主消纳率 | F2: 余电上网率 | K2: 供电局购电价 | L2: 尖电电价 | M2: 峰电电价 | N2: 平段电价 | O2: 谷电电价 | P2: 输配电费（尖） | Q2: 输配电费（峰） | R2: 输配电费（平） | S2: 基金及附加费
B3: 年份 | C3: 系统发电效率(%) | D3: 发电量（度） | E3: 0 | F3: =1-E3 -> 1 | G3: 节能效益（元） | H3: 月平均发电量（度） | J3: 余电上网电价（元） | L3: =光伏发电衰减表min!L3 -> 1.4773 | M3: =光伏发电衰减表min!M3 -> 1.1872 | N3: =光伏发电衰减表min!N3 -> 0.7097 | O3: 忽略 | P3: =光伏发电衰减表min!P3 -> 0 | Q3: =光伏发电衰减表min!Q3 -> 0 | R3: =光伏发电衰减表min!R3 -> 0 | S3: =光伏发电衰减表min!S3 -> 0
B4: 1 | C4: 0.99 | D4: =$J$10*C4 -> 0 | E4: =D4*E3 -> 0 | F4: =D4*F3 -> 0 | G4: =$J$12*C4*$E$3*$L$8*(1-$J$6)+$J$14*C4*$E$3*$L$17*(1-$J$6) -> 0 | H4: =D4/12 -> 0 | J4: 0.453 | K4: 光伏发电电价 | L4: 尖电电价 | M4: 峰电电价 | N4: 平段电价 | O4: 谷电电价
B5: 2 | C5: =C4-0.004 -> 0.986 | D5: =$J$10*C5 -> 0 | E5: =D5*$E$3 -> 0 | F5: =D5*$F$3 -> 0 | G5: =$J$12*C5*$E$3*$L$8*(1-$J$6)+$J$14*C5*$E$3*$L$17*(1-$J$6) -> 0 | H5: =D5/12 -> 0 | J5: 折扣 | L5: =L3+P3+S3 -> 1.4773 | M5: =M3+Q3+S3 -> 1.1872 | N5: =N3+R3+S3 -> 0.7097 | O5: 忽略
B6: 3 | C6: =C5-0.004 -> 0.982 | D6: =$J$10*C6 -> 0 | E6: =D6*$E$3 -> 0 | F6: =D6*$F$3 -> 0 | G6: =$J$12*C6*$E$3*$L$8*(1-$J$6)+$J$14*C6*$E$3*$L$17*(1-$J$6) -> 0 | H6: =D6/12 -> 0 | J6: 0.85 | L6: 加权系数 | M6: 加权系数 | N6: 加权系数 | O6: 加权系数 | P6: 合计时段
B7: 4 | C7: =C6-0.004 -> 0.978 | D7: =$J$10*C7 -> 0 | E7: =D7*$E$3 -> 0 | F7: =D7*$F$3 -> 0 | G7: =$J$12*C7*$E$3*$L$8*(1-$J$6)+$J$14*C7*$E$3*$L$17*(1-$J$6) -> 0 | H7: =D7/12 -> 0 | J7: 全年平均电价 | L7: 0 | M7: 5 | N7: 4 | O7: 0 | P7: 9
B8: 5 | C8: =C7-0.004 -> 0.974 | D8: =$J$10*C8 -> 0 | E8: =D8*$E$3 -> 0 | F8: =D8*$F$3 -> 0 | G8: =$J$12*C8*$E$3*$L$8*(1-$J$6)+$J$14*C8*$E$3*$L$17*(1-$J$6) -> 0 | H8: =D8/12 -> 0 | J8: =(L8*9+L17*3)/12 -> 0.99915278 | K8: 加权后平均电价 | L8: =(M5*M7+N5*N7)/P7 -> 0.97497778
